Workbook

Sheet Лист1
A1: metric_code | B1: metric_name | C1: Юнит | D1: трайб | E1: product | F1: тип | G1: факт | H1: макс балл | I1: metric_group | J1: Column4 | K1: Column5 | L1: metric_subgroup | M1: metric_footer | N1: recommendation | O1: is_visible | P1: recommendation_group | Q1: sort | R1: flg
A2: 22 | B2: Оповещения по бизнес-метрикам | C2: УБ | D2: ДИиН | E2: БПИФ | F2: продукт | G2: 0 | H2: 1 | I2: Алерты | M2: Светофоры целей, драйверов, воронок | N2: Внедрить систему оповещений | O2: 1 | P2: 5 | Q2: 1 | R2: 1
A3: 22 | B3: Оповещения по бизнес-метрикам | C3: УБ | D3: ДББ | E3: Брокерский счет | F3: продукт | G3: 0 | H3: 1 | I3: Алерты | M3: Светофоры целей, драйверов, воронок | N3: Внедрить систему оповещений | O3: 1 | P3: 5 | Q3: 1 | R3: 1
A4: 22 | B4: Оповещения по бизнес-метрикам | C4: CBP | D4: Сбережения клиентов | E4: Вклады+НС | F4: продукт | G4: 0 | H4: 1 | I4: Алерты | M4: Светофоры целей, драйверов, воронок | N4: Внедрить систему оповещений | O4: 1 | P4: 5 | Q4: 1 | R4: 1
A5: 22 | B5: Оповещения по бизнес-метрикам | C5: DB | D5: Социальные и зарплатные решения | E5: Военная пенсия | F5: продукт | G5: 0 | H5: 1 | I5: Алерты | M5: Светофоры целей, драйверов, воронок | N5: Внедрить систему оповещений | O5: 1 | P5: 5 | Q5: 1 | R5: 1
A6: 22 | B6: Оповещения по бизнес-метрикам | C6: УБ | D6: ДЗСПиС | E6: ДСЖ КК | F6: продукт | G6: 0 | H6: 1 | I6: Алерты | M6: Светофоры целей, драйверов, воронок | N6: Внедрить систему оповещений | O6: 1 | P6: 5 | Q6: 1 | R6: 1
A7: 22 | B7: Оповещения по бизнес-метрикам | C7: УБ | D7: ДИиН | E7: ДУ | F7: продукт | G7: 0 | H7: 1 | I7: Алерты | M7: Светофоры целей, драйверов, воронок | N7: Внедрить систему оповещений | O7: 1 | P7: 5 | Q7: 1 | R7: 1
A8: 22 | B8: Оповещения по бизнес-метрикам | C8: DB | D8: Кошелёк клиента | E8: Дебетовая карта | F8: продукт | G8: 0 | H8: 1 | I8: Алерты | M8: Светофоры целей, драйверов, воронок | N8: Внедрить систему оповещений | O8: 1 | P8: 5 | Q8: 1 | R8: 1
A9: 22 | B9: Оповещения по бизнес-метрикам | C9: DB | D9: Кошелёк клиента | E9: Детская карта | F9: продукт | G9: 0 | H9: 1 | I9: Алерты | M9: Светофоры целей, драйверов, воронок | N9: Внедрить систему оповещений | O9: 1 | P9: 5 | Q9: 1 | R9: 1
A10: 22 | B10: Оповещения по бизнес-метрикам | C10: УБ | D10: ДИиН | E10: ЗПИФ | F10: продукт | G10: 0 | H10: 1 | I10: Алерты | M10: Светофоры целей, драйверов, воронок | N10: Внедрить систему оповещений | O10: 1 | P10: 5 | Q10: 1 | R10: 1
A11: 22 | B11: Оповещения по бизнес-метрикам | C11: DB | D11: Социальные и зарплатные решения | E11: Зарплатный продукт | F11: продукт | G11: 0 | H11: 1 | I11: Алерты | M11: Светофоры целей, драйверов, воронок | N11: Внедрить систему оповещений | O11: 1 | P11: 5 | Q11: 1 | R11: 1
A12: 22 | B12: Оповещения по бизнес-метрикам | C12: УБ | D12: ДИиН | E12: ИСЖ | F12: продукт | G12: 0 | H12: 1 | I12: Алерты | M12: Светофоры целей, драйверов, воронок | N12: Внедрить систему оповещений | O12: 1 | P12: 5 | Q12: 1 | R12: 1
A13: 22 | B13: Оповещения по бизнес-метрикам | C13: УБ | D13: РИБ | E13: ИнвестКопилка | F13: продукт | G13: 0 | H13: 1 | I13: Алерты | M13: Светофоры целей, драйверов, воронок | N13: Внедрить систему оповещений | O13: 1 | P13: 5 | Q13: 1 | R13: 1
... A313: 4 | B313: Факторный анализ — драйверы 1–2 ур. | C313: PC | D313: СберМобайл | E313: СберМобайл | F313: ДЗО | G313: 0,5 | H313: 1 | I313: Цели | M313: Драйверы согласно модели бизнес-планирования выведены в Навигатор | N313: Декомпозировать значения целей на драйверы, вывести в Навигатор | O313: 1 | P313: 7 | Q313: 2 | R313: 1
A314: 7 | B314: Факторный анализ — драйверы 1–2 ур. | C314: ДомКлик | D314: Лайфстайл | E314: Личный кабинет сопровождения ипотеки (далее - ЛКС) | F314: ДЗО | G314: 1 | H314: 1 | I314: Цели | K314: В навигаторе (покрытие >90% целей) | M314: Драйверы согласно модели бизнес-планирования выведены в Навигатор | N314: Декомпозировать значения целей на драйверы, вывести в Навигатор | O314: 0 | P314: 7 | Q314: 2 | R314: 0
A315: 7 | B315: Факторный анализ — драйверы 1–2 ур. | C315: ДомКлик | D315: Лайфстайл | E315: Моя Недвижимость | F315: ДЗО | G315: 1 | H315: 1 | I315: Цели | K315: В навигаторе (покрытие >90% целей) | M315: Драйверы согласно модели бизнес-планирования выведены в Навигатор | N315: Декомпозировать значения целей на драйверы, вывести в Навигатор | O315: 0 | P315: 7 | Q315: 2 | R315: 0
A316: 7 | B316: Факторный анализ — драйверы 1–2 ур. | C316: PC | D316: СберМобайл | E316: СберМобайл | F316: ДЗО | G316: 1 | H316: 1 | I316: Цели | K316: В навигаторе (покрытие >90% целей) | M316: Драйверы согласно модели бизнес-планирования выведены в Навигатор | N316: Декомпозировать значения целей на драйверы, вывести в Навигатор | O316: 0 | P316: 7 | Q316: 2 | R316: 0
A317: 4 | B317: Факторный анализ — драйверы 1–2 ур. | C317: CBP | D317: Авто | E317: Автокредит | F317: продукт | G317: =VLOOKUP(E317,Лист2!A:D,3,0) -> 0 | H317: 1 | I317: Цели | M317: Драйверы согласно модели бизнес-планирования выведены в Навигатор | N317: Декомпозировать значения целей на драйверы, вывести в Навигатор | O317: 1 | P317: 7 | Q317: 2 | R317: 1
A318: 7 | B318: Факторный анализ — драйверы 1–2 ур. | C318: PC | D318: Развитие сервиса в каналах | E318: Колл-центр | F318: Канал | G318: 1 | H318: 1 | I318: Цели | K318: В навигаторе (покрытие >90% целей) | M318: Драйверы согласно модели бизнес-планирования выведены в Навигатор | N318: Декомпозировать значения целей на драйверы, вывести в Навигатор | O318: 0 | P318: 7 | Q318: 2 | R318: 0
A319: 3 | B319: Цели выведены на мониторинг | C319: CBP | D319: Авто | E319: Автокредит | F319: продукт | G319: =VLOOKUP(E319,Лист2!A:B,2,0) -> 0 | H319: 1 | I319: Цели | M319: Регулярное обновление в Навигаторе | N319: Обогащение целей в Навигаторе | O319: 1 | P319: 2 | Q319: 1 | R319: 1
A320: 7 | B320: Факторный анализ — драйверы 1–2 ур. | C320: PC | D320: Развитие продаж в каналах | E320: Телемаркетинг | F320: Канал | G320: 1 | H320: 1 | I320: Цели | K320: В навигаторе (покрытие >90% целей) | M320: Драйверы согласно модели бизнес-планирования выведены в Навигатор | N320: Декомпозировать значения целей на драйверы, вывести в Навигатор | O320: 0 | P320: 7 | Q320: 2 | R320: 0
A321: 5 | B321: Прогноз по целям | C321: CBP | D321: Авто | E321: Автокредит | F321: продукт | G321: =VLOOKUP(E321,Лист2!A:D,4,0) -> 0.5 | H321: 1 | I321: Цели | M321: Прогноз выведен в Навигатор | N321: Сформировать прогнозные значения, вывести в Навигатор | O321: 1 | P321: 8 | Q321: 3 | R321: 1
A322: 7 | B322: Факторный анализ — драйверы 1–2 ур. | C322: PC | D322: Платформа Phygital | E322: Чат | F322: Канал | G322: 1 | H322: 1 | I322: Цели | K322: В навигаторе (покрытие >90% целей) | M322: Драйверы согласно модели бизнес-планирования выведены в Навигатор | N322: Декомпозировать значения целей на драйверы, вывести в Навигатор | O322: 0 | P322: 7 | Q322: 2 | R322: 0
A323: 4 | B323: Факторный анализ — драйверы 1–2 ур. | C323: УБ | D323: ДИиН | E323: БПИФ | F323: продукт | G323: =VLOOKUP(E323,Лист2!A:D,3,0) -> 0 | H323: 1 | I323: Цели | M323: Драйверы согласно модели бизнес-планирования выведены в Навигатор | N323: Декомпозировать значения целей на драйверы, вывести в Навигатор | O323: 1 | P323: 7 | Q323: 2 | R323: 1
A324: 7 | B324: Факторный анализ — драйверы 1–2 ур. | C324: DP | D324: СБОЛ | E324: СБОЛ | F324: Канал | G324: 0 | H324: 1 | I324: Цели | K324: В навигаторе (покрытие >90% целей) | M324: Драйверы согласно модели бизнес-планирования выведены в Навигатор | N324: Декомпозировать значения целей на драйверы, вывести в Навигатор | O324: 0 | P324: 7 | Q324: 2 | R324: 0
A325: 3 | B325: Цели выведены на мониторинг | C325: УБ | D325: ДИиН | E325: БПИФ | F325: продукт | G325: =VLOOKUP(E325,Лист2!A:B,2,0) -> 0.5 | H325: 1 | I325: Цели | M325: Регулярное обновление в Навигаторе | N325: Обогащение целей в Навигаторе | O325: 1 | P325: 2 | Q325: 1 | R325: 1
A326: 7 | B326: Факторный анализ — драйверы 1–2 ур. | C326: DP | D326: СберKids | E326: СберKids | F326: Канал | G326: 0 | H326: 1 | I326: Цели | K326: В навигаторе (покрытие >90% целей) | M326: Драйверы согласно модели бизнес-планирования выведены в Навигатор | N326: Декомпозировать значения целей на драйверы, вывести в Навигатор | O326: 0 | P326: 7 | Q326: 2 | R326: 0
A327: 5 | B327: Прогноз по целям | C327: УБ | D327: ДИиН | E327: БПИФ | F327: продукт | G327: =VLOOKUP(E327,Лист2!A:D,4,0) -> 0.5 | H327: 1 | I327: Цели | M327: Прогноз выведен в Навигатор | N327: Сформировать прогнозные значения, вывести в Навигатор | O327: 1 | P327: 8 | Q327: 3 | R327: 1
A328: 7 | B328: Факторный анализ — драйверы 1–2 ур. | C328: DP | D328: СберИнвестор | E328: СберИнвестор | F328: Канал | G328: 0 | H328: 1 | I328: Цели | K328: В навигаторе (покрытие >90% целей) | M328: Драйверы согласно модели бизнес-планирования выведены в Навигатор | N328: Декомпозировать значения целей на драйверы, вывести в Навигатор | O328: 0 | P328: 7 | Q328: 2 | R328: 0
A329: 4 | B329: Факторный анализ — драйверы 1–2 ур. | C329: УБ | D329: ДББ | E329: Брокерский счет | F329: продукт | G329: =VLOOKUP(E329,Лист2!A:D,3,0) -> 0 | H329: 1 | I329: Цели | M329: Драйверы согласно модели бизнес-планирования выведены в Навигатор | N329: Декомпозировать значения целей на драйверы, вывести в Навигатор | O329: 1 | P329: 7 | Q329: 2 | R329: 1
A330: 7 | B330: Факторный анализ — драйверы 1–2 ур. | C330: DP | D330: Уведомления | E330: Уведомления | F330: Канал | G330: 0 | H330: 1 | I330: Цели | K330: В навигаторе (покрытие >90% целей) | M330: Драйверы согласно модели бизнес-планирования выведены в Навигатор | N330: Декомпозировать значения целей на драйверы, вывести в Навигатор | O330: 0 | P330: 7 | Q330: 2 | R330: 0
A331: 4 | B331: Факторный анализ — драйверы 1–2 ур. | C331: CBP | D331: Товарное кредитование | E331: BNPL | F331: Продукт | G331: 0 | H331: 1 | I331: Цели | M331: Драйверы согласно модели бизнес-планирования выведены в Навигатор | N331: Декомпозировать значения целей на драйверы, вывести в Навигатор | O331: 1 | P331: 7 | Q331: 2 | R331: 1
A332: 7 | B332: Факторный анализ — драйверы 1–2 ур. | C332: CBP | D332: Товарное кредитование | E332: BNPL | F332: Продукт | G332: 0 | H332: 1 | I332: Цели | K332: В навигаторе (покрытие >90% целей) | M332: Драйверы согласно модели бизнес-планирования выведены в Навигатор | N332: Декомпозировать значения целей на драйверы, вывести в Навигатор | O332: 0 | P332: 7 | Q332: 2 | R332: 0
A333: 7 | B333: Факторный анализ — драйверы 1–2 ур. | C333: ДомКлик | D333: Аренда жилья | E333: Долгосрочная Аренда | F333: ДЗО | G333: 0 | H333: 1 | I333: Цели | K333: В навигаторе (покрытие >90% целей) | M333: Драйверы согласно модели бизнес-планирования выведены в Навигатор | N333: Декомпозировать значения целей на драйверы, вывести в Навигатор | O333: 0 | P333: 7 | Q333: 2 | R333: 0
A334: 4 | B334: Факторный анализ — драйверы 1–2 ур. | C334: DB | D334: Государственные продукты и сервисы | E334: Карта Жителя | F334: ДЗО | G334: 0 | H334: 1 | I334: Цели | M334: Драйверы согласно модели бизнес-планирования выведены в Навигатор | N334: Декомпозировать значения целей на драйверы, вывести в Навигатор | O334: 1 | P334: 7 | Q334: 2 | R334: 1
A335: 4 | B335: Факторный анализ — драйверы 1–2 ур. | C335: DB | D335: Платежи | E335: Телеком (Оплата сотовой связи) и сканер QR | F335: ДЗО | G335: 0 | H335: 1 | I335: Цели | M335: Драйверы согласно модели бизнес-планирования выведены в Навигатор | N335: Декомпозировать значения целей на драйверы, вывести в Навигатор | O335: 1 | P335: 7 | Q335: 2 | R335: 1
A336: 7 | B336: Факторный анализ — драйверы 1–2 ур. | C336: DB | D336: Государственные продукты и сервисы | E336: Карта Жителя | F336: ДЗО | G336: 0 | H336: 1 | I336: Цели | K336: В навигаторе (покрытие >90% целей) | M336: Драйверы согласно модели бизнес-планирования выведены в Навигатор | N336: Декомпозировать значения целей на драйверы, вывести в Навигатор | O336: 0 | P336: 7 | Q336: 2 | R336: 0
A337: 7 | B337: Факторный анализ — драйверы 1–2 ур. | C337: DB | D337: Платежи | E337: Телеком (Оплата сотовой связи) и сканер QR | F337: ДЗО | G337: 0 | H337: 1 | I337: Цели | K337: В навигаторе (покрытие >90% целей) | M337: Драйверы согласно модели бизнес-планирования выведены в Навигатор | N337: Декомпозировать значения целей на драйверы, вывести в Навигатор | O337: 0 | P337: 7 | Q337: 2 | R337: 0
A338: 4 | B338: Факторный анализ — драйверы 1–2 ур. | C338: DB | D338: Государственные продукты и сервисы | E338: Госуслуги | F338: Исключить | G338: 0 | H338: 1 | I338: Цели | M338: Драйверы согласно модели бизнес-планирования выведены в Навигатор | N338: Декомпозировать значения целей на драйверы, вывести в Навигатор | O338: 1 | P338: 7 | Q338: 2 | R338: 1
A339: 4 | B339: Факторный анализ — драйверы 1–2 ур. | C339: DB | D339: Социальные и зарплатные решения | E339: Демаркирование карт от зарплатного продукта | F339: Исключить | G339: 0 | H339: 1 | I339: Цели | M339: Драйверы согласно модели бизнес-планирования выведены в Навигатор | N339: Декомпозировать значения целей на драйверы, вывести в Навигатор | O339: 1 | P339: 7 | Q339: 2 | R339: 1
...

Sheet Лист2
B1: Ответ продукта
A2: Продукт | B2: Цели уровня ЛЮ-ЛТ выведены на мониторинг | C2: Драйверы целей | D2: Прогноз по целям | F2: product | G2: факт
B3: в Навигатор 1 балл ( +90% целей) -< 90% 0 баллов (проверка по цифровым следам- учет ЦС) - своя отчетность 0,5 балл все метрики | F3: POS-кредиты | G3: 0 | H3: =VLOOKUP(F3,A:D,2,0) -> 1 | I3: =H3=G3 -> FALSE | K3: product | L3: тип | M3: факт
A4: Продукт | B4: 3 | C4: 4 | D4: 5 | F4: SberPay Вжух | G4: 0 | H4: =VLOOKUP(F4,A:D,2,0) -> 0 | I4: =H4=G4 -> FALSE | K4: POS-кредиты | L4: продукт | M4: =VLOOKUP(K4,A:D,2,0) -> 1
A5: ОСАГО | B5: 0.5 | C5: 0 | D5: 0.5 | F5: Автокредит | G5: 0 | H5: =VLOOKUP(F5,A:D,2,0) -> 0 | I5: =H5=G5 -> FALSE | K5: SberPay Вжух | L5: продукт | M5: =VLOOKUP(K5,A:D,2,0) -> 0
A6: КАСКО | B6: 0.5 | C6: 0.5 | D6: 0.5 | F6: Вклады+НС | G6: 0 | H6: =VLOOKUP(F6,A:D,2,0) -> 0 | I6: =H6=G6 -> FALSE | K6: Автокредит | L6: продукт | M6: =VLOOKUP(K6,A:D,2,0) -> 0
A7: ИнвестКопилка | B7: 1 | C7: 0 | D7: 0.5 | F7: Военная пенсия | G7: 0 | H7: =VLOOKUP(F7,A:D,2,0) -> 0 | I7: =H7=G7 -> FALSE | K7: Вклады+НС | L7: продукт | M7: =VLOOKUP(K7,A:D,2,0) -> 0
A8: СберСова | B8: 0 | C8: 0 | D8: 0 | F8: Дебетовая карта | G8: 0 | H8: =VLOOKUP(F8,A:D,2,0) -> 1 | I8: =H8=G8 -> FALSE | K8: Военная пенсия | L8: продукт | M8: =VLOOKUP(K8,A:D,2,0) -> 0
A9: Залоговое страхование (корпоративное страхование) | B9: 1 | C9: 0 | D9: 0 | F9: ЗЛС | G9: 0 | H9: =VLOOKUP(F9,A:D,2,0) -> 0 | I9: =H9=G9 -> FALSE | K9: Дебетовая карта | L9: продукт | M9: =VLOOKUP(K9,A:D,2,0) -> 1
A10: НСЖ | B10: 1 | C10: 0.5 | D10: 1 | F10: Зарплатный продукт | G10: 0 | H10: =VLOOKUP(F10,A:D,2,0) -> 0 | I10: =H10=G10 -> FALSE | K10: ЗЛС | L10: продукт | M10: =VLOOKUP(K10,A:D,2,0) -> 0
A11: ИСЖ | B11: 1 | C11: 0 | D11: 1 | F11: Как зарплатный | G11: 0 | H11: =VLOOKUP(F11,A:D,2,0) -> 0 | I11: =H11=G11 -> FALSE | K11: Зарплатный продукт | L11: продукт | M11: =VLOOKUP(K11,A:D,2,0) -> 0
A12: Страхование жизни | B12: 1 | C12: 0 | D12: 1 | F12: Пенсионный продукт | G12: 0 | H12: =VLOOKUP(F12,A:D,2,0) -> 0 | I12: =H12=G12 -> FALSE | K12: Как зарплатный | L12: продукт | M12: =VLOOKUP(K12,A:D,2,0) -> 0
A13: Брокерский счет | B13: 1 | C13: 0 | D13: 0.5 | F13: Платежи | G13: 0 | H13: =VLOOKUP(F13,A:D,2,0) -> 1 | I13: =H13=G13 -> FALSE | K13: Пенсионный продукт | L13: продукт | M13: =VLOOKUP(K13,A:D,2,0) -> 0
A14: БПИФ | B14: 0.5 | C14: 0 | D14: 0.5 | F14: СберСова | G14: 0 | H14: =VLOOKUP(F14,A:D,2,0) -> 0 | I14: =H14=G14 -> FALSE | K14: Платежи | L14: продукт | M14: =VLOOKUP(K14,A:D,2,0) -> 1
A15: ЗПИФ | B15: 1 | C15: 0 | D15: 1 | F15: Сценарии оплаты | G15: 0 | H15: =VLOOKUP(F15,A:D,2,0) -> 1 | I15: =H15=G15 -> FALSE | K15: СберСова | L15: продукт | M15: =VLOOKUP(K15,A:D,2,0) -> 0
... A80: Переводы по РФ | B80: 1 | C80: 0 | D80: 0.5 | F80: МВС | G80: 1 | H80: =VLOOKUP(F80,A:D,2,0) -> 1 | I80: =H80=G80 -> FALSE | K80: PB | L80: Сегмент | M80: =VLOOKUP(K80,A:D,2,0) -> 1
A81: Переводы подарков | B81: 0.5 | C81: 0 | D81: 0.5 | K81: МВС | L81: Сегмент | M81: =VLOOKUP(K81,A:D,2,0) -> 1
A82: Оплата улыбкой | B82: 0.5 | C82: 0.5 | D82: 0.5
A83: Торговый Эквайринг | B83: 0 | C83: 0 | D83: 0
A84: Дебетовая карта | B84: 1 | C84: 0.5 | D84: 0
A85: SberPay NFC | B85: 1 | C85: 0 | D85: 0.5
A86: Как зарплатный | B86: 0 | C86: 0 | D86: 0
A87: Сценарии оплаты | B87: 1 | C87: 0 | D87: 0
A88: Интернет-Эквайринг | B88: 0.5 | C88: 0 | D88: 0.5
A89: SberPay Ecom | B89: 1 | C89: 0.5 | D89: 0.5
A90: SberPay Вжух | B90: 0 | C90: 0 | D90: 0
A91: Пенсионный продукт | B91: 0 | C91: 0 | D91: 0
A92: Зарплатный продукт B2B | B92: 0 | C92: 0 | D92: 0.5
A93: СберЧаевые | B93: 0.5 | C93: 0.5 | D93: 0.5
... A99: СберСпасибо | B99: 1 | C99: 0.5 | D99: 0

Sheet Sheet1
A1: 22 | B1: Оповещения по системным сбоям
A2: 22 | B2: Оповещения по системным сбоям
A3: 22 | B3: Оповещения по системным сбоям
A4: 22 | B4: Оповещения по системным сбоям
A5: 22 | B5: Оповещения по системным сбоям
A6: 22 | B6: Оповещения по системным сбоям
A7: 22 | B7: Оповещения по системным сбоям
A8: 22 | B8: Оповещения по системным сбоям
A9: 22 | B9: Оповещения по системным сбоям
A10: 22 | B10: Оповещения по системным сбоям
A11: 22 | B11: Оповещения по системным сбоям
A12: 22 | B12: Оповещения по системным сбоям
... A183: 418 | B183: Оповещения по бизнес-метрикам
