Workbook

Sheet Sheet1
B1: Created | C1: Resolved | D1: Status | E1: Issue key | F1: Issue id | G1: Reporter | H1: Assignee | I1: Resolution | J1: direction | K1: scenario | L1: team
A2: 0 | B2: 08/May/26 12:46 | C2: 14/May/26 14:37 | D2: Resolved | E2: VOTSLHGUWJ-267 | F2: 22854859 | G2: 21427280 | H2: 20652724 | I2: Done | J2: =VLOOKUP(E2,Лист1!A:C,2,0) -> Выгрузки | K2: =VLOOKUP(E2,Лист1!A:C,3,0) -> exports_to_excel | L2: СберЧаевые
A3: 1 | B3: 21/Apr/26 23:02 | C3: 25/Apr/26 01:05 | D3: Resolved | E3: VOTSLHGUWJ-258 | F3: 22642805 | G3: 21427280 | H3: 20652724 | I3: Done | J3: =VLOOKUP(E3,Лист1!A:C,2,0) -> Выгрузки | K3: =VLOOKUP(E3,Лист1!A:C,3,0) -> exports_to_excel | L3: СберЧаевые
A4: 2 | B4: 25/Jun/26 14:11 | C4: 03/Jul/26 18:24 | D4: Cancelled | E4: VOTSLHGUWJ-294 | F4: 23500634 | G4: Salimonov1-EV | H4: 20652724 | I4: Заведено ошибочно | J4: =VLOOKUP(E4,Лист1!A:C,2,0) -> Выгрузки | K4: =VLOOKUP(E4,Лист1!A:C,3,0) -> exports_to_excel | L4: СберЧаевые
A5: 3 | B5: 01/Jun/26 14:29 | C5: 02/Jun/26 18:58 | D5: Resolved | E5: VOTSLHGUWJ-279 | F5: 23158998 | G5: 21427280 | H5: 20652724 | I5: Done | J5: =VLOOKUP(E5,Лист1!A:C,2,0) -> Выгрузки | K5: =VLOOKUP(E5,Лист1!A:C,3,0) -> exports_to_excel | L5: СберЧаевые
A6: 4 | B6: 02/Jun/26 15:35 | C6: 02/Jun/26 18:57 | D6: Resolved | E6: VOTSLHGUWJ-281 | F6: 23180586 | G6: 21427280 | H6: 20652724 | I6: Done | J6: =VLOOKUP(E6,Лист1!A:C,2,0) -> Выгрузки | K6: =VLOOKUP(E6,Лист1!A:C,3,0) -> exports_to_excel | L6: СберЧаевые
A7: 5 | B7: 01/Jun/26 14:52 | C7: 01/Jun/26 18:13 | D7: Resolved | E7: VOTSLHGUWJ-280 | F7: 23159692 | G7: 21427280 | H7: 20652724 | I7: Done | J7: =VLOOKUP(E7,Лист1!A:C,2,0) -> Выгрузки | K7: =VLOOKUP(E7,Лист1!A:C,3,0) -> exports_to_excel | L7: СберЧаевые
A8: 6 | B8: 27/May/26 12:37 | C8: 28/May/26 19:18 | D8: Resolved | E8: VOTSLHGUWJ-275 | F8: 23091321 | G8: 21427280 | H8: 20652724 | I8: Done | J8: =VLOOKUP(E8,Лист1!A:C,2,0) -> Выгрузки | K8: =VLOOKUP(E8,Лист1!A:C,3,0) -> exports_to_excel | L8: СберЧаевые
A9: 7 | B9: 20/May/26 13:50 | C9: 25/May/26 12:08 | D9: Resolved | E9: VOTSLHGUWJ-269 | F9: 22994707 | G9: 21427280 | H9: 20652724 | I9: Done | J9: =VLOOKUP(E9,Лист1!A:C,2,0) -> Отчеты вне BI | K9: =VLOOKUP(E9,Лист1!A:C,3,0) -> excel_reports | L9: СберЧаевые
A10: 8 | B10: 21/May/26 19:40 | C10: 21/May/26 20:20 | D10: Resolved | E10: VOTSLHGUWJ-273 | F10: 23021715 | G10: 21427280 | H10: 20652724 | I10: Done | J10: =VLOOKUP(E10,Лист1!A:C,2,0) -> Выгрузки | K10: =VLOOKUP(E10,Лист1!A:C,3,0) -> exports_to_excel | L10: СберЧаевые
A11: 9 | B11: 20/May/26 15:31 | C11: 21/May/26 16:01 | D11: Resolved | E11: VOTSLHGUWJ-270 | F11: 22997233 | G11: 21427280 | H11: 20652724 | I11: Done | J11: =VLOOKUP(E11,Лист1!A:C,2,0) -> Выгрузки | K11: =VLOOKUP(E11,Лист1!A:C,3,0) -> exports_to_excel | L11: СберЧаевые
A12: 10 | B12: 21/Apr/26 22:48 | C12: 24/Apr/26 11:20 | D12: Resolved | E12: VOTSLHGUWJ-257 | F12: 22642803 | G12: 21427280 | H12: 20652724 | I12: Done | J12: =VLOOKUP(E12,Лист1!A:C,2,0) -> Моделирование | K12: =VLOOKUP(E12,Лист1!A:C,3,0) -> business_planning | L12: СберЧаевые
A13: 11 | B13: 10/Mar/26 14:34 | C13: 10/Apr/26 14:43 | D13: Resolved | E13: VOTSLHGUWJ-220 | F13: 22053566 | G13: 19427267 | H13: 20652724 | I13: Done | J13: =VLOOKUP(E13,Лист1!A:C,2,0) -> Аналитика | K13: =VLOOKUP(E13,Лист1!A:C,3,0) -> customer_experience_analytics | L13: СберЧаевые
... A22: 20 | B22: 26/Feb/26 14:02 | C22: 26/Feb/26 19:26 | D22: Resolved | E22: VOTSLHGUWJ-203 | F22: 21903723 | G22: 21427280 | H22: 20652724 | I22: Done | J22: =VLOOKUP(E22,Лист1!A:C,2,0) -> Выгрузки | K22: =VLOOKUP(E22,Лист1!A:C,3,0) -> exports_to_excel | L22: СберЧаевые
A23: 21 | B23: 23/Jun/26 17:57 | D23: In Progress | E23: VOTSLHGUWJ-293 | F23: 23465779 | G23: 23487514 | H23: 20652724 | J23: =VLOOKUP(E23,Лист1!A:C,2,0) -> Разработка и поддержка BI | K23: =VLOOKUP(E23,Лист1!A:C,3,0) -> dashboard_improvements | L23: СберЧаевые
A24: 22 | B24: 07/Jul/26 17:35 | C24: 10/Jul/26 15:11 | D24: Resolved | E24: VOTSLHGUWJ-299 | F24: 23688184 | G24: Salimonov1-EV | H24: 20652724 | I24: Done | J24: =VLOOKUP(E24,Лист1!A:C,2,0) -> Аналитика | K24: =VLOOKUP(E24,Лист1!A:C,3,0) -> customer_experience_analytics | L24: СберЧаевые
A25: 23 | B25: 19/Jun/26 13:43 | C25: 10/Jul/26 14:14 | D25: Resolved | E25: VOTSLHGUWJ-291 | F25: 23418480 | G25: 23811360 | H25: 20652724 | I25: Done | J25: =VLOOKUP(E25,Лист1!A:C,2,0) -> Моделирование | K25: =VLOOKUP(E25,Лист1!A:C,3,0) -> financial_impact_estimation | L25: СберЧаевые
A26: 24 | B26: 08/Jun/26 18:32 | C26: 10/Jul/26 14:14 | D26: Resolved | E26: VOTSLHGUWJ-289 | F26: 23264642 | G26: 21265084 | H26: 20652724 | I26: Done | J26: =VLOOKUP(E26,Лист1!A:C,2,0) -> Аналитика | K26: =VLOOKUP(E26,Лист1!A:C,3,0) -> customer_experience_analytics | L26: СберЧаевые
A27: 25 | B27: 04/Jun/26 23:11 | D27: In Progress | E27: VOTSLHGUWJ-283 | F27: 23227028 | G27: 21265084 | H27: 20652724 | J27: =VLOOKUP(E27,Лист1!A:C,2,0) -> Аналитика | K27: =VLOOKUP(E27,Лист1!A:C,3,0) -> customer_experience_analytics | L27: СберЧаевые
A28: 26 | B28: 23/Jun/26 17:54 | D28: Backlog | E28: VOTSLHGUWJ-292 | F28: 23465776 | G28: 23487514 | H28: 20652724 | J28: =VLOOKUP(E28,Лист1!A:C,2,0) -> Выгрузки (автоматические) | K28: =VLOOKUP(E28,Лист1!A:C,3,0) -> excel_automatic_reports | L28: СберЧаевые
A29: 27 | B29: 18/Jun/26 21:23 | D29: Backlog | E29: VOTSLHGUWJ-290 | F29: 23408205 | G29: 23487514 | H29: 20652724 | J29: =VLOOKUP(E29,Лист1!A:C,2,0) -> Неизвестно | K29: =VLOOKUP(E29,Лист1!A:C,3,0) -> metric_calculation | L29: СберЧаевые
A30: 28 | B30: 06/Apr/26 11:33 | C30: 25/Apr/26 01:05 | D30: Resolved | E30: VOTSLHGUWJ-249 | F30: 22423885 | G30: 23487514 | H30: 20652724 | I30: Done | J30: =VLOOKUP(E30,Лист1!A:C,2,0) -> Выгрузки | K30: =VLOOKUP(E30,Лист1!A:C,3,0) -> exports_to_excel | L30: СберЧаевые
A31: 29 | B31: 27/May/26 19:08 | D31: Backlog | E31: VOTSLHGUWJ-276 | F31: 23099176 | G31: 21265084 | H31: 20652724 | J31: =VLOOKUP(E31,Лист1!A:C,2,0) -> Неизвестно | K31: =VLOOKUP(E31,Лист1!A:C,3,0) -> metric_calculation | L31: СберЧаевые
A32: 30 | B32: 21/May/26 14:35 | C32: 26/May/26 12:08 | D32: Resolved | E32: VOTSLHGUWJ-272 | F32: 23014767 | G32: Salimonov1-EV | H32: 20652724 | I32: Done | J32: =VLOOKUP(E32,Лист1!A:C,2,0) -> Отчеты вне BI | K32: =VLOOKUP(E32,Лист1!A:C,3,0) -> excel_reports | L32: СберЧаевые
A33: 31 | B33: 21/May/26 10:28 | C33: 21/May/26 14:25 | D33: Resolved | E33: VOTSLHGUWJ-271 | F33: 23008424 | G33: 21265084 | H33: 20652724 | I33: Done | J33: =VLOOKUP(E33,Лист1!A:C,2,0) -> Выгрузки | K33: =VLOOKUP(E33,Лист1!A:C,3,0) -> exports_to_excel | L33: СберЧаевые
A34: 32 | B34: 16/Apr/26 16:34 | C34: 25/Apr/26 03:58 | D34: Resolved | E34: VOTSLHGUWJ-255 | F34: 22577408 | G34: kovalev-evp | H34: 20652724 | I34: Done | J34: =VLOOKUP(E34,Лист1!A:C,2,0) -> Выгрузки | K34: =VLOOKUP(E34,Лист1!A:C,3,0) -> exports_to_excel | L34: СберЧаевые
A35: 33 | B35: 16/Apr/26 16:34 | C35: 25/Apr/26 01:05 | D35: Cancelled | E35: VOTSLHGUWJ-256 | F35: 22577409 | G35: kovalev-evp | H35: 20652724 | I35: Дубликат | J35: =VLOOKUP(E35,Лист1!A:C,2,0) -> Выгрузки | K35: =VLOOKUP(E35,Лист1!A:C,3,0) -> exports_to_excel | L35: СберЧаевые
A36: 34 | B36: 24/Apr/26 09:41 | C36: 25/Apr/26 01:05 | D36: Resolved | E36: VOTSLHGUWJ-259 | F36: 22681834 | G36: 21265084 | H36: 20652724 | I36: Done | J36: =VLOOKUP(E36,Лист1!A:C,2,0) -> Отчеты вне BI | K36: =VLOOKUP(E36,Лист1!A:C,3,0) -> presentations | L36: СберЧаевые
A37: 35 | B37: 06/Apr/26 10:43 | C37: 24/Apr/26 11:19 | D37: Resolved | E37: VOTSLHGUWJ-248 | F37: 22422377 | G37: elsukov-kv | H37: 20652724 | I37: Done | J37: =VLOOKUP(E37,Лист1!A:C,2,0) -> Разработка и поддержка BI | K37: =VLOOKUP(E37,Лист1!A:C,3,0) -> dashboard_improvements | L37: СберЧаевые
A38: 36 | B38: 24/Mar/26 21:10 | C38: 23/Apr/26 17:16 | D38: Resolved | E38: VOTSLHGUWJ-228 | F38: 22256854 | G38: 21427280 | H38: 20652724 | I38: Done | J38: =VLOOKUP(E38,Лист1!A:C,2,0) -> Неизвестно | K38: =VLOOKUP(E38,Лист1!A:C,3,0) -> metric_calculation | L38: СберЧаевые
A39: 37 | B39: 10/Mar/26 10:02 | C39: 23/Apr/26 17:16 | D39: Resolved | E39: VOTSLHGUWJ-219 | F39: 22044710 | G39: 21265084 | H39: 20652724 | I39: Done | J39: =VLOOKUP(E39,Лист1!A:C,2,0) -> Выгрузки | K39: =VLOOKUP(E39,Лист1!A:C,3,0) -> exports_to_excel | L39: СберЧаевые
A40: 38 | B40: 09/Apr/26 11:12 | C40: 10/Apr/26 10:36 | D40: Resolved | E40: VOTSLHGUWJ-252 | F40: 22478248 | G40: Salimonov1-EV | H40: 20652724 | I40: Done | J40: =VLOOKUP(E40,Лист1!A:C,2,0) -> Выгрузки | K40: =VLOOKUP(E40,Лист1!A:C,3,0) -> exports_to_excel | L40: СберЧаевые
A41: 39 | B41: 09/Apr/26 11:35 | C41: 09/Apr/26 16:55 | D41: Resolved | E41: VOTSLHGUWJ-253 | F41: 22479240 | G41: kovalev-evp | H41: 20652724 | I41: Done | J41: =VLOOKUP(E41,Лист1!A:C,2,0) -> Аналитика | K41: =VLOOKUP(E41,Лист1!A:C,3,0) -> customer_experience_analytics | L41: СберЧаевые
A42: 40 | B42: 09/Apr/26 11:58 | C42: 09/Apr/26 16:54 | D42: Resolved | E42: VOTSLHGUWJ-254 | F42: 22480202 | G42: kovalev-evp | H42: 20652724 | I42: Done | J42: =VLOOKUP(E42,Лист1!A:C,2,0) -> Выгрузки | K42: =VLOOKUP(E42,Лист1!A:C,3,0) -> exports_to_excel | L42: СберЧаевые
A43: 41 | B43: 30/Mar/26 08:55 | C43: 09/Apr/26 11:47 | D43: Resolved | E43: VOTSLHGUWJ-230 | F43: 22321538 | G43: 21427280 | H43: 20652724 | I43: Done | J43: =VLOOKUP(E43,Лист1!A:C,2,0) -> Выгрузки | K43: =VLOOKUP(E43,Лист1!A:C,3,0) -> exports_to_excel | L43: СберЧаевые
... A51: 49 | B51: 27/Feb/26 17:04 | C51: 19/Mar/26 13:34 | D51: Cancelled | E51: VOTSLHGUWJ-211 | F51: 21928157 | G51: orlov-vv | H51: 20652724 | I51: Неактуально | J51: =VLOOKUP(E51,Лист1!A:C,2,0) -> Данные и автоматизация | K51: =VLOOKUP(E51,Лист1!A:C,3,0) -> data_marts | L51: СберЧаевые
B52: 2026-06-22T07:41:17.275013Z | C52: 2026-07-20T07:49:25.967667Z | D52: Выполнен | E52: CI8LDDG1KY-7088 | G52: Заика Андрей Михайлович | H52: Заика Андрей Михайлович | I52: Выполнен | J52: Разработка и поддержка BI | K52: dashboard_improvements | L52: Объект Авто
B53: 2026-05-12T08:20:59.738419Z | C53: 2026-07-20T07:49:20.459186Z | D53: Выполнен | E53: CI8LDDG1KY-6903 | G53: Заика Андрей Михайлович | H53: Заика Андрей Михайлович | I53: Выполнен | J53: Разработка и поддержка BI | K53: dashboard_improvements | L53: Объект Авто
B54: 2026-05-31T18:44:28.273358Z | C54: 2026-07-20T07:49:15.361145Z | D54: Выполнен | E54: CI8LDDG1KY-6999 | G54: Чернов Валерий Юрьевич | H54: Заика Андрей Михайлович | I54: Выполнен | J54: Разработка и поддержка BI | K54: dashboard_improvements | L54: Объект Авто
B55: 2026-07-20T07:37:08.637404Z | C55: 2026-07-20T07:37:25.465439Z | D55: Создан | E55: CI8LDDG1KY-7170 | G55: Мурадян Мария Наириевна | H55: Мурадян Мария Наириевна | I55: Создан | J55: Данные и автоматизация | K55: data_marts | L55: Объект Авто
...

Sheet Лист1
A1: issuekey | B1: direction | C1: scenario
A2: VOTSLHGUWJ-200 | B2: Разработка и поддержка BI | C2: dashboard_improvements
A3: VOTSLHGUWJ-283 | B3: Аналитика | C3: customer_experience_analytics
A4: VOTSLHGUWJ-289 | B4: Аналитика | C4: customer_experience_analytics
A5: VOTSLHGUWJ-267 | B5: Выгрузки | C5: exports_to_excel
A6: VOTSLHGUWJ-215 | B6: Аналитика | C6: customer_experience_analytics
A7: VOTSLHGUWJ-223 | B7: Выгрузки | C7: exports_to_excel
A8: VOTSLHGUWJ-255 | B8: Выгрузки | C8: exports_to_excel
A9: VOTSLHGUWJ-225 | B9: Отчеты вне BI | C9: excel_reports
A10: VOTSLHGUWJ-203 | B10: Выгрузки | C10: exports_to_excel
A11: VOTSLHGUWJ-212 | B11: Аналитика | C11: customer_experience_analytics
A12: VOTSLHGUWJ-199 | B12: Аналитика | C12: customer_experience_analytics
... A51: VOTSLHGUWJ-258 | B51: Выгрузки | C51: exports_to_excel
