Workbook

Sheet Лист1
A3: Названия строк | B3: Сумма по полю Ожидание прироста индекса DD, п.п. | C3: аплифт
A4: БПИФ_Воронка оттока | B4: 6 | C4: =VLOOKUP(A:A,'[1]Невыполненные метрики'!$A:$B,2,0) -> #N/A | D4: =IF(B4>C4,"ошибка","") -> #N/A
A5: БПИФ_Воронка привлечения | B5: 5 | C5: =VLOOKUP(A:A,'[1]Невыполненные метрики'!$A:$B,2,0) -> #N/A | D5: =IF(B5>C5,"ошибка","") -> #N/A
A6: БПИФ_Знание ключевых метрик | B6: 3.4 | C6: =VLOOKUP(A:A,'[1]Невыполненные метрики'!$A:$B,2,0) -> #N/A | D6: =IF(B6>C6,"ошибка","") -> #N/A
A7: БПИФ_Цели | B7: 5.9 | C7: =VLOOKUP(A:A,'[1]Невыполненные метрики'!$A:$B,2,0) -> #N/A | D7: =IF(B7>C7,"ошибка","") -> #N/A
A8: Брокерский счет_Гипотезы и инициативы | B8: 1.9 | C8: =VLOOKUP(A:A,'[1]Невыполненные метрики'!$A:$B,2,0) -> #N/A | D8: =IF(B8>C8,"ошибка","") -> #N/A
A9: Брокерский счет_Знание ключевых метрик | B9: 3.4 | C9: =VLOOKUP(A:A,'[1]Невыполненные метрики'!$A:$B,2,0) -> #N/A | D9: =IF(B9>C9,"ошибка","") -> #N/A
A10: Брокерский счет_Цели | B10: 3.3 | C10: =VLOOKUP(A:A,'[1]Невыполненные метрики'!$A:$B,2,0) -> #N/A | D10: =IF(B10>C10,"ошибка","") -> #N/A
A11: ВЗР_Алерты | B11: 2 | C11: =VLOOKUP(A:A,'[1]Невыполненные метрики'!$A:$B,2,0) -> #N/A | D11: =IF(B11>C11,"ошибка","") -> #N/A
A12: ВЗР_Воронка оттока | B12: 4 | C12: =VLOOKUP(A:A,'[1]Невыполненные метрики'!$A:$B,2,0) -> #N/A | D12: =IF(B12>C12,"ошибка","") -> #N/A
A13: ВЗР_Воронка привлечения | B13: 7.9 | C13: =VLOOKUP(A:A,'[1]Невыполненные метрики'!$A:$B,2,0) -> #N/A | D13: =IF(B13>C13,"ошибка","") -> #N/A
A14: ВЗР_Гипотезы и инициативы | B14: 4 | C14: =VLOOKUP(A:A,'[1]Невыполненные метрики'!$A:$B,2,0) -> #N/A | D14: =IF(B14>C14,"ошибка","") -> #N/A
A15: ВЗР_Знание ключевых метрик | B15: 4.5 | C15: =VLOOKUP(A:A,'[1]Невыполненные метрики'!$A:$B,2,0) -> #N/A | D15: =IF(B15>C15,"ошибка","") -> #N/A
... A25: ДСЖ КК_Цели | B25: 3.8 | C25: =VLOOKUP(A:A,'[1]Невыполненные метрики'!$A:$B,2,0) -> #N/A | D25: =IF(B25>C25,"ошибка","") -> #N/A
A26: ДСЖ ПК_Знание ключевых метрик | C26: =VLOOKUP(A:A,'[1]Невыполненные метрики'!$A:$B,2,0) -> #N/A | D26: =IF(B26>C26,"ошибка","") -> #N/A
A27: ДСЖ ПК_Цели | C27: =VLOOKUP(A:A,'[1]Невыполненные метрики'!$A:$B,2,0) -> #N/A | D27: =IF(B27>C27,"ошибка","") -> #N/A
A28: Залоговое страхование (корпоративное страхование)_Воронка оттока | B28: 2.1 | C28: =VLOOKUP(A:A,'[1]Невыполненные метрики'!$A:$B,2,0) -> #N/A | D28: =IF(B28>C28,"ошибка","") -> #N/A
A29: Залоговое страхование (корпоративное страхование)_Воронка привлечения | B29: 2.1 | C29: =VLOOKUP(A:A,'[1]Невыполненные метрики'!$A:$B,2,0) -> #N/A | D29: =IF(B29>C29,"ошибка","") -> #N/A
A30: Залоговое страхование (корпоративное страхование)_Гипотезы и инициативы | B30: 4.3 | C30: =VLOOKUP(A:A,'[1]Невыполненные метрики'!$A:$B,2,0) -> #N/A | D30: =IF(B30>C30,"ошибка","") -> #N/A
A31: Залоговое страхование (корпоративное страхование)_Механики | B31: 4.3 | C31: =VLOOKUP(A:A,'[1]Невыполненные метрики'!$A:$B,2,0) -> #N/A | D31: =IF(B31>C31,"ошибка","") -> #N/A
A32: Залоговое страхование (корпоративное страхование)_Цели | B32: 8.6 | C32: =VLOOKUP(A:A,'[1]Невыполненные метрики'!$A:$B,2,0) -> #N/A | D32: =IF(B32>C32,"ошибка","") -> #N/A
A33: ЗЛС_Алерты | B33: 2 | C33: =VLOOKUP(A:A,'[1]Невыполненные метрики'!$A:$B,2,0) -> #N/A | D33: =IF(B33>C33,"ошибка","") -> #N/A
A34: ЗЛС_Воронка оттока | B34: 6 | C34: =VLOOKUP(A:A,'[1]Невыполненные метрики'!$A:$B,2,0) -> #N/A | D34: =IF(B34>C34,"ошибка","") -> #N/A
A35: ЗЛС_Воронка привлечения | B35: 7 | C35: =VLOOKUP(A:A,'[1]Невыполненные метрики'!$A:$B,2,0) -> #N/A | D35: =IF(B35>C35,"ошибка","") -> #N/A
A36: ЗЛС_Гипотезы и инициативы | B36: 12 | C36: =VLOOKUP(A:A,'[1]Невыполненные метрики'!$A:$B,2,0) -> #N/A | D36: =IF(B36>C36,"ошибка","") -> #N/A
A37: ЗЛС_Знание ключевых метрик | B37: 2.6 | C37: =VLOOKUP(A:A,'[1]Невыполненные метрики'!$A:$B,2,0) -> #N/A | D37: =IF(B37>C37,"ошибка","") -> #N/A
A38: ЗЛС_Механики | B38: 8 | C38: =VLOOKUP(A:A,'[1]Невыполненные метрики'!$A:$B,2,0) -> #N/A | D38: =IF(B38>C38,"ошибка","") -> #N/A
A39: ЗЛС_Цели | B39: 8 | C39: =VLOOKUP(A:A,'[1]Невыполненные метрики'!$A:$B,2,0) -> #N/A | D39: =IF(B39>C39,"ошибка","") -> #N/A
... A95: Общий итог | B95: 417.8 | C95: =VLOOKUP(A:A,'[1]Невыполненные метрики'!$A:$B,2,0) -> #N/A | D95: =IF(B95>C95,"ошибка","") -> #N/A

Sheet УБ
A1: ключ | B1: Продукт | C1: Квартал | D1: Блок для развития | E1: Планируемое мероприятие | F1: Срок исполнения | G1: Ожидание прироста индекса DD, п.п. | H1: Статус | I1: Контактное лицо (ФИО) | J1: Верификация мероприятий Штабом B2C | K1: Аплифт
A2: =CONCATENATE(B2,"_",D2) -> СберСова_Цели | B2: СберСова | C2: 3Q2026 | D2: Цели | E2: Цели выведены в Навигатор | F2: 46230 | G2: 5.7 | H2: Выполнен | I2: Волков Дмитрий Александрович | K2: =IF(A2="","",VLOOKUP(A:A,[2]Свод!$A:$B,2,0)) -> 17.1
B3: СберСова | C3: 3Q2026 | D3: Цели | E3: Цели декомпозированы на драйверы и выведены в Навигатор | F3: 46230 | G3: 5.7 | H3: Выполнен | I3: Волков Дмитрий Александрович | K3: =IF(A3="","",VLOOKUP(A:A,'[1]Невыполненные метрики'!$A:$B,2,0))
B4: СберСова | C4: 3Q2026 | D4: Цели | E4: Сформированы прогнозные значения и выведены в Навигатор | F4: 46230 | G4: 5.7 | H4: Выполнен | I4: Волков Дмитрий Александрович | K4: =IF(A4="","",VLOOKUP(A:A,'[1]Невыполненные метрики'!$A:$B,2,0))
A5: =CONCATENATE(B5,"_",D5) -> СберСова_Знание ключевых метрик | B5: СберСова | C5: 3Q2026 | D5: Знание ключевых метрик | E5: Проработано понимание доступной отчетности и регулярного мониторинга | F5: 46230 | G5: 1.4 | H5: Выполнен | I5: Волков Дмитрий Александрович | K5: =IF(A5="","",VLOOKUP(A:A,[2]Свод!$A:$B,2,0)) -> 1.4
A6: =CONCATENATE(B6,"_",D6) -> СберСова_Воронка привлечения | B6: СберСова | C6: 3Q2026 | D6: Воронка привлечения | E6: Настроена отчетность по воронке привлечения | F6: 46230 | G6: 1.4 | H6: Выполнен | I6: Волков Дмитрий Александрович | K6: =IF(A6="","",VLOOKUP(A:A,[2]Свод!$A:$B,2,0)) -> 5.6
B7: СберСова | C7: 3Q2026 | D7: Воронка привлечения | E7: Отчетность по воронке привлечения обогащена метриками (полнота) | F7: 46230 | G7: 1.4 | H7: Выполнен | I7: Волков Дмитрий Александрович | K7: =IF(A7="","",VLOOKUP(A:A,[2]Свод!$A:$B,2,0))
A8: =CONCATENATE(B8,"_",D8) -> СберСова_Механики | B8: СберСова | C8: 3Q2026 | D8: Механики | E8: Исключить из расчета "Гибкое изменение условий продукта" - Не применимо для продукта | F8: 46295 | G8: 5.7 | H8: В работе | I8: Волков Дмитрий Александрович | J8: Почему? Штаб УБ- нужен коммент и заключение | K8: =IF(A8="","",VLOOKUP(A:A,[2]Свод!$A:$B,2,0)) -> 14.2
B9: СберСова | C9: 3Q2026 | D9: Механики | E9: Механики Cross-sell проработаны | F9: 46265 | G9: 2.8 | H9: В работе | I9: Волков Дмитрий Александрович | K9: =IF(A9="","",VLOOKUP(A:A,[2]Свод!$A:$B,2,0))
A10: =CONCATENATE(B10,"_",D10) -> БПИФ_Знание ключевых метрик | B10: БПИФ | C10: 3Q2026 | D10: Знание ключевых метрик | E10: Проработано понимание доступной отчетности и регулярного мониторинга | F10: 46239 | G10: 1 | H10: Выполнен | I10: Сулейманов Расим Орудж оглы | K10: =IF(A10="","",VLOOKUP(A:A,[2]Свод!$A:$B,2,0)) -> 3.4
A11: =CONCATENATE(B11,"_",D11) -> БПИФ_Знание ключевых метрик | B11: БПИФ | C11: 4Q2026 | D11: Знание ключевых метрик | E11: Совместно со штабом обогатить целями в Навигаторе | F11: 46325 | G11: 2.4 | H11: Ожидание | I11: Сулейманов Расим Орудж оглы | K11: =IF(A11="","",VLOOKUP(A:A,[2]Свод!$A:$B,2,0)) -> 3.4
A12: =CONCATENATE(B12,"_",D12) -> БПИФ_Воронка оттока | B12: БПИФ | C12: 3Q2026 | D12: Воронка оттока | E12: Настроить мониторинг по воронке оттока | F12: 46265 | G12: 2 | H12: В работе | I12: Сулейманов Расим Орудж оглы | K12: =IF(A12="","",VLOOKUP(A:A,[2]Свод!$A:$B,2,0)) -> 8
A13: =CONCATENATE(B13,"_",D13) -> БПИФ_Воронка привлечения | B13: БПИФ | C13: 3Q2026 | D13: Воронка привлечения | E13: Обогатить метриками мониторинг по воронке привлечения | F13: 46265 | G13: 1 | H13: В работе | I13: Сулейманов Расим Орудж оглы | K13: =IF(A13="","",VLOOKUP(A:A,[2]Свод!$A:$B,2,0)) -> 11
A14: =CONCATENATE(B14,"_",D14) -> БПИФ_Воронка привлечения | B14: БПИФ | C14: 3Q2026 | D14: Воронка привлечения | E14: Провести анализ привлечения, выявить точки роста | F14: 46265 | G14: 2 | H14: В работе | I14: Сулейманов Расим Орудж оглы | K14: =IF(A14="","",VLOOKUP(A:A,[2]Свод!$A:$B,2,0)) -> 11
A15: =CONCATENATE(B15,"_",D15) -> БПИФ_Воронка привлечения | B15: БПИФ | C15: 3Q2026 | D15: Воронка привлечения | E15: Сформировать бенчмарки по продуктовым метрикам | F15: 46265 | G15: 2 | H15: В работе | I15: Сулейманов Расим Орудж оглы | K15: =IF(A15="","",VLOOKUP(A:A,[2]Свод!$A:$B,2,0)) -> 11
A16: =CONCATENATE(B16,"_",D16) -> БПИФ_Воронка оттока | B16: БПИФ | C16: 3Q2026 | D16: Воронка оттока | E16: Провести анализ оттока, выявить точки роста | F16: 46265 | G16: 2 | H16: В работе | I16: Сулейманов Расим Орудж оглы | K16: =IF(A16="","",VLOOKUP(A:A,[2]Свод!$A:$B,2,0)) -> 8
A17: =CONCATENATE(B17,"_",D17) -> БПИФ_Воронка оттока | B17: БПИФ | C17: 3Q2026 | D17: Воронка оттока | E17: Сформировать бенчмарки по продуктовым метрикам | F17: 46265 | G17: 2 | H17: В работе | I17: Сулейманов Расим Орудж оглы | K17: =IF(A17="","",VLOOKUP(A:A,[2]Свод!$A:$B,2,0)) -> 8
A18: =CONCATENATE(B18,"_",D18) -> БПИФ_Цели | B18: БПИФ | C18: 4Q2026 | D18: Цели | E18: Совместно со штабом декомпозировать значения целей на драйверы, вывести в Навигатор | F18: 46325 | G18: 3.9 | H18: Ожидание | I18: Сулейманов Расим Орудж оглы | K18: =IF(A18="","",VLOOKUP(A:A,[2]Свод!$A:$B,2,0)) -> 8
A19: =CONCATENATE(B19,"_",D19) -> БПИФ_Цели | B19: БПИФ | C19: 4Q2026 | D19: Цели | E19: Совместно со штабом сформировать прогнозные значения, вывести в Навигатор | F19: 46325 | G19: 2 | H19: Ожидание | I19: Сулейманов Расим Орудж оглы | K19: =IF(A19="","",VLOOKUP(A:A,[2]Свод!$A:$B,2,0)) -> 8
A20: =CONCATENATE(B20,"_",D20) -> Брокерский счет_Знание ключевых метрик | B20: Брокерский счет | C20: Q32026 | D20: Знание ключевых метрик | E20: Совместно со Штабом УБ проведена синхронизация отчетности и знаний продукта | F20: 46356 | G20: 3.4 | H20: В работе | I20: Аганина Яна Анатольевна | J20: Недостаточно запланированных мероприятий, т.к. ожидаемого прироста индекса не хватит для перехода на уровень "Зрелые" | K20: =IF(A20="","",VLOOKUP(A:A,[2]Свод!$A:$B,2,0)) -> 3.4
A21: =CONCATENATE(B21,"_",D21) -> Брокерский счет_Цели | B21: Брокерский счет | C21: Q32026 | D21: Цели | E21: Совместно со Штабом УБ проведена синхронизация и вывод драйверов целей ЛТ/ЛЮ | F21: 46356 | G21: 3.3 | H21: В работе | I21: Аганина Яна Анатольевна | K21: =IF(A21="","",VLOOKUP(A:A,[2]Свод!$A:$B,2,0)) -> 5.7
A22: =CONCATENATE(B22,"_",D22) -> Брокерский счет_Гипотезы и инициативы | B22: Брокерский счет | C22: Q32026 | D22: Гипотезы и инициативы | E22: Запустить A/B-тестирование открытия счета | F22: 46356 | G22: 1.9 | H22: В работе | I22: Аганина Яна Анатольевна | K22: =IF(A22="","",VLOOKUP(A:A,[2]Свод!$A:$B,2,0)) -> 9.5
A23: =CONCATENATE(B23,"_",D23) -> ВЗР_Знание ключевых метрик | B23: ВЗР | C23: 3Q2026 | D23: Знание ключевых метрик | E23: Объем целевого рынка в России | F23: Проведение встречи после отправки ДК (до 14.08) для синхронизации и согласования логики расчетов | G23: 4.5 | H23: В работе | I23: Мартусенко Игорь Викторович, Архипова Марина Алексеевна | J23: Ожидание прироста суммарно по продукту нереалистично и сверхдостаточно (103%) | K23: =IF(A23="","",VLOOKUP(A:A,[2]Свод!$A:$B,2,0)) -> 4.6
E24: Текущее значение в дешборде 0% | K24: =IF(A24="","",VLOOKUP(A:A,'[1]Невыполненные метрики'!$A:$B,2,0))
E25: Мероприятие: синхронизация по логике расчета | K25: =IF(A25="","",VLOOKUP(A:A,'[1]Невыполненные метрики'!$A:$B,2,0))
E26: Как считает продуктовая команда: | K26: =IF(A26="","",VLOOKUP(A:A,'[1]Невыполненные метрики'!$A:$B,2,0))
E27: Согласно оф.данным Росстата (https://rosstat.gov.ru/statistics/turizm) | K27: =IF(A27="","",VLOOKUP(A:A,'[1]Невыполненные метрики'!$A:$B,2,0))
E28: число выездных туристских поездок граждан России в зарубежные страны за 1q26 = 5,63 млн. Т.о в год : 5,63*4 = 22,5 млн. поездок. Это объем целевого рынка в России. | K28: =IF(A28="","",VLOOKUP(A:A,'[1]Невыполненные метрики'!$A:$B,2,0))
K29: =IF(A29="","",VLOOKUP(A:A,'[1]Невыполненные метрики'!$A:$B,2,0))
E30: Объем целевого рынка в Сбере | K30: =IF(A30="","",VLOOKUP(A:A,'[1]Невыполненные метрики'!$A:$B,2,0))
E31: Текущее значение в дешборде 0% | K31: =IF(A31="","",VLOOKUP(A:A,'[1]Невыполненные метрики'!$A:$B,2,0))
E32: Мероприятие: синхронизация по логике расчета | K32: =IF(A32="","",VLOOKUP(A:A,'[1]Невыполненные метрики'!$A:$B,2,0))
E33: Как считает продуктовая команда: | K33: =IF(A33="","",VLOOKUP(A:A,'[1]Невыполненные метрики'!$A:$B,2,0))
E34: 1) Посчитаем частоту поездок в год на 1 россиянина: 22,5 млн. поездок / 146 млн. чел. = 15,4 %. | K34: =IF(A34="","",VLOOKUP(A:A,'[1]Невыполненные метрики'!$A:$B,2,0))
E35: 2) Применим частоту поездок в год на 1 россиянина к объему активных пользователей Сбера: 100 млн. активн.польз * 15,4% = 15,4 млн. Далее вычитаем 2,6 млн. владельцы ПУ, где включена страховка | K35: =IF(A35="","",VLOOKUP(A:A,'[1]Невыполненные метрики'!$A:$B,2,0))
E36: Т.о. объем целевого рынка в Сбере = 12,8 млн. поездок | K36: =IF(A36="","",VLOOKUP(A:A,'[1]Невыполненные метрики'!$A:$B,2,0))
K37: =IF(A37="","",VLOOKUP(A:A,'[1]Невыполненные метрики'!$A:$B,2,0))
E38: Клиенты с продуктом | K38: =IF(A38="","",VLOOKUP(A:A,'[1]Невыполненные метрики'!$A:$B,2,0))
E39: Текущее значение в дешборде 0% | K39: =IF(A39="","",VLOOKUP(A:A,'[1]Невыполненные метрики'!$A:$B,2,0))
E40: Мероприятие: синхронизация по логике расчета | K40: =IF(A40="","",VLOOKUP(A:A,'[1]Невыполненные метрики'!$A:$B,2,0))
...

Sheet ВЗР
A1: Продукт | B1: Квартал | C1: Блок для развития | D1: Планируемое мероприятие | E1: Срок исполнения | F1: Ожидание прироста индекса DD, п.п. | G1: Статус | H1: Контактное лицо (ФИО) | I1: Верификация мероприятий Штабом B2C | J1: Текущий индекс DD | K1: Прогноз индекса DD
A2: ВЗР | B2: 3Q2026 | C2: Знание ключевых метрик | D2: Объем целевого рынка в России (+0,8 п.п.) | E2: Данные уже имеются | F2: +4,48 п.п. | G2: Ожидание | H2: Мартусенко Игорь Викторович | K2: 0.008
D3: Текущее значение в дешборде 0% | H3: Архипова Марина Алексеевна
D4: Просьба применить значения, из расчета описанного ниже.
D5: Продукт "Страхование путешественников" не может быть применим абсолютно к каждому клиенту.
D6: Продукт применим только к клиенту, который отправляется в путешествие.
D7: Как считаем:
D8: 1. Согласно оф.данным Росстата (https://rosstat.gov.ru/statistics/turizm)
D9: число выездных туристских поездок граждан России в зарубежные страны за 1q26 = 5,63 млн. Т.о в год : 5,63*4 = 22,5 млн. поездок.
D10: 2. Рынок страхования:
D11: Согласно данным от ЦБ (информации из страховой компании) , Общий объем рынка страховых премий = 5,6 млрд. за 3 мес. 2026г.
D12: Таким образом за год общий объем рынка в России = (5,6 млрд. * 4) / ср.чек (2 900р.) = 7,7 млн. полисов (не клиентов). Доля Сбербанка в рынке ВЗР = 20%
D14: Объем целевого рынка в Сбере (+0,8 п.п.) | K14: 0.008
D15: Текущее значение в дешборде 0%
D16: Просьба применить значения, из расчета описанного ниже.
D17: Как считаем:
D18: Берем долю Сбербанка в рынке ВЗР (оф. данные от СберСтрахования полученной от ЦБ) = 20% и считаем от объема целевого рынка в РФ (7,7 млн. полисов)
D19: 7,7 млн полисов * 20% = 1,54 млн. полисов.
D21: Клиенты с продуктом (+0,8 п.п.) | K21: 0.008
D22: Текущее значение в дешборде 0%
D23: Просьба применить значения, из расчета описанного ниже.
D24: Факт оформленных полисов за период с янв.26 по июль 26 = 115 257 шт. ; План по продажам полисов с авг.26 по дек.26 = 82 000 шт.; ИТОГО клиентов с продуктом за год = 195 257
D26: MAU продукта (+0,8 п.п.) | K26: 0.008
D27: Просьба применить значения, из расчета описанного ниже.
D28: Определение MAU, которым руководствовались - количество уникальных пользователей, которые совершили хотя бы одно целевое действие на протяжении 30 дней.
D29: Целевое действие = мы считаем переход на карточку продукта, потому что если смотреть целевое действие = оформление продукта, то это будет та же самая цифра, что и "Клиенты с продуктом"
D30: Тогда MAU = 100 000 клиентов. Это кол-во уник. клиентов которые перешли на карточку продукта в МП СБОЛ.
D32: Знание продуктов спутников (+0,4 п.п.) | K32: 0.004
D33: Текущее значение в дешборде 50%.
D34: Просьба учесть комментарий: при ответе был указан только один спутник - "СберПрайм". В новом опросе будет указан дополнительный спутник (продукт "СберСПАСИБО" и продукт "справка для визы").
D35: Продукт продается только в СБОЛ. Продукт не реализуется в сети ВСП. Продукт является базовой (ситуативной) потребности. Продукт стоит на витрине продукта "Справки и выписки" -> заказ справок для визы.
D36: Так же продукт выведен в сценарии сервиса "ограничения на выезд за границу" - "аресты и вызскания"
D37: Продукт представлен в разделе "Для жизни" - под.раздлеы: путешествие, Отели, За рубеж
D39: Знание об отчетности в Навигаторе (+1 п.п.) | K39: 0.01
D40: Текущее значение в дешборде 50%.
D41: Просьба учесть дополнительную ссылку в навигаторе.
D42: Ссылка на Дэшборд в навигаторе
D43: https://navigator.sigma.sbrf.ru/gdash/1000000720?prod=%D0%A1%D1%82%D1%80%D0%B0%D1%85%D0%BE%D0%B2%D0%B0%D0%BD%D0%B8%D0%B5%20%D0%BF%D1%83%D1%82%D0%B5%D1%88%D0%B5%D1%81%D1%82%D0%B2%D0%B5%D0%BD%D0%BD%D0%B8%D0%BA%D0%BE%D0%B2%20-%20%D0%BA%D1%80%D0%BE%D0%BC%D0%B5%20%D0%9F%D0%A3&period=3
A46: ВЗР | B46: 3Q2026 | C46: Воронка привлечения | D46: Настроена отчетность по воронке привлечения (+1 п.п) | E46: Данные уже имеются | F46: +8 п.п. | G46: Ожидание | H46: Мартусенко Игорь Викторович
D47: Текущее значение в дешборде 50%. | H47: Архипова Марина Алексеевна
...

Sheet DB
B1: Продукт | C1: Квартал | D1: Блок для развития | E1: Планируемое мероприятие | F1: Срок исполнения | G1: Ожидание прироста индекса DD, п.п. | H1: Статус | I1: Контактное лицо (ФИО) | J1: Верификация мероприятий Штабом B2C | K1: Текущий индекс DD | L1: Прогноз индекса DD | M1: Аплифт
A2: =CONCATENATE(B2,"_",D2) -> SberPay NFC_Знание ключевых метрик | B2: SberPay NFC | C2: 4Q2026 | D2: Знание ключевых метрик | E2: 1. Проверить воронку TAM/SAM (+3пп) | F2: 46326 | G2: 3 | I2: Маманков Максим | K2: 0.77 | L2: =SUM(K2,G2:G3/100) -> 0.8 | M2: =VLOOKUP(A:A,[2]Свод!$A:$B,2,0) -> 3
A3: =CONCATENATE(B2,"_",D3) -> SberPay NFC_Цели | D3: Цели | E3: 2. Вывести прогноз в Навигатор (+2,3пп) | G3: 2.3 | M3: =VLOOKUP(A:A,[2]Свод!$A:$B,2,0) -> 6.9
B4: Переводы по РФ | E4: мероприятия не запланированы, т.к. Зрелая команда | I4: Невелич Дмитрий | K4: 0.68 | L4: =SUM(K4,G4/100) -> 0.68
A5: =CONCATENATE(B5,"_",D5) -> Оплата улыбкой_Знание ключевых метрик | B5: Оплата улыбкой | C5: 3Q2026 | D5: Знание ключевых метрик | E5: Проверить воронку TAM/SAM | F5: 46295 | G5: 2.5 | I5: Терсков Павел | K5: 0.66 | L5: =SUM(K5,SUM(G5:G6)/100) -> 0.71 | M5: =VLOOKUP(A:A,[2]Свод!$A:$B,2,0) -> 2.5
A6: =CONCATENATE(B5,"_",D6) -> Оплата улыбкой_Гипотезы и инициативы | C6: 4Q2026 | D6: Гипотезы и инициативы | E6: Повысить долю исследований >=40% | F6: 46356 | G6: 2.5 | M6: =VLOOKUP(A:A,[2]Свод!$A:$B,2,0) -> 7.6
B7: Торговый Эквайринг | E7: мероприятия не запланированы, т.к. Зрелая команда | I7: Фисенко Владислав | K7: 0.63 | L7: =SUM(K7,G7/100) -> 0.63
A8: =CONCATENATE(B8,"_",D8) -> Кредитные карты_Знание ключевых метрик | B8: Кредитные карты | C8: 3Q2026 | D8: Знание ключевых метрик | E8: Проверить воронку TAM/SAM, рассказать ВП о дэшах (+3,7пп) Штабу B2C: 1. Учесть июньские DD (+3,8пп) 2. Скорректировать знание продуктов-спутников (ВП ответил) | F8: 46295 | G8: 3.7 | I8: Кононов Иван | K8: 0.6 | L8: =SUM(K8,G8/100) -> 0.637 | M8: =VLOOKUP(A:A,[2]Свод!$A:$B,2,0) -> 3.8
A9: =CONCATENATE(B9,"_",D9) -> Дебетовая карта_Знание ключевых метрик | B9: Дебетовая карта | D9: Знание ключевых метрик | E9: Проверить воронку TAM/SAM (+1,7пп) Штабу B2C: 1. Исключить блок бенчмарков, нерелевантно по словам ВП (+1,9пп) | F9: 46295 | G9: 1.7 | I9: Яковлев Сергей | K9: 0.57 | L9: =SUM(K9,G9/100) -> 0.587 | M9: =VLOOKUP(A:A,[2]Свод!$A:$B,2,0) -> 1.8
B10: Сценарии оплаты | E10: Исключить из оценки и расчета | I10: Балцану Михаил | K10: 0.51
B11: SberPay Ecom | E11: не нашли опросник | I11: Ведерникова Юлия, Кравченко Тимофей | K11: 0.44 | L11: =SUM(K11,G11/100) -> 0.44
A12: =CONCATENATE(B12,"_",D12) -> Платежи_Цели | B12: Платежи | C12: 4Q2026 | D12: Цели | E12: Вывести прогноз в Навигатор (+4пп) Штабу B2C: 1. Объединить Сценарии оплаты и Платежи (+10пп) 2. Засчитать DD по выставленным счетам (+4пп) 3. Засчитать наличие бенчмарков (+4пп) | F12: 46326 | G12: 4 | I12: Балцану Михаил, Юрковский Роберт | K12: 0.41 | L12: =SUM(K12,G12/100) -> 0.45 | M12: =VLOOKUP(A:A,[2]Свод!$A:$B,2,0) -> 7.6
A13: =CONCATENATE(B13,"_",D13) -> SberPay Вжух_ | B13: SberPay Вжух | E13: не нашли опросник | I13: Дрожжина Валентина | K13: 0.4 | L13: =SUM(K13,G13/100) -> 0.4
A14: =CONCATENATE(B14,"_",D14) -> Детская карта_ | B14: Детская карта | C14: 3Q2026 | E14: 1. Подготовить DD (+3,9 пп) | F14: 46295 | G14: 3.9 | I14: Фомин Андрей | K14: 0.38 | L14: =SUM(K14,G14/100) -> 0.419 | M14: =VLOOKUP(A:A,[2]Свод!$A:$B,2,0) -> #N/A
A15: =CONCATENATE(B15,"_",D15) -> СберЧаевые_ | B15: СберЧаевые | E15: не нашли опросник | I15: Губин Юрий | K15: 0.38 | L15: =SUM(K15,G15/100) -> 0.38
A16: =CONCATENATE(B16,"_",D16) -> Трансграничные переводы_ | B16: Трансграничные переводы | C16: 4Q2026 | E16: Подготовить DD (+4,2пп) Штабу B2C: 1. Исключить блок бенчмарков, нерелевантно по словам ВП (+2,1пп) 2. Цели выведены в Навигатор, дэшборд Переводы за рубеж (+4,2пп) | F16: 46326 | G16: 4.2 | I16: Сидорова Ксения | K16: 0.38 | L16: =SUM(K16,G16/100) -> 0.422 | M16: =VLOOKUP(A:A,[2]Свод!$A:$B,2,0) -> #N/A
B17: Переводы подарков | E17: Исключить из оценки и расчета | I17: Невелич Дмитрий | K17: 0.37
B18: Интернет-Эквайринг | E18: не нашли опросник | I18: Кравченко Тимофей | K18: 0.37 | L18: =SUM(K18,G18/100) -> 0.37
B19: Как зарплатный | E19: Исключить из оценки и расчета | I19: Киселева Мария, Иванов Михаил | K19: 0.37
B20: Школьные сервисы | E20: Исключить из оценки и расчета | I20: Торукало Анна | K20: 0.36
A21: =CONCATENATE(B21,"_",D21) -> Трансграничный эквайринг_ | B21: Трансграничный эквайринг | C21: 4Q2026 | E21: Подготовить DD (+4,8пп) | F21: 46356 | G21: =4.8+4.9+0.5 -> 10.2 | I21: Забегаев Михаил | K21: 0.34 | L21: =SUM(K21,G21/100) -> 0.442 | M21: =VLOOKUP(A:A,[2]Свод!$A:$B,2,0) -> #N/A
A22: =CONCATENATE(B21,"_",D22) -> Трансграничный эквайринг_Цели | D22: Цели | E22: Вывести дэшборд с основными показателями (+4,9пп) | M22: =VLOOKUP(A:A,[2]Свод!$A:$B,2,0) -> 14.4
A23: =CONCATENATE(B21,"_",D23) -> Трансграничный эквайринг_Знание ключевых метрик | D23: Знание ключевых метрик | E23: Рассказать про продукты-спутники (+0,5пп) | M23: =VLOOKUP(A:A,[2]Свод!$A:$B,2,0) -> 0.5
B24: Пенсионный продукт | E24: не нашли опросник | I24: Мерзликин Иван | K24: 0.33 | L24: =SUM(K24,G24/100) -> 0.33
B25: Зарплатный продукт | E25: не нашли опросник | I25: Шматов Никита | K25: 0.3 | L25: =SUM(K25,G25/100) -> 0.3
B26: Военная пенсия | E26: Исключить из оценки и расчета | I26: Мерзликин Иван | K26: 0.28
B27: Транспортный эквайринг | E27: Исключить из оценки и расчета | I27: Паренков Алексей | K27: 0.24
K28: 0.44

Sheet СВР
B1: Продукт | C1: Квартал | D1: Блок для развития | E1: Планируемое мероприятие | F1: Срок исполнения | G1: Ожидание прироста индекса DD, п.п. | H1: Статус | I1: Контактное лицо (ФИО) | J1: Верификация мероприятий Штабом B2C | K1: Текущий индекс DD | L1: Прогноз индекса DD | M1: Аплифт
A2: =CONCATENATE(B2,"_",D2) -> Вклады+НС_Воронка привлечения | B2: Вклады+НС | C2: 4Q | D2: Воронка привлечения | E2: пилотирование расширения воронки по черновикам | F2: сентябрь - пилот октябрь - корректировка триггера и рост метрики | G2: 3.8 | H2: запланированы пилоты | I2: Колесников Денис Олегович | K2: 0.37 | L2: =K2+SUM(G2:G4)/100 -> 0.465 | M2: =VLOOKUP(A:A,[2]Свод!$A:$B,2,0) -> 10.5
A3: =CONCATENATE(B2,"_",D3) -> Вклады+НС_Воронка привлечения | C3: 3Q | D3: Воронка привлечения | E3: запуск успешных пилотов через SS | F3: 3Q | G3: 1.9 | H3: запланированы пилоты | I3: Колесников Денис Олегович | M3: =VLOOKUP(A:A,[2]Свод!$A:$B,2,0) -> 10.5
A4: =CONCATENATE(B2,"_",D4) -> Вклады+НС_CX Score | C4: 4Q | D4: CX Score | E4: доработка и уточнение методологии расчетов | F4: 4Q | G4: 3.8 | H4: В работе | I4: Романенко Анна Вадимовна | M4: =VLOOKUP(A:A,[2]Свод!$A:$B,2,0) -> #N/A
A5: =CONCATENATE(B5,"_",D5) -> Потребительский кредит_Знание ключевых метрик | B5: Потребительский кредит | C5: 3Q2026 | D5: Знание ключевых метрик | E5: Гемба для команды по отчетности в Навигаторе (совместно со штабом: Герасимова Ольга) | F5: 46295 | G5: 1 | H5: В работе | I5: Ильина Ольга | K5: 0.77 | L5: =K5+SUM(G5:G7)/100 -> 0.824 | M5: =VLOOKUP(A:A,[2]Свод!$A:$B,2,0) -> 3.4
A6: =CONCATENATE(B5,"_",D6) -> Потребительский кредит_Цели | C6: 3Q2026 | D6: Цели | E6: Вывод планов и прогнозов в мастер-дэш по КПЭ ЛТ и Картине недели | F6: 46295 | G6: 2 | H6: В работе | I6: Таранов Александр | M6: =VLOOKUP(A:A,[2]Свод!$A:$B,2,0) -> 6
A7: =CONCATENATE(B5,"_",D7) -> Потребительский кредит_Знание ключевых метрик | C7: 4Q2026 | D7: Знание ключевых метрик | E7: Гемба для команды по ключевым метрикам, в т.ч. объем целевого рынка России и Сбера | F7: 46326 | G7: 2.4 | H7: В работе | I7: Ильина Ольга | M7: =VLOOKUP(A:A,[2]Свод!$A:$B,2,0) -> 3.4
A8: =CONCATENATE(B8,"_",D8) -> Образовательный кредит_Воронка оттока | B8: Образовательный кредит | C8: Q3 | D8: Воронка оттока | E8: Проведение комплексного анализа воронки оттока | F8: до 30.08 | G8: 2.2 | H8: Готово | I8: Семенов Тимофей Александрович | K8: 0.58 | L8: =K8+SUM(G8:G10)/100 -> 0.686 | M8: =VLOOKUP(A:A,[2]Свод!$A:$B,2,0) -> 2.2
A9: =CONCATENATE(B9,"_",D9) -> Образовательный кредит_Гипотезы и инициативы | C9: Q4 | D9: Гипотезы и инициативы | E9: Сформировать перечень инициатив | F9: до 31.12 | G9: 4.4 | H9: Запланировано | I9: Семенов Тимофей Александрович | M9: =VLOOKUP(A:A,[2]Свод!$A:$B,2,0) -> 11
A10: =CONCATENATE(B10,"_",D10) -> Образовательный кредит_Цели | C10: Q4 | D10: Цели | E10: Прогноз по целям | F10: до 31.12 | G10: 4 | H10: Запланировано | I10: Семенов Тимофей Александрович | M10: =VLOOKUP(A:A,[2]Свод!$A:$B,2,0) -> 8.8
A11: =CONCATENATE(B11,"_",D11) -> Кредитный потенциал_Алерты | B11: Кредитный потенциал | C11: Q4 | D11: Алерты | E11: Оповещения по бизнес-метрикам: подключение светофора (совместно со штабом: Герасимова Ольга) Оповещения по системным сбоям: Гемба для команды по отчетности в Навигаторе (совместно со штабом: Герасимова Ольга) | F11: 46326 | G11: 5 | H11: в работе | I11: Малышева Анастасия, Тупиков Павел | K11: 0.66 | L11: =K11+SUM(G11:G14)/100 -> 0.835 | M11: =VLOOKUP(A:A,[2]Свод!$A:$B,2,0) -> 5
A12: =CONCATENATE(B11,"_",D12) -> Кредитный потенциал_Цели | C12: Q4 | D12: Цели | E12: Факторный анализ - драйверы 1-2 ур.: Гемба для команды по отчетности в Навигаторе (совместно со штабом: Герасимова Ольга) Прогноз по целям: Вывод прогнозов в мастер-дэш по КПЭ ЛТ | F12: 46326 | G12: 5 | H12: в работе | I12: Родина Марина, Кистерский Сергей | M12: =VLOOKUP(A:A,[2]Свод!$A:$B,2,0) -> 5
A13: =CONCATENATE(B11,"_",D13) -> Кредитный потенциал_Воронка привлечения | C13: Q4 | D13: Воронка привлечения | E13: Проведение комплексного анализа воронки привлечения: Гемба для команды по анализу (совместно со штабом: Герасимова Ольга) | F13: 46326 | G13: 2.5 | H13: в работе | I13: Кистерский Сергей | M13: =VLOOKUP(A:A,[2]Свод!$A:$B,2,0) -> 6.3
A14: =CONCATENATE(B11,"_",D14) -> Кредитный потенциал_Механики | C14: Q4 | D14: Механики | E14: Гемба для команды по механикам (совместно со штабом: Герасимова Ольга) | F14: 46326 | G14: 5 | H14: в работе | I14: Родина Марина | M14: =VLOOKUP(A:A,[2]Свод!$A:$B,2,0) -> 5
A15: =CONCATENATE($B$15,"_",D15) -> Объект Авто_Воронка привлечения | B15: Объект Авто | C15: 3-4 кв | D15: Воронка привлечения | E15: Организован системный кампейнинг для привлечения и удержания пользователей Объекта Авто - Налажена регулярная работа через селф-сервис Юнита + Разовые охватные кампании | F15: с 01.06.2026 организован | G15: 6.5 | H15: в работе | I15: Кравченко Анна | K15: 0.66 | L15: =K15+SUM(G15:G18)/100 -> 0.834 | M15: =VLOOKUP(A:A,[2]Свод!$A:$B,2,0) -> 13.2
A16: =CONCATENATE($B$15,"_",D16) -> Объект Авто_Цели | D16: Цели | E16: Добавлены цели CSI ОМ Авто, MAU - Цели Н.Русовой выведены на поверхность Мастер-Дэша СВ Вывод прогноза по целям в Навигатор - Делаем постановку задачи для добавление метрик в Навигатор | F16: 3-4 кв | G16: 4.4 | H16: в работе | I16: Мищенко и Кравченко | M16: =VLOOKUP(A:A,[2]Свод!$A:$B,2,0) -> 8.7
A17: =CONCATENATE($B$15,"_",D17) -> Объект Авто_Гипотезы и инициативы | D17: Гипотезы и инициативы | E17: Сформировать перечень инициатив на 2027 год - Проводим оценку предложенных инициатив для включения в бэклог | F17: 3-4 кв | G17: 4.3 | H17: в работе | I17: Мищенко и Кравченко | M17: =VLOOKUP(A:A,[2]Свод!$A:$B,2,0) -> 12.9
A18: =CONCATENATE($B$15,"_",D18) -> Объект Авто_Алерты | D18: Алерты | E18: Вывод на мониторинг отклонений по процессам - Сформированы отчеты по системным отлонениям на базе PM для дальнейшего вывода на оперативный ДЭШ | F18: 3-4 кв | G18: 2.2 | H18: в работе | I18: Мищенко и Кравченко | M18: =VLOOKUP(A:A,[2]Свод!$A:$B,2,0) -> 6.5
A19: =CONCATENATE($B$19,"_",D19) -> Автокредит_Воронка привлечения | B19: Автокредит | C19: Q3 | D19: Воронка привлечения | E19: Черновики в СБОЛ >=70% Покрытие черновиков коммуникациями - запуск коммуникации по брошенным корзинам | F19: с 01.09.2026 организован | G19: 4.3 | H19: в работе | I19: Кравченко Анна | K19: 0.4 | L19: =K19+SUM(G19:G21)/100 -> 0.637 | M19: =VLOOKUP(A:A,[2]Свод!$A:$B,2,0) -> 12
A20: =CONCATENATE($B$19,"_",D20) -> Автокредит_Механики | C20: Q3 | D20: Механики | E20: Гибкое изменение условий продукта: Следующие опции запущены: размер перв. взноса, переменная ставка внутри жизни кредита Cross-sell: Инициативы и ответы отразили в системе Допродажи (up-sell): альтернативное решение с учетом предоставления документов (больше сумма при условии предоставления подтверждения дохода), запуск Опции авто в Прайм | F20: реализовано 3-4 кв. Альтернативное решение реализовано, опция авто - окт.2026 | G20: 12.9 | H20: запущено | I20: Бажанова Елена, Логанов Максим (страховые допы и Прайм), Мищенко Максим (допы из объекта), Логанов Максим | M20: =VLOOKUP(A:A,[2]Свод!$A:$B,2,0) -> 12.9
A21: =CONCATENATE($B$19,"_",D21) -> Автокредит_Воронка оттока | C21: Q4 | D21: Воронка оттока | E21: Запуск работы с оттоком - отдельным сегментам клиентов, которым до погашения автокредита осталось 6 и менее месяцев: кампейнинг с предложением стратегии замены авто и новых условий кредита Настроить воронку оттока | F21: ноя.26-дек.26 | G21: 6.5 | H21: в работе | I21: Кравченко Анна | M21: =VLOOKUP(A:A,[2]Свод!$A:$B,2,0) -> 15.2
A22: =CONCATENATE($B$22,"_",D22) -> POS-кредиты_Воронка привлечения | B22: POS-кредиты | C22: 3-4 квартал | D22: Воронка привлечения | E22: Анализ: Проведение комплексного анализа воронки привлечения | F22: 46266 | G22: 2.1 | H22: Выполнено | I22: Переведенцева Ольга | K22: 0.54 | L22: =K22+SUM(G22:G25)/100 -> 0.639 | M22: =VLOOKUP(A:A,[2]Свод!$A:$B,2,0) -> 9.4
A23: =CONCATENATE($B$22,"_",D23) -> POS-кредиты_Воронка привлечения | D23: Воронка привлечения | E23: Кампейнинг - запуски кампаний за квартал: 1) Информирование клиента о возможности взять доп.кред.продукт при выдачи POS кредита 2) Информирование клиента о возможности оформить доп. кредит при высоких чеках за покупки. | F23: 3-4 квартал | G23: 2.1 | H23: в работе | I23: Мосягина Оксана | M23: =VLOOKUP(A:A,[2]Свод!$A:$B,2,0) -> 9.4
A24: =CONCATENATE($B$22,"_",D24) -> POS-кредиты_Цели | D24: Цели | E24: Вывод Прогноза по части целей в Навигатор (объем выдач POS) | F24: 3-4 квартал | G24: 4.1 | H24: в работе | I24: Герасимова Ольга, Смирнов Илья | M24: =VLOOKUP(A:A,[2]Свод!$A:$B,2,0) -> 8.2
A25: =CONCATENATE($B$22,"_",D25) -> POS-кредиты_Знание ключевых метрик | D25: Знание ключевых метрик | E25: Объем целевого рынка в России: выведено в Навигатор Объем целевого рынка в Сбере: выведено в Навигатор | F25: 46266 | G25: 1.6 | H25: Выполнено | I25: Смирнов Илья | M25: =VLOOKUP(A:A,[2]Свод!$A:$B,2,0) -> 1.6
A26: =CONCATENATE($B$26,"_",D26) -> BNPL_Знание ключевых метрик | B26: BNPL | C26: 3-4 квартал | D26: Знание ключевых метрик | E26: Знание об отчетности в Навигаторе. Понимание доступной отчетности и регулярного мониторинга. Значение можно улучшить при следующей самооценке команды в Oprosso в 3-ем квартале. | F26: 3-4 квартал | G26: 1 | H26: в работе | I26: Болотов С. | K26: 0.54 | L26: =K26+SUM(G26:G28)/100 -> 0.643
A27: =CONCATENATE($B$26,"_",D27) -> BNPL_Воронка привлечения | D27: Воронка привлечения | E27: Анализ: Наличие бенчмарков. Цели / динамика / рынок Кампейнинг: Наличие успешных бизнес-запусков. Self-service / кампейнинг, успешность | F27: 46266 | G27: 4.1 | H27: Выполнено | I27: Денисова М., Магомедова Л.
A28: =CONCATENATE($B$26,"_",D28) -> BNPL_Воронка оттока | D28: Воронка оттока | E28: Анализ: повышение полноты анализа воронки оттока, проведение комплексного анализа воронки оттока, оценка причин и узких мест Наличие бенчмарков: Цели / динамика / рынок Отчетность: Полнота отчета. Retention, CR, удержание | F28: 3-4 квартал | G28: 5.2 | H28: в работе выполнено выполнено | I28: Болотов С., Денисова М.
A30: Сейфы_Знание ключевых метрик | B30: Сейфы | C30: Q42026 | D30: Знание ключевых метрик | E30: Валидация данных об Объеме целевого рынка в России, объем целевого рынка в Сбере, клиенты с продуктом, MAU продукта, знание продуктов-спутников | F30: окт.26 | G30: 1 | H30: в работе | K30: 0.48 | L30: 0.63 | M30: 1
A31: Сейфы_Воронка привлечения | B31: Сейфы | C31: Q42026 | D31: Воронка привлечения | E31: Черновики в СБОЛ; Разработка CJM с воронками и процентами привлечения; Наличие Self-Service; Наличие бенчмарков - предоставить отчет по рынку | F31: окт.26-дек.26 | G31: 7.9 | H31: в работе | M31: 14
A32: Сейфы_Цели | B32: Сейфы | C32: Q42026 | D32: Цели | E32: Цели уровня ЛЮ и ЛТ выведены на мониторинг и Прогноз по целям | F32: дек.26 | G32: 6 | H32: в работе | M32: 6

Sheet CX
B1: Продукт / Сегмент | C1: Квартал | D1: Блок для развития | E1: Планируемое мероприятие | F1: Срок исполнения | G1: Ожидание прироста индекса DD, п.п. | H1: Статус | I1: Контактное лицо (ФИО) | J1: Верификация мероприятий Штабом B2C | K1: DD индекс 2 кв. 2026 | L1: Прогноз DD индекс 3 кв. 2026 | M1: Аплифт
A2: =CONCATENATE($B$2,"_",D2) -> Пакет услуг СберПремьер_Алерты | B2: Пакет услуг СберПремьер | D2: Алерты | E2: Внедрить систему оповещений Образ результата: Вопрос на проработке у Ю.Петуховой, вернутся в ближайшее время. По результату донести на РГ DD до трайбов | G2: 4 | I2: Штаб CX | K2: 0.58 | L2: =K2+SUM(G2:G5)/100 -> 0.69 | M2: =IF(A2="","",VLOOKUP(A:A,[2]Свод!$A:$B,2,0)) -> 4
A3: =CONCATENATE($B$2,"_",D3) -> Пакет услуг СберПремьер_Цели | D3: Цели | E3: Сформировать прогнозные значения, вывести в Навигатор Централизованно проверить для всех трайбов (частично решена) | G3: 4 | I3: Штаб CX | J3: Сложно достижимая цель. Есть более простые: - Настроить мониторинг по воронкам оттока и привлечения (+3 п.п.); - Обогатить метриками мониторинг по воронке оттока (+2 п.п.) | M3: =IF(A3="","",VLOOKUP(A:A,[2]Свод!$A:$B,2,0)) -> 6
A4: =CONCATENATE($B$2,"_",D4) -> Пакет услуг СберПремьер_Гипотезы и инициативы | D4: Гипотезы и инициативы | E4: Сфокусировать бэклог аналитиков на research-задачи Направлены правила заполнения задач, необходимо на РГ data-driven рассказать, как правильно заводить задачи | G4: 2 | I4: Продукт/Сегмент | M4: =IF(A4="","",VLOOKUP(A:A,[2]Свод!$A:$B,2,0)) -> 6
A5: =CONCATENATE($B$2,"_",D5) -> Пакет услуг СберПремьер_Знание ключевых метрик | D5: Знание ключевых метрик | E5: Знание метрик и инструментов Результат на основе опроса. Трайбам необходимо лучше знать свои метрики | G5: 1 | I5: Продукт/Сегмент | M5: =IF(A5="","",VLOOKUP(A:A,[2]Свод!$A:$B,2,0)) -> 1
A6: =CONCATENATE($B$6,"_",D6) -> Пакет услуг СберПервый_Алерты | B6: Пакет услуг СберПервый | D6: Алерты | E6: Внедрить систему оповещений Образ результата: Вопрос на проработке у Ю.Петуховой, вернутся в ближайшее время. По результату донести на РГ DD до трайбов | G6: 3.8 | I6: Штаб CX | K6: 0.43 | L6: =K6+SUM(G6:G10)/100 -> 0.569 | M6: =IF(A6="","",VLOOKUP(A:A,[2]Свод!$A:$B,2,0)) -> 3.8
A7: =CONCATENATE($B$6,"_",D7) -> Пакет услуг СберПервый_Цели | D7: Цели | E7: Сформировать прогнозные значения, вывести в Навигатор Централизованно проверить для всех трайбов (частично решена); Декомпозировать значения целей на драйверы, вывести в Навигатор | G7: 1.9 | I7: Штаб CX | J7: Сложно достижимая цель, есть более простые: - Обогащение целей в Навигаторе (+1,9 п.п.); - Настроить мониторинг по воронкам оттока и привлечения (+2,9 п.п.) | M7: =IF(A7="","",VLOOKUP(A:A,[2]Свод!$A:$B,2,0)) -> 7.6
A8: =CONCATENATE($B$6,"_",D8) -> Пакет услуг СберПервый_Гипотезы и инициативы | D8: Гипотезы и инициативы | E8: Сфокусировать бэклог аналитиков на research-задачи - Направлены правила заполнения задач, необходимо на РГ data-driven рассказать, как правильно заводить задачи; - Сформировать перечень инициатив | G8: 1.9 | I8: Продукт/Сегмент | M8: =IF(A8="","",VLOOKUP(A:A,[2]Свод!$A:$B,2,0)) -> 9.5
A9: =CONCATENATE($B$6,"_",D9) -> Пакет услуг СберПервый_Знание ключевых метрик | D9: Знание ключевых метрик | E9: Знание метрик и инструментов Результат на основе опроса. Трайбам необходимо лучше знать свои метрики | G9: 2.5 | I9: Продукт/Сегмент | M9: =IF(A9="","",VLOOKUP(A:A,[2]Свод!$A:$B,2,0)) -> 2.6
A10: =CONCATENATE($B$6,"_",D10) -> Пакет услуг СберПервый_Воронка привлечения | D10: Воронка привлечения | E10: Обогатить метриками мониторинг по воронке привлечения/оттока - задача в работе у Е.Волобуева; Провести анализ привлечения, выявить точки роста | G10: 3.8 | I10: Штаб CX | M10: =IF(A10="","",VLOOKUP(A:A,[2]Свод!$A:$B,2,0)) -> 14.3
A11: =CONCATENATE($B$11,"_",D11) -> МВС_Алерты | B11: МВС | D11: Алерты | E11: Внедрить систему оповещений | G11: 4.3 | I11: Штаб CX | K11: 0.41 | L11: =K11+SUM(G11:G16)/100 -> 0.631 | M11: =IF(A11="","",VLOOKUP(A:A,[2]Свод!$A:$B,2,0)) -> 4.3
A12: =CONCATENATE($B$11,"_",D12) -> МВС_Цели | D12: Цели | E12: Сформировать прогнозные значения, вывести в Навигатор; Декомпозировать значения целей на драйверы, вывести в Навигатор | G12: 4.3 | I12: Штаб CX | J12: Сложно достижимая цель. Есть более простые: - Настроить мониторинг по воронкам оттока и привлечения (+3,3 п.п.); - Обогатить метриками мониторинг по воронке оттока (+3,3 п.п.) | M12: =IF(A12="","",VLOOKUP(A:A,[2]Свод!$A:$B,2,0)) -> 6.5
A13: =CONCATENATE($B$11,"_",D13) -> МВС_Гипотезы и инициативы | D13: Гипотезы и инициативы | E13: Сфокусировать бэклог аналитиков на research-задачи: - Сформировать перечень инициатив - Повысить качество проводимых исследований | G13: 8.6 | I13: Продукт/Сегмент | M13: =IF(A13="","",VLOOKUP(A:A,[2]Свод!$A:$B,2,0)) -> 10.8
A14: =CONCATENATE($B$11,"_",D14) -> МВС_Знание ключевых метрик | D14: Знание ключевых метрик | E14: Необходимо улучшить знание своих метрики | G14: 0.5 | I14: Продукт/Сегмент | M14: =IF(A14="","",VLOOKUP(A:A,[2]Свод!$A:$B,2,0)) -> 0.5
A15: =CONCATENATE($B$11,"_",D15) -> МВС_Воронка привлечения | D15: Воронка привлечения | E15: Обогатить метриками мониторинг по воронке привлечения/оттока - Провести анализ привлечения, выявить точки роста | G15: 3.3 | M15: =IF(A15="","",VLOOKUP(A:A,[2]Свод!$A:$B,2,0)) -> 6.6
A16: =CONCATENATE($B$11,"_",D16) -> МВС_Механики | D16: Механики | E16: Проработать механики повышения уровня клиента | G16: 1.1 | M16: =IF(A16="","",VLOOKUP(A:A,[2]Свод!$A:$B,2,0)) -> 16.1
A17: =CONCATENATE($B$17,"_",D17) -> Дети_Алерты | B17: Дети | D17: Алерты | E17: Внедрить систему оповещений | G17: 4.9 | I17: Штаб CX | K17: 0.54 | L17: =K17+SUM(G17:G20)/100 -> 0.681 | M17: =IF(A17="","",VLOOKUP(A:A,[2]Свод!$A:$B,2,0)) -> 4.9
A18: =CONCATENATE($B$17,"_",D18) -> Дети_Цели | D18: Цели | E18: Сформировать прогнозные значения, вывести в Навигатор | G18: 4.9 | I18: Штаб CX | J18: Сложно достижимая цель. Проще обогатить цели в Навигаторе (+2,5 п.п.), настроить мониторинг по воронке оттока (+1,2 п.п.), обогатить метриками мониторинг по воронкам привлечения и оттока (+2,4 п.п.) | M18: =IF(A18="","",VLOOKUP(A:A,[2]Свод!$A:$B,2,0)) -> 7.4
A19: =CONCATENATE($B$17,"_",D19) -> Дети_Гипотезы и инициативы | D19: Гипотезы и инициативы | E19: Сфокусировать бэклог аналитиков на research-задачи: правильно формировать задачи | G19: 2.4 | I19: Продукт/Сегмент | M19: =IF(A19="","",VLOOKUP(A:A,[2]Свод!$A:$B,2,0)) -> 7.4
A20: =CONCATENATE($B$17,"_",D20) -> Дети_Знание ключевых метрик | D20: Знание ключевых метрик | E20: Необходимо улучшить знание своих метрики | G20: 1.9 | I20: Продукт/Сегмент | M20: =IF(A20="","",VLOOKUP(A:A,[2]Свод!$A:$B,2,0)) -> 1.9
A21: =CONCATENATE($B$21,"_",D21) -> Молодежь_Алерты | B21: Молодежь | D21: Алерты | E21: Внедрить систему оповещений | G21: 5.1 | I21: Штаб CX | K21: 0.48 | L21: =K21+SUM(G21:G24)/100 -> 0.669 | M21: =IF(A21="","",VLOOKUP(A:A,[2]Свод!$A:$B,2,0)) -> 5.1
A22: =CONCATENATE($B$21,"_",D22) -> Молодежь_Цели | D22: Цели | E22: Сформировать прогнозные значения, вывести в Навигатор | G22: 5.1 | I22: Штаб CX | J22: Сложно достижимая цель | M22: =IF(A22="","",VLOOKUP(A:A,[2]Свод!$A:$B,2,0)) -> 7.6
A23: =CONCATENATE($B$21,"_",D23) -> Молодежь_Гипотезы и инициативы | D23: Гипотезы и инициативы | E23: Сфокусировать бэклог аналитиков на research-задачи: правильно формировать задачи | G23: 5.1 | I23: Продукт/Сегмент | M23: =IF(A23="","",VLOOKUP(A:A,[2]Свод!$A:$B,2,0)) -> 10.2
A24: =CONCATENATE($B$21,"_",D24) -> Молодежь_Знание ключевых метрик | D24: Знание ключевых метрик | E24: Необходимо улучшить знание своих метрики | G24: 3.6 | I24: Продукт/Сегмент | M24: =IF(A24="","",VLOOKUP(A:A,[2]Свод!$A:$B,2,0)) -> 3.7
A25: =CONCATENATE($B$25,"_",D25) -> Зрелость_Алерты | B25: Зрелость | D25: Алерты | E25: Внедрить систему оповещений | G25: 4.8 | I25: Штаб CX | K25: 0.38 | L25: =K25+SUM(G25:G27)/100 -> 0.476 | M25: =IF(A25="","",VLOOKUP(A:A,[2]Свод!$A:$B,2,0)) -> 4.8
A26: =CONCATENATE($B$25,"_",D26) -> Зрелость_Цели | D26: Цели | E26: Сформировать прогнозные значения, вывести в Навигатор | G26: 2.4 | I26: Штаб CX | J26: Сложно достижимые цели. Проще Настроить мониторинг по воронкам оттока и привлечения (+4,9 п.п.), обогатить метриками мониторинг по воронкам оттока и привлечения (+4,8 п.п.) | M26: =IF(A26="","",VLOOKUP(A:A,[2]Свод!$A:$B,2,0)) -> 4.8
A27: =CONCATENATE($B$25,"_",D27) -> Зрелость_Гипотезы и инициативы | D27: Гипотезы и инициативы | E27: Сфокусировать бэклог аналитиков на research-задачи: правильно формировать задачи | G27: 2.4 | I27: Продукт/Сегмент | M27: =IF(A27="","",VLOOKUP(A:A,[2]Свод!$A:$B,2,0)) -> 7.2
A28: =CONCATENATE($B$28,"_",D28) -> PB_Цели | B28: PB | D28: Цели | E28: Сформировать прогнозные значения, вывести в Навигатор | G28: 2.3 | I28: Штаб CX | K28: 0.52 | L28: =K28+SUM(G28:G30)/100 -> 0.605 | M28: =IF(A28="","",VLOOKUP(A:A,[2]Свод!$A:$B,2,0)) -> 4.4
A29: =CONCATENATE($B$28,"_",D29) -> PB_Гипотезы и инициативы | D29: Гипотезы и инициативы | E29: Сфокусировать бэклог аналитиков на research-задачи: правильно формировать задачи | G29: 4.5 | I29: Продукт/Сегмент | M29: =IF(A29="","",VLOOKUP(A:A,[2]Свод!$A:$B,2,0)) -> 9
A30: =CONCATENATE($B$28,"_",D30) -> PB_Знание ключевых метрик | D30: Знание ключевых метрик | E30: Необходимо улучшить знание своих метрики | G30: 1.7 | I30: Продукт/Сегмент | M30: =IF(A30="","",VLOOKUP(A:A,[2]Свод!$A:$B,2,0)) -> 1.7
A31: =CONCATENATE($B$31,"_",D31) -> Top Affluent_Цели | B31: Top Affluent | D31: Цели | E31: Сформировать прогнозные значения, вывести в Навигатор; Декомпозировать значения целей на драйверы, вывести в Навигатор | G31: 4.2 | I31: Штаб CX | K31: 0.53 | L31: =K31+SUM(G31:G34)/100 -> 0.609 | M31: =IF(A31="","",VLOOKUP(A:A,[2]Свод!$A:$B,2,0)) -> 6.3
A32: =CONCATENATE($B$31,"_",D32) -> Top Affluent_Гипотезы и инициативы | D32: Гипотезы и инициативы | E32: Сфокусировать бэклог аналитиков на research-задачи: правильно формировать задачи | G32: 2.1 | I32: Продукт/Сегмент | M32: =IF(A32="","",VLOOKUP(A:A,[2]Свод!$A:$B,2,0)) -> 10.5
A33: =CONCATENATE($B$31,"_",D33) -> Top Affluent_Знание ключевых метрик | D33: Знание ключевых метрик | E33: Необходимо улучшить знание своих метрики | G33: 0.5 | I33: Продукт/Сегмент | M33: =IF(A33="","",VLOOKUP(A:A,[2]Свод!$A:$B,2,0)) -> 0.5
A34: =CONCATENATE($B$31,"_",D34) -> Top Affluent_Воронка привлечения | D34: Воронка привлечения | E34: Обогатить метриками мониторинг по воронке привлечения | G34: 1.1 | I34: Штаб CX | M34: =IF(A34="","",VLOOKUP(A:A,[2]Свод!$A:$B,2,0)) -> 3.2
K35: 0.58 | L35: =AVERAGE(L2:L34)-AVERAGE(K2:K34)+K35 -> 0.7125

Sheet Data
B1: Продукт | C1: Квартал | D1: Блок для развития | E1: Планируемое мероприятие | F1: Срок исполнения | G1: Ожидание прироста индекса DD, п.п. | H1: Статус | I1: Контактное лицо (ФИО) | J1: Верификация мероприятий Штабом B2C
B3: Средний DD-индекс 74% - Зрелые

Sheet DP
B1: Продукт | C1: Квартал | D1: Блок для развития | E1: Планируемое мероприятие | F1: Срок исполнения | G1: Ожидание прироста индекса DD, п.п. | H1: Статус | I1: Контактное лицо (ФИО) | J1: Верификация мероприятий Штабом B2C | K1: Текущий индекс DD | L1: Прогноз индекса DD | M1: Аплифт
A2: =CONCATENATE($B$2,"_",D2) -> СберKids_Цели | B2: СберKids | C2: Q3 | D2: Цели | E2: Вывести в Навигатор факторный анализ драйверов 1-2 ур. и прогноз | F2: 46295 | G2: 7 | I2: Пашковская Анна | K2: 0.58 | L2: =K2+SUM(G2:G3)/100 -> 0.722 | M2: =IF(A2="","",VLOOKUP(A:A,[2]Свод!$A:$B,2,0)) -> 7
A3: =CONCATENATE($B$2,"_",D3) -> СберKids_Механики | C3: Q4 | D3: Механики | E3: Настроить механики реактивации и удержания оттекающих клиентов | F3: 46387 | G3: 7.2 | M3: =IF(A3="","",VLOOKUP(A:A,[2]Свод!$A:$B,2,0)) -> 7.2
A4: =CONCATENATE($B$4,"_",D4) -> СберИнвестор_Цели | B4: СберИнвестор | C4: Q3 | D4: Цели | E4: Декомпозировать значения целей на драйверы, сформировать прогнозные значения, вывести в Навигатор | F4: 46295 | G4: 10.5 | K4: 0.46 | L4: =K4+SUM(G4:G6)/100 -> 0.636 | M4: =IF(A4="","",VLOOKUP(A:A,[2]Свод!$A:$B,2,0)) -> 10.5
A5: =CONCATENATE($B$4,"_",D5) -> СберИнвестор_Механики | C5: Q3 | D5: Механики | E5: Проработать механики реактивации клиентов | F5: 46295 | G5: 1.8 | M5: =IF(A5="","",VLOOKUP(A:A,[2]Свод!$A:$B,2,0)) -> 7.1
A6: =CONCATENATE($B$4,"_",D6) -> СберИнвестор_Воронка оттока | C6: Q3 | D6: Воронка оттока | E6: Провести анализ оттока, выявить точки роста. Сформировать перечень мероприятий по снижению оттока | F6: 46295 | G6: 5.3 | M6: =IF(A6="","",VLOOKUP(A:A,[2]Свод!$A:$B,2,0)) -> 8
A7: =CONCATENATE($B$7,"_",D7) -> Уведомления_Механики | B7: Уведомления | C7: Q3 | D7: Механики | E7: Проработать механики реактивации и удержания клиентов | F7: 46295 | G7: 5.5 | K7: 0.53 | L7: =K7+SUM(G7:G8)/100 -> 0.622 | M7: =IF(A7="","",VLOOKUP(A:A,[2]Свод!$A:$B,2,0)) -> 7.3
A8: =CONCATENATE($B$7,"_",D8) -> Уведомления_Гипотезы и инициативы | C8: Q3 | D8: Гипотезы и инициативы | E8: Повысить качество проведенных исседований | F8: 46295 | G8: 3.7 | M8: =IF(A8="","",VLOOKUP(A:A,[2]Свод!$A:$B,2,0)) -> 7.4

Sheet PC
B1: Продукт / Канал | C1: Квартал | D1: Блок для развития | E1: Планируемое мероприятие | F1: Срок исполнения | G1: Ожидание прироста индекса DD, п.п. | H1: Статус | I1: Контактное лицо (ФИО) | J1: Верификация мероприятий Штабом B2C | K1: DD индекс 2 кв. 2026 | L1: Прогноз DD индекс 3 кв. 2026 | M1: Аплифт
B2: Колл-центр | K2: 0.9
B3: Телемаркетинг | K3: 0.84
B4: Чат | K4: 0.72
A5: =CONCATENATE($B$5,"_",D5) -> Выписки, справки_Воронка привлечения | B5: Выписки, справки | D5: Воронка привлечения | E5: Настроить отчетность, чтобы построить воронку оформления | G5: 6.2 | K5: 0.54 | L5: =K5+SUM(G5:G7)/100 -> 0.694 | M5: =IF(A5="","",VLOOKUP(A:A,[2]Свод!$A:$B,2,0)) -> 21.5
A6: =CONCATENATE($B$5,"_",D6) -> Выписки, справки_Воронка оттока | D6: Воронка оттока | E6: Наличие бенчмарков - удалить из расчета в 3 кв., т.к. неприменимо | G6: 3.1 | M6: =IF(A6="","",VLOOKUP(A:A,[2]Свод!$A:$B,2,0)) -> 3.1
A7: =CONCATENATE($B$5,"_",D7) -> Выписки, справки_Гипотезы и инициативы | D7: Гипотезы и инициативы | E7: Доля исследовательских задач >=40%. Введение ролевой модели и калькулятора достаточности ресурса DA | G7: 6.1 | M7: =IF(A7="","",VLOOKUP(A:A,[2]Свод!$A:$B,2,0)) -> 12.2

Sheet ДомКлик
B1: Продукт | C1: Квартал | D1: Блок для развития | E1: Планируемое мероприятие | F1: Срок исполнения | G1: Ожидание прироста индекса DD, п.п. | H1: Статус | I1: Контактное лицо (ФИО) | J1: Верификация мероприятий Штабом B2C | K1: DD индекс 2 кв. 2026 | L1: Прогноз DD индекс 3 кв. 2026 | M1: Аплифт
B2: Сделка вторичка, Загородка | C2: 3Q2026 | D2: Алерты | E2: Внедрение «дерева метрик» в разрезе по дивизионам (в тч загородка) позволит проработать отклонение в «Алертах по системным сбоям» | G2: 5.7 | K2: 0.74 | L2: =K2+G2/100 -> 0.797 | M2: 5.7
B3: Сделка ИЖС, Загородка | C3: 3Q2026 | D3: Воронка оттока | E3: Внедрение «дерева метрик» в разрезе по дивизионам (в тч загородка) позволит прорабоотать отклонение в «Анализе воронки оттока» | G3: 8 | K3: 0.53 | L3: =K3+SUM(G3:G5)/100 -> 0.67 | M3: 12
C4: 3Q2026 | D4: Гипотезы и инициативы | E4: Доля задач DA, связанных с исследованиями (Discovery) ≥40% бэклога: Конвертация существующих задач на выгрузку в исследовательские через интервью заказчика, выявление истинной потребности | G4: 2 | M4: 6
C5: 3Q2026 | D5: Воронка привлечения | E5: Запуск пилота акции лояльности в неипотеке, даем скидки партнеру на ипотечные сделки за неипотеку для увеличению партнерской базы. На регулярной основе CRM рассылки, продуктовые акции на пути клиента (например, Регистрация и Расчеты за 490р) | G5: 4 | M5: 6
