Workbook

Sheet Группы_
G1: Ответ продукта | H1: Ответ продукта | I1: Ответ продукта | L1: Цифровые следы | O1: Ответ продукта | R1: Ответ продукта | U1: Ответ продукта | W1: Ответ продукта | AA1: Ответ продукта | AD1: Механники | AY1: Ответ продукта | BA1: кампейнинг /SS-Цифровые следы | BD1: Цифровые следы | BE1: Цифровые следы | BF1: Цифровые следы | BG1: Цифровые следы | BH1: Цифровые следы
B2: Юнит | C2: Продукт | D2: Оценка | E2: Группа | F2: тип | G2: Знание своих метрик | H2: Все основные метрики выведены в отчетность | I2: Цели уровня ЛЮ-ЛТ выведены на мониторинг | J2: Драйверы целей | K2: Прогноз по целям | L2: Цели уровня ЛЮ-ЛТ выведены на мониторинг (>90% покрытие) | M2: Драйверы целей | N2: Прогноз по целям | O2: Отчетность по воронке привечения | P2: Полнота отчета по воронке привлечения | Q2: Регулярность | R2: Отчетность по воронке оттока | S2: Полнота отчета по воронке оттока | T2: Регулярность | U2: Наличие бенчмарков | V2: Какие бенчмарки? | W2: Анализ воронки привлечения | X2: инициативы по привлечению | Y2: Анализ воронки оттока | Z2: инициативы по оттоку | AA2: Алерты по системным сбоям | AB2: Алерты по бизнес метрикам | AC2: Привлечения | AD2: Удержание клиентов | AE2: База для механники удержания | AF2: Настроена модель склонности к оттоку | AG2: Настроены предоттоковые автоматические сценарии | AH2: Ручной мониторинг | AI2: Информационная комуникация | AJ2: Создание ценности | AK2: Возврат клиентов | AL2: Информационная комуникация | AM2: Создание ценности | AN2: Перекрестные продажи (cross-sell) | AO2: В процессе оформления и после покупки | AP2: Только в процессе оформления | AQ2: Только после покупки | AR2: Допродажи (upsell) | AS2: Реагирования на жизненные события | AT2: Персонализации клиентского опыта | AU2: Есть метрики мониторинга механник | AV2: Примеры метрик мониторинга механник | AW2: Не релевантны предложенные механники | AX2: Возможно ли изменить набор опций по продукту без IT-разработки? | AY2: Доля задач DA, связанных с исследованиями (Discovery) ≥40% бэклога | AZ2: нет аналитиков | BA2: Наличие запусков Кампейнинг/SS | BB2: Наличие успешных запусков | BC2: Использование SS | BD2: Черновики в СБОЛ | BE2: СХ Score | BF2: Проведение A/B-тестов | BG2: Рейтинг DataDriven исследований ≥7,5 | BH2: Наличие доп инициатив сверх БП | BI2: Каких инструментов или какой поддержки не хватает вам для повышения уровня data driven вашего продукта? | BJ2: ФИО-кто проходил | BK2: Комментарий Штаба В2С | BL2: Комментарий Штаба Юнита
D3: =AVERAGE(D5:D136) -> 0.46346226 | G3: Оценивается +-5% попадания в верный ответ (проверка по отчетности в Навигаторе/Штаб Юнита) | H3: 0,5 балл- деш в Навигаторе/ или своя отчетность Если через Запрос аналитику 0,25 баллов | I3: в Навигатор 1 балл ( +90% целей) -< 90% 0 баллов (проверка по цифровым следам- учет ЦС) - своя отчетность 0,5 балл все метрики | O3: Да- 0,5 баллов (умножается на К регулярности) | P3: 0,5 -все 0,25 большая часть | Q3: Автоматически (daily или weekly) *1 если нет то *0,5 | R3: Да- 0,5 баллов (умножается на К регулярности) | S3: 0,5 -все 0,25 большая часть | T3: Автоматически (daily или weekly) *1 если нет то *0,5 | U3: цели/динамика/рыночный бенчмаркc 1 балл (оценка с учетом типа бенчмарка | W3: Комплексный 1 балл не полный 0,5 баллов | X3: Флаг1 -наличия 1 балл | Y3: Комплексный 1 балл не полный 0,5 баллов | Z3: Флаг1 -наличия 1 балл | AA3: 1 балл - да 0,5 баллов частично | AC3: Для сегментов | AD3: наличие механники (оценка по остовляющим) | AF3: Для сегментов 1- флаг наличия | AG3: Для сегментов 1- флаг наличия | AH3: Для сегментов 1- флаг наличия | AI3: Для продуктов Флаг1 -наличие механники 0,5 балл | AJ3: Для продуктов Флаг1 -наличие механники 0,5 балл | AK3: наличие механники (оценка по остовляющим) | AL3: Для продуктов Флаг1 -наличие механники 0,5 балл | AM3: Для продуктов Флаг1 -наличие механники 0,5 балл | AN3: Для продуктов наличие механники (оценка по остовляющим) | AO3: Для продуктов Флаг1 -наличие механники 1 балл | AP3: Для продуктов Флаг1 -наличие механники 0,5 балл | AQ3: Для продуктов Флаг1 -наличие механники 0,5 балл | AR3: Для продуктов наличие механники | AS3: Для сегментов | AT3: Для сегментов | AW3: для инфо | AY3: ≥40% 1 балл От 20 до 39% 0,5 баллов | AZ3: для инфо 1- нет аналитиков в команде | BA3: 0.5 | BB3: 0.5 | BC3: 0.5 | BD3: -покрытие ≥70% от потенциала продукта (1 балл) -покрытие <70% но больше 15% от потенциала продукта (0,5 баллов) Расчет по максимальному проценту за месяцы квартала | BE3: Зеленая зона СХ Score (1 балл) Желтая зона СХ Score (0,5 балл) | BF3: ≥80% (1 балл) ≥30% (0,5 балла) | BG3: Оценка исследований не ниже 7,5 (1 балл) (средний бал по исследованиям) С начала года | BH3: Доходные/Расходные инициативы 1 балл | BI3: Ответ из опроса
B4: Юнит | C4: Продукт | D4: Оценка | E4: Группа | F4: тип | G4: 1 | H4: 2 | I4: 3 | J4: 4 | K4: 5 | L4: 6 | M4: 7 | N4: 8 | O4: 9 | P4: 10 | Q4: 11 | R4: 12 | S4: 13 | T4: 14 | U4: 15 | V4: 16 | W4: 17 | X4: 18 | Y4: 19 | Z4: 20 | AA4: 21 | AB4: 22 | AC4: 222 | AD4: 23 | AE4: 500 | AF4: 500 | AG4: 501 | AH4: 502 | AI4: 24 | AJ4: 25 | AK4: 26 | AL4: 27 | AM4: 28 | AN4: 30 | AO4: 30 | AP4: 31 | AQ4: 32 | AR4: 33 | AS4: 223 | AT4: 224 | AU4: 48 | AW4: 34 | AX4: 47 | AY4: 35 | AZ4: 36 | BA4: 38 | BB4: 39 | BC4: 40 | BD4: 41 | BE4: 42 | BF4: 43 | BG4: 44 | BH4: 45 | BI4: 37 | BJ4: 1000 | BK4: 46
A5: 75 | B5: УБ | C5: ОСАГО | D5: 0.62574257 | E5: Зрелые | F5: продукт | G5: 0.3 | H5: 0.5 | I5: 0.5 | J5: 0 | K5: 0.5 | L5: 1 | M5: 0 | N5: 1 | O5: 1 | P5: 1 | Q5: 1 | R5: 1 | S5: 0 | T5: 1 | U5: 1 | V5: Успешный опыт конкурентов, исследование рынка, интервью | W5: 1 | X5: 1 | Y5: 1 | Z5: 1 | AA5: 1 | AB5: 1 | AC5: для продукта не включается в расчет | AD5: =IF(AI5="не релевантно","не релевантн",(AI5+AJ5)/2) -> 1 | AI5: 1 | AJ5: 1 | AK5: =IF(AL5="не релевантно","не релевантн",(AL5+AM5)/2) -> 1 | AL5: 1 | AM5: 1 | AN5: 0.5 | AO5: 0 | AP5: 1 | AQ5: 0 | AR5: 0 | AS5: для продукта не включается в расчет | AT5: для продукта не включается в расчет | AU5: 1 | AV5: CR, CTR, GPW | AW5: 0 | AX5: 0 | AY5: 0.5 | AZ5: 0 | BA5: 1 | BB5: 0 | BC5: 1 | BD5: 0.5 | BE5: 0.5 | BF5: TBD | BG5: 0 | BH5: 0 | BI5: Стабильная работа PXF Серверов | BJ5: Сипугин Николай Александрович | BK5: Проверить- должен быть кросс сейл в процессе оформления с ОСАГО на авто. По ответу продукта нет
A6: 80 | B6: УБ | C6: КАСКО | D6: 0.62574257 | E6: Зрелые | F6: продукт | G6: 0.3 | H6: 0.5 | I6: 0.5 | J6: 0.5 | K6: 0.5 | L6: 1 | M6: 0 | N6: 1 | O6: 1 | P6: 1 | Q6: 1 | R6: 1 | S6: 0 | T6: 1 | U6: 1 | V6: Успешный опыт конкурентов, исследование рынка, интервью | W6: 1 | X6: 1 | Y6: 1 | Z6: 1 | AA6: 1 | AB6: 1 | AC6: для продукта не включается в расчет | AD6: =IF(AI6="не релевантно","не релевантн",(AI6+AJ6)/2) -> 1 | AI6: 1 | AJ6: 1 | AK6: =IF(AL6="не релевантно","не релевантн",(AL6+AM6)/2) -> 1 | AL6: 1 | AM6: 1 | AN6: 0.5 | AO6: 0 | AP6: 1 | AQ6: 0 | AR6: 0 | AS6: для продукта не включается в расчет | AT6: для продукта не включается в расчет | AU6: 1 | AV6: CR, CTR, GPW | AW6: 0 | AX6: 0 | AY6: 0.5 | AZ6: 0 | BA6: 1 | BB6: 0 | BC6: 1 | BD6: 0.5 | BE6: 0.5 | BF6: TBD | BG6: 0 | BH6: 0 | BI6: Стабильная работа PXF Серверов | BJ6: Сипугин Николай Александрович | BK6: 0
A7: 85 | B7: УБ | C7: ИнвестКопилка | D7: 0.47640449 | E7: Развивающиеся | F7: продукт | G7: 0.6 | H7: 0.5 | I7: 1 | J7: 0 | K7: 0.5 | L7: 1 | M7: 0 | N7: 0 | O7: 0.5 | P7: 0.5 | Q7: 0.5 | R7: 1 | S7: 0 | T7: 1 | U7: 1 | V7: Сравнение с историческими значениями + ручное прогнозирование целевых бенчмарк показателей | W7: 1 | X7: 1 | Y7: 0.5 | Z7: 1 | AA7: 1 | AB7: 0 | AC7: для продукта не включается в расчет | AD7: =IF(AI7="не релевантно","не релевантн",(AI7+AJ7)/2) -> не релевантн | AI7: не релевантно | AJ7: не релевантно | AK7: =IF(AL7="не релевантно","не релевантн",(AL7+AM7)/2) -> не релевантн | AL7: не релевантно | AM7: не релевантно | AN7: не релевантно | AO7: 0 | AP7: 0 | AQ7: 0 | AR7: 0 | AS7: для продукта не включается в расчет | AT7: для продукта не включается в расчет | AU7: 1 | AV7: Воронка продаж | AW7: 1 | AX7: 0 | AY7: 0 | AZ7: 1 | BA7: 0 | BB7: 0 | BC7: 0 | BD7: 0.5 | BE7: нет продукта | BF7: TBD | BG7: 0 | BH7: 1 | BI7: Ресурс аналитиков данных. Очень трудно получить приоритет и фокус на решение сложных задач. Некоторые исследования были похорошены в стол из за отсутсвия ресурса. Также нужны: стабильность поставки данных в навигатор, автоматизация анализа притока ДС и NPV, автоматизация прогнозных оценок, методология расчета влияния сервисов на CLTV, инструмент работы над метчинг исследованиями | BJ7: Коробова Екатерина Вадимовна | BK7: Требуется проверить метрики в блоке-метрики продукта- продукт не выделен в ЕКМ Нет продуктовых механник? Подтвердить релевантны или нет
A8: 90 | B8: УБ | C8: СберСова | D8: 0.47293447 | E8: Развивающиеся | F8: продукт | G8: 1 | H8: 0.5 | I8: 0 | J8: 0 | K8: 0 | L8: 0 | M8: 0 | N8: 0 | O8: 0.5 | P8: 0.5 | Q8: 0.5 | R8: не релевантно | S8: не релевантно | T8: 0 | U8: 1 | V8: Маркетинговые отчеты и аналитика | W8: 0.5 | X8: 1 | Y8: не релевантно | AA8: 1 | AB8: 0.5 | AC8: для продукта не включается в расчет | AD8: =IF(AI8="не релевантно","не релевантн",(AI8+AJ8)/2) -> 0.5 | AI8: 0 | AJ8: 1 | AK8: =IF(AL8="не релевантно","не релевантн",(AL8+AM8)/2) -> 0.5 | AL8: 0 | AM8: 1 | AN8: 0.5 | AO8: 0 | AP8: 1 | AQ8: 0 | AR8: 0 | AS8: для продукта не включается в расчет | AT8: для продукта не включается в расчет | AU8: 1 | AV8: Retention Rate, метрика отказа | AW8: 0 | AX8: 0 | AY8: 0 | AZ8: 1 | BA8: не релевантно | BB8: не релевантно | BC8: не релевантно | BD8: не релевантно | BE8: нет продукта | BF8: TBD | BG8: 0 | BH8: не релевантно | BI8: Витрин данных | BJ8: Волков Дмитрий Александрович | BK8: 1.Отсутвует воронка оттока, но есть механника возврата и RR 2.Подтвердить какие продуктовые механники действительно не релевантны и должны быть исключены из общего расчета
A9: 95 | B9: УБ | C9: Залоговое страхование (корпоративное) | D9: 0.36082474 | E9: Требуют внимания | F9: продукт | G9: 1 | H9: 1 | I9: 1 | J9: 0 | K9: 0 | L9: 1 | M9: 0 | N9: 1 | O9: 0 | P9: 0 | Q9: 0 | R9: 1 | S9: 0 | T9: 1 | U9: 0 | W9: 0.5 | X9: 1 | Y9: 0.5 | Z9: 1 | AA9: 1 | AB9: 0.5 | AC9: для продукта не включается в расчет | AD9: =IF(AI9="не релевантно","не релевантн",(AI9+AJ9)/2) -> 0 | AI9: 0 | AJ9: 0 | AK9: =IF(AL9="не релевантно","не релевантн",(AL9+AM9)/2) -> 0 | AL9: 0 | AM9: 0 | AN9: 0 | AO9: 0 | AP9: 0 | AQ9: 0 | AR9: 1 | AS9: для продукта не включается в расчет | AT9: для продукта не включается в расчет | AU9: 1 | AV9: Рост среднего чека | AW9: 0 | AX9: 0 | AY9: 0 | AZ9: 1 | BA9: 0 | BB9: 0 | BC9: 0 | BD9: 0 | BE9: нет продукта | BF9: TBD | BG9: 0 | BH9: 0 | BI9: 0 | BJ9: Дубинина Татьяна Валерьевна | BK9: 1. Нет Воронки привлечения! 2. Есть Воронка оттока (пролонгации)- Детальный деш в Навигаторе! В разных разрезах 3 Требуется проверить метрики в блоке-метрики продукта- продукт не выделен в ЕКМ 4 Подтвердить UP-sell- подтвердить
A10: 100 | B10: УБ | C10: НСЖ | D10: 0.46419753 | E10: Развивающиеся | F10: продукт | G10: 0.4 | H10: 0.5 | I10: 1 | J10: 0.5 | K10: 1 | L10: 1 | M10: 0 | N10: 1 | O10: 0 | P10: 0 | Q10: 0 | R10: 1 | S10: 0 | T10: 1 | U10: 0 | W10: 1 | X10: 1 | Y10: 0.5 | Z10: 1 | AA10: 1 | AB10: 0 | AC10: для продукта не включается в расчет | AD10: =IF(AI10="не релевантно","не релевантн",(AI10+AJ10)/2) -> 0 | AI10: 0 | AJ10: 0 | AK10: =IF(AL10="не релевантно","не релевантн",(AL10+AM10)/2) -> 0 | AL10: 0 | AM10: 0 | AN10: не релевантно | AO10: 0 | AP10: 0 | AQ10: 0 | AR10: не релевантно | AS10: для продукта не включается в расчет | AT10: для продукта не включается в расчет | AU10: 1 | AV10: Доля сборов по продукту среди всех сборов в сегменте/канале | AW10: 1 | AX10: 0 | AY10: 0 | AZ10: 1 | BA10: 0 | BB10: 0 | BC10: 0 | BD10: 0 | BE10: нет продукта | BF10: TBD | BG10: 0 | BH10: 1 | BI10: Большая автоматизация отслеживания метрик | BJ10: Волобуев Андрей Николаевич | BK10: Отсутсвуют стандартные механники. Отсутвуют черновики (Формула жизни)- должны быть Вернуться с ОС - почему не релевантны механники cross-sell/up-sell?
A11: 105 | B11: УБ | C11: ИСЖ | D11: 0.46236559 | E11: Развивающиеся | F11: продукт | G11: 1 | H11: 0.5 | I11: 1 | J11: 0 | K11: 1 | L11: 1 | M11: 0 | N11: 1 | O11: 0.5 | P11: 0 | Q11: 0.5 | R11: 0 | S11: 0 | T11: 0 | U11: 0 | W11: 0.5 | X11: 1 | Y11: 0.5 | Z11: 1 | AA11: 1 | AB11: 0 | AC11: для продукта не включается в расчет | AD11: =IF(AI11="не релевантно","не релевантн",(AI11+AJ11)/2) -> 1 | AI11: 1 | AJ11: 1 | AK11: =IF(AL11="не релевантно","не релевантн",(AL11+AM11)/2) -> не релевантн | AL11: не релевантно | AM11: не релевантно | AN11: 0 | AO11: 0 | AP11: 0 | AQ11: 0 | AR11: 1 | AS11: для продукта не включается в расчет | AT11: для продукта не включается в расчет | AU11: 1 | AV11: отчет по воронкам кампейнинга | AW11: 0 | AX11: 0 | AY11: 0 | AZ11: 1 | BA11: 0 | BB11: 0 | BC11: 0 | BD11: 0 | BE11: нет продукта | BF11: TBD | BG11: 0 | BH11: 1 | BI11: нет ответа | BJ11: Клычева Олеся Олеговна | BK11: Отсутсвуют стандартные механники. Отсутвуют черновики (Формула жизни) Вернуться с ОС - почему не релевантны механники cross-sell/up-sell?
A12: 110 | B12: УБ | C12: Страхование жизни | D12: 0.4 | E12: Развивающиеся | F12: продукт | G12: 0.2 | H12: 0.5 | I12: 1 | J12: 0 | K12: 1 | L12: 1 | M12: 0 | N12: 1 | O12: 0 | P12: 0 | Q12: 0 | R12: 0 | S12: 0 | T12: 0 | U12: 0 | W12: 0.5 | X12: 1 | Y12: 0.5 | Z12: 0 | AA12: 1 | AB12: 1 | AC12: для продукта не включается в расчет | AD12: =IF(AI12="не релевантно","не релевантн",(AI12+AJ12)/2) -> 1 | AI12: 1 | AJ12: 1 | AK12: =IF(AL12="не релевантно","не релевантн",(AL12+AM12)/2) -> 0.5 | AL12: 1 | AM12: 0 | AN12: 0 | AO12: 0 | AP12: 0 | AQ12: 0 | AR12: 0 | AS12: для продукта не включается в расчет | AT12: для продукта не включается в расчет | AU12: 1 | AV12: % удержания клиентов после окончания страхового поиса | AW12: 0 | AX12: 0 | AY12: 0 | AZ12: 0 | BA12: 0 | BB12: 0 | BC12: 0 | BD12: 0.5 | BE12: нет продукта | BF12: TBD | BG12: 0 | BH12: 1 | BI12: Более тесного взаимодействия банк-ДЗО, есть структурно непраивльно выстроенные подразделения | BJ12: Кобзарь Игорь Викторович | BK12: 0
A13: 115 | B13: УБ | C13: Брокерский счет | D13: 0.42178218 | E13: Развивающиеся | F13: продукт | G13: 0.4 | H13: 0.5 | I13: 1 | J13: 0 | K13: 0.5 | L13: 1 | M13: 0 | N13: 1 | O13: 0.5 | P13: 0 | Q13: 0.5 | R13: 0 | S13: 0 | T13: 0 | U13: 0 | W13: 0.5 | X13: 1 | Y13: 0 | Z13: 0 | AA13: 1 | AB13: 0 | AC13: для продукта не включается в расчет | AD13: =IF(AI13="не релевантно","не релевантн",(AI13+AJ13)/2) -> 0 | AI13: 0 | AJ13: 0 | AK13: =IF(AL13="не релевантно","не релевантн",(AL13+AM13)/2) -> 0.5 | AL13: 1 | AM13: 0 | AN13: 1 | AO13: 1 | AP13: 0 | AQ13: 0 | AR13: 1 | AS13: для продукта не включается в расчет | AT13: для продукта не включается в расчет | AU13: 1 | AV13: Количество клиентов открывших счет, после догоняющих коммуникаций | AW13: 0 | AX13: 0 | AY13: 0 | AZ13: 1 | BA13: 1 | BB13: 0 | BC13: 1 | BD13: 0.5 | BE13: 0.5 | BF13: TBD | BG13: 0 | BH13: 1 | BI13: Не хватает self-service аналитики, удобных A/B-тестов, предиктивных ML-моделей (отток, конверсия в первую сделку) и единого обзора клиентского пути с продуктовыми метриками в реальном времени. | BJ13: Аганина Яна | BK13: Нет Воронки оттока
A14: 120 | B14: УБ | C14: БПИФ | D14: 0.48041237 | E14: Развивающиеся | F14: продукт | G14: 0.4 | H14: 0.5 | I14: 0.5 | J14: 0 | K14: 0.5 | L14: 1 | M14: 0 | N14: 1 | O14: 1 | P14: 0.5 | Q14: 1 | R14: 0 | S14: 0 | T14: 0 | U14: 0 | W14: 0.5 | X14: 1 | Y14: 0.5 | Z14: 1 | AA14: 1 | AB14: 0 | AC14: для продукта не включается в расчет | AD14: =IF(AI14="не релевантно","не релевантн",(AI14+AJ14)/2) -> 0.5 | AI14: 1 | AJ14: 0 | AK14: =IF(AL14="не релевантно","не релевантн",(AL14+AM14)/2) -> 0 | AL14: 0 | AM14: 0 | AN14: 1 | AO14: 1 | AP14: 0 | AQ14: 0 | AR14: 1 | AS14: для продукта не включается в расчет | AT14: для продукта не включается в расчет | AU14: 1 | AV14: кол-во показов, кол-во кликов | AW14: 0 | AX14: 0.5 | AY14: 0 | AZ14: 1 | BA14: 1 | BB14: 0 | BC14: 1 | BD14: 0 | BE14: нет продукта | BF14: TBD | BG14: 0 | BH14: 1 | BI14: сложно сказать | BJ14: Сулейманов Расим Орудж оглы | BK14: Требуется проверить метрики в блоке-метрики продукта- продукт не выделен в ЕКМ Подтвердить- действительно ли не релевантна механника Возврата 0 у ЗПИФ например есть -Акции кэшбеков и иных поощрений за возврат средств от погашенного фонда в другой наш продукт
A15: 125 | B15: УБ | C15: ЗПИФ | D15: 0.63505155 | E15: Зрелые | F15: продукт | G15: 0.4 | H15: 0.5 | I15: 1 | J15: 0 | K15: 1 | L15: 1 | M15: 0 | N15: 1 | O15: 0.5 | P15: 0.5 | Q15: 0.5 | R15: 1 | S15: 0 | T15: 1 | U15: 1 | V15: Цели по удержанию доли рынка, историческая динамика, бенчмарком может быть зарубежный рынок reit (но в РФ есть своя специфика) | W15: 1 | X15: 1 | Y15: 1 | Z15: 1 | AA15: 0.5 | AB15: 0 | AC15: для продукта не включается в расчет | AD15: =IF(AI15="не релевантно","не релевантн",(AI15+AJ15)/2) -> 1 | AI15: 1 | AJ15: 1 | AK15: =IF(AL15="не релевантно","не релевантн",(AL15+AM15)/2) -> 0.5 | AL15: 1 | AM15: 0 | AN15: 1 | AO15: 1 | AP15: 0 | AQ15: 0 | AR15: 1 | AS15: для продукта не включается в расчет | AT15: для продукта не включается в расчет | AU15: 1 | AV15: CR кампаний | AW15: 0 | AX15: 0.5 | AY15: 0 | AZ15: 1 | BA15: 1 | BB15: 0 | BC15: 1 | BD15: 0 | BE15: нет продукта | BF15: TBD | BG15: 0 | BH15: 1 | BI15: Бизнес-мониторинг (оповещение при отклонении бизнес-метрик от заданного порога), инструменты для связи метрик кликстрим с конкретными клиентами и объемами продаж (в рублях) | BJ15: Зырянская Валерия Юрьевна | BK15: Требуется проверить метрики в блоке-метрики продукта- продукт не выделен в ЕКМ Проверить соотвтетвие полноты механник
A16: 130 | B16: УБ | C16: ПДС | D16: 0.55483871 | E16: Развивающиеся | F16: продукт | G16: 0.4 | H16: 0.5 | I16: 1 | J16: 0 | K16: 1 | L16: 1 | M16: 0 | N16: 1 | O16: 1 | P16: 1 | Q16: 1 | R16: не релевантно | S16: не релевантно | T16: 0 | U16: 0 | W16: 1 | X16: 1 | Y16: 0 | Z16: 0 | AA16: 1 | AB16: 0 | AC16: для продукта не включается в расчет | AD16: =IF(AI16="не релевантно","не релевантн",(AI16+AJ16)/2) -> 1 | AI16: 1 | AJ16: 1 | AK16: =IF(AL16="не релевантно","не релевантн",(AL16+AM16)/2) -> 0 | AL16: 0 | AM16: 0 | AN16: 1 | AO16: 1 | AP16: 0 | AQ16: 0 | AR16: 1 | AS16: для продукта не включается в расчет | AT16: для продукта не включается в расчет | AU16: 1 | AV16: Сколько удержано в рублях и штуках. Воронка процесса удержания, тепловая карта процесса. | AW16: 0 | AX16: 0.5 | AY16: 0 | AZ16: 1 | BA16: 1 | BB16: 1 | BC16: 1 | BD16: 0 | BE16: нет продукта | BF16: TBD | BG16: 0 | BH16: 1 | BI16: Длинные сроки глубинных данных по клиентам, которые выгрцзить можно только через DS | BJ16: Процесс оформления ПДС | BK16: Не релевантна воронка оттока- не согласны, так как есть как прекращение пополнений или досрочный выход (с потерями) Прошу подтвердить Механника возврата также релевантна- прошу подтвердить
A17: 135 | B17: УБ | C17: ОПИФ | D17: 0.60990099 | E17: Зрелые | F17: продукт | G17: 0.4 | H17: 0.5 | I17: 1 | J17: 0 | K17: 1 | L17: 1 | M17: 0 | N17: 1 | O17: 0.5 | P17: 0.5 | Q17: 0.5 | R17: 1 | S17: 0 | T17: 1 | U17: 1 | V17: На стороне Управляющей компании: цели по завоеванию доли рынка, историческая динамика | W17: 1 | X17: 1 | Y17: 0.5 | Z17: 1 | AA17: 0.5 | AB17: 0 | AC17: для продукта не включается в расчет | AD17: =IF(AI17="не релевантно","не релевантн",(AI17+AJ17)/2) -> 1 | AI17: 1 | AJ17: 1 | AK17: =IF(AL17="не релевантно","не релевантн",(AL17+AM17)/2) -> 1 | AL17: 1 | AM17: 1 | AN17: 1 | AO17: 1 | AP17: 0 | AQ17: 0 | AR17: 1 | AS17: для продукта не включается в расчет | AT17: для продукта не включается в расчет | AU17: 1 | AV17: CR кампаний, % retention | AW17: 0 | AX17: 0.5 | AY17: 0 | AZ17: 1 | BA17: 1 | BB17: 0 | BC17: 1 | BD17: 0 | BE17: 0 | BF17: TBD | BG17: 0 | BH17: 1 | BI17: Оперативное отслеживание объемов продаж (в руб.) по метрикам кликстрим, оперативное оповещение в случае посадки бизнес-метрик | BJ17: Клочкова Ольга Владимировна | BK17: Требуется проверить метрики в блоке-метрики продукта- продукт не выделен в ЕКМ
A18: 140 | B18: УБ | C18: ВЗР | D18: 0.57029703 | E18: Развивающиеся | F18: продукт | G18: 0.9 | H18: 0.5 | I18: 1 | J18: 0 | K18: 1 | L18: 1 | M18: 0 | N18: 1 | O18: 0.5 | P18: 0.5 | Q18: 0.5 | R18: 0.5 | S18: 0.5 | T18: 0.5 | U18: 0 | W18: 1 | X18: 1 | Y18: 1 | Z18: 1 | AA18: 1 | AB18: 0.5 | AC18: для продукта не включается в расчет | AD18: =IF(AI18="не релевантно","не релевантн",(AI18+AJ18)/2) -> 1 | AI18: 1 | AJ18: 1 | AK18: =IF(AL18="не релевантно","не релевантн",(AL18+AM18)/2) -> 0.5 | AL18: 1 | AM18: 0 | AN18: 0.5 | AO18: 0 | AP18: 0 | AQ18: 1 | AR18: 1 | AS18: для продукта не включается в расчет | AT18: для продукта не включается в расчет | AU18: 1 | AV18: % повторных, CR по ЭФ оформления, CR в черновики, CSI, NPS | AW18: 0 | AX18: 0 | AY18: 0 | AZ18: 0 | BA18: 0 | BB18: 0 | BC18: 0 | BD18: 1 | BE18: 0.5 | BF18: TBD | BG18: 0 | BH18: 0 | BI18: Легких и простых процессов запуска пилотов, простых способов получения данных по продукту (вкл. источников данных для сбора кампаний) | BJ18: Мартусенко Игорь Викторович | BK18: Требуется проверить метрики в блоке-метрики продукта- продукт не выделен в ЕКМ
A19: 145 | B19: УБ | C19: ДУ | D19: 0.40449438 | E19: Развивающиеся | F19: продукт | G19: 1 | H19: 0.5 | I19: 1 | J19: 0 | K19: 1 | L19: 1 | M19: 0 | N19: 1 | O19: 0.5 | P19: 0.5 | Q19: 0.5 | R19: 1 | S19: 0 | T19: 1 | U19: 1 | V19: Цели УК Первая по завоеванию доли рынка + историческая динамика | W19: 0.5 | X19: 0 | Y19: 0.5 | Z19: 1 | AA19: 0.5 | AB19: 0 | AC19: для продукта не включается в расчет | AD19: =IF(AI19="не релевантно","не релевантн",(AI19+AJ19)/2) -> 0 | AI19: 0 | AJ19: 0 | AK19: =IF(AL19="не релевантно","не релевантн",(AL19+AM19)/2) -> 0.5 | AL19: 1 | AM19: 0 | AN19: Не релевантно | AO19: 0 | AP19: 0 | AQ19: 0 | AR19: 0 | AS19: для продукта не включается в расчет | AT19: для продукта не включается в расчет | AU19: 1 | AV19: CR кампейна | AW19: 0 | AX19: 0.5 | AY19: 0 | AZ19: 1 | BA19: 0 | BB19: 0 | BC19: 0 | BE19: нет продукта | BF19: TBD | BG19: 0 | BH19: 0 | BI19: нет ответа | BJ19: Казакова Елена Алексеевна | BK19: Требуется проверить метрики в блоке-метрики продукта- продукт не выделен в ЕКМ Нет механник кроме Возврата. Для ДУ длжны быть релевантны все- например Up-sell в ДУ — это не «купите более дорогой тариф», а увеличение активов под управлением и переход на более сложные стратегии Провеить есть ли кампейн и черновики? Из данных Навигатора не понятно- продукт не выделен
A20: 150 | B20: УБ | C20: Страхование залога (к ипотеке) | D20: 0.51546392 | E20: Развивающиеся | F20: продукт | G20: 1 | H20: 0.5 | I20: 1 | J20: 0 | K20: 1 | L20: 1 | M20: 0 | N20: 1 | O20: 0 | P20: 0 | Q20: 0 | R20: 1 | S20: 0 | T20: 1 | U20: 1 | V20: % удержания | W20: 0.5 | X20: 1 | Y20: 0.5 | Z20: 1 | AA20: 1 | AB20: 0 | AC20: для продукта не включается в расчет | AD20: =IF(AI20="не релевантно","не релевантн",(AI20+AJ20)/2) -> 0.5 | AI20: 1 | AJ20: 0 | AK20: =IF(AL20="не релевантно","не релевантн",(AL20+AM20)/2) -> 1 | AL20: 1 | AM20: 1 | AN20: 0.5 | AO20: 0 | AP20: 0 | AQ20: 1 | AR20: 1 | AS20: для продукта не включается в расчет | AT20: для продукта не включается в расчет | AU20: 1 | AV20: доля Перехвата | AW20: 0 | AX20: 0 | AY20: 0 | AZ20: 1 | BA20: 0 | BB20: 0 | BC20: 0 | BD20: 0.5 | BE20: нет продукта | BF20: TBD | BG20: 0 | BH20: 0 | BI20: не хватает единого инструмента, к которому можно подключиться/донастроить с учетом специфики продукта. Сейчас каждая команда с нуля собирает необходимые данные | BJ20: Казакова Кристина Юрьевна | BK20: 0
A21: 155 | B21: УБ | C21: Личная защита Плюс | D21: 0.60412371 | E21: Зрелые | F21: продукт | G21: 0.9 | H21: 0.5 | I21: 1 | J21: 0.5 | K21: 1 | L21: 1 | M21: 0 | N21: 1 | O21: 1 | P21: 0 | Q21: 1 | R21: 1 | S21: 0.5 | T21: 1 | U21: 1 | V21: Уровень пролонгации, уровень расторжений | W21: 1 | X21: 1 | Y21: 1 | Z21: 1 | AA21: 0.5 | AB21: 0.5 | AC21: для продукта не включается в расчет | AD21: =IF(AI21="не релевантно","не релевантн",(AI21+AJ21)/2) -> 1 | AI21: 1 | AJ21: 1 | AK21: =IF(AL21="не релевантно","не релевантн",(AL21+AM21)/2) -> 0 | AL21: 0 | AM21: 0 | AN21: 1 | AO21: 1 | AP21: 0 | AQ21: 0 | AR21: 1 | AS21: для продукта не включается в расчет | AT21: для продукта не включается в расчет | AU21: 1 | AV21: Уровень пролонгации, уровень расторжений, проникновение в кредитование, конверсия, GWP, ЧКД | AW21: 0 | AX21: 0 | AY21: 0.5 | AZ21: 0 | BA21: 0 | BB21: 0 | BC21: 0 | BD21: 0 | BE21: нет продукта | BF21: TBD | BG21: 0 | BH21: 0 | BI21: Более детальной отчетности по продукту в разных разрезах и по разным каналам продажи. Более понятные дашборды по кампаниям продаж | BJ21: Горбунова Екатерина Эдуардовна | BK21: 0
A22: 160 | B22: УБ | C22: Защита на любой случай | D22: 0.54491018 | E22: Развивающиеся | F22: продукт | G22: 0.5 | H22: 0.5 | I22: 0 | J22: 0 | K22: 1 | L22: 1 | M22: 0 | N22: 1 | O22: 1 | P22: 0.5 | Q22: 1 | R22: 1 | S22: 0 | T22: 1 | U22: 0 | W22: 1 | X22: 1 | Y22: 0.5 | Z22: 1 | AA22: 1 | AB22: 0.5 | AC22: для продукта не включается в расчет | AD22: =IF(AI22="не релевантно","не релевантн",(AI22+AJ22)/2) -> 1 | AI22: 1 | AJ22: 1 | AK22: =IF(AL22="не релевантно","не релевантн",(AL22+AM22)/2) -> 0.5 | AL22: 1 | AM22: 0 | AN22: 0.5 | AO22: 0 | AP22: 1 | AQ22: 0 | AR22: 1 | AS22: для продукта не включается в расчет | AT22: для продукта не включается в расчет | AU22: 1 | AV22: СRR, доля пролонгации, доля очередных взносов | AW22: 0 | AX22: 0 | AY22: 0 | AZ22: 1 | BA22: 1 | BB22: 1 | BC22: 1 | BD22: 0 | BE22: 1 | BF22: TBD | BG22: 0 | BH22: 0 | BI22: дата аналитиков, легких процессов работы с отчетностью и пилотами | BJ22: Корпачева Надежда Олеговна | BK22: 0
A23: 165 | B23: УБ | C23: ДСЖ ПК | D23: 0.55058824 | E23: Развивающиеся | F23: продукт | G23: 0.2 | H23: 0.5 | I23: 1 | J23: 0 | K23: 1 | L23: 1 | M23: 0 | N23: 1 | O23: 0.5 | P23: 0.5 | Q23: 0.5 | R23: 0.5 | S23: 0.5 | T23: 0.5 | U23: 1 | V23: показатель построен на ретро данных, показатель должен быть не выше заложенного в БП | W23: 0.5 | X23: 1 | Y23: 0.5 | Z23: 1 | AA23: 1 | AB23: 1 | AC23: для продукта не включается в расчет | AD23: =IF(AI23="не релевантно","не релевантн",(AI23+AJ23)/2) -> 1 | AI23: 1 | AJ23: 1 | AK23: =IF(AL23="не релевантно","не релевантн",(AL23+AM23)/2) -> не релевантн | AL23: Не релевантно | AM23: Не релевантно | AN23: Не релевантно | AO23: 0 | AP23: 0 | AQ23: 0 | AR23: 0 | AS23: для продукта не включается в расчет | AT23: для продукта не включается в расчет | AU23: 1 | AV23: % оттока | AW23: 0 | AX23: 0 | AY23: 0 | AZ23: 1 | BA23: 0 | BB23: 0 | BC23: 0 | BD23: не релевантно | BE23: нет продукта | BF23: TBD | BG23: 0 | BH23: 1 | BI23: нет аналитиков DA, внутри Трайба сложно встать в бэклог Команды Аналитика данных (DE УБ) | BJ23: Кузнецова Ольга Сергеевна | BK23: Отчеты по воронкам автоматической нет В комментарии отчетность в Навигаторе по продукту, но не по воронке Воронки как я поняла по запросу- прошу подтвердить Вернуться с ответом релевантна ли (возможна ли) механника cross-sell
A24: 170 | B24: УБ | C24: ДСЖ КК | D24: 0.56853933 | E24: Развивающиеся | F24: продукт | G24: 0.4 | H24: 0.5 | I24: 1 | J24: 0 | K24: 1 | L24: 1 | M24: 0 | N24: 1 | O24: 1 | P24: 0.5 | Q24: 1 | R24: 0.5 | S24: 0.5 | T24: 0.5 | U24: 1 | V24: Используются поставленные Цели (клиентские платы, GPW, проникновение, % выставленных счетов, уровень оплачиваемости, средний чек, % расторжений). Использование рыночного бенчмарка не релевантно, т.к. в Сбере используется подход прозрачных продаж и клиентоцентричности, конкуренты продают аналогичный продукт "под капотом" | W24: 1 | X24: 1 | Y24: 1 | Z24: 1 | AA24: 0.5 | AB24: 0 | AC24: для продукта не включается в расчет | AD24: =IF(AI24="не релевантно","не релевантн",(AI24+AJ24)/2) -> 1 | AI24: 1 | AJ24: 1 | AK24: =IF(AL24="не релевантно","не релевантн",(AL24+AM24)/2) -> не релевантн | AL24: Не релевантно | AM24: Не релевантно | AN24: Не релевантно | AO24: 0 | AP24: 0 | AQ24: 0 | AR24: 0 | AS24: для продукта не включается в расчет | AT24: для продукта не включается в расчет | AU24: 1 | AV24: Оценивался % снижения расторжений при внедрении механик | AW24: 0 | AX24: 0 | AY24: 0 | AZ24: 1 | BA24: 1 | BB24: 0 | BC24: 1 | BD24: 0 | BE24: нет продукта | BF24: TBD | BG24: 0 | BH24: 1 | BI24: Единого дэша для объединения всех аналитических срезов по всем активностям. Скорости внедрения изменений в аналитику/отчетность Навигатора | BJ24: Большакова Наталья Сергеевна | BK24: 0
A25: 175 | B25: УБ | C25: ЦФА | D25: 0.28808864 | E25: Требуют внимания | F25: продукт | G25: 0.25 | H25: 0.5 | I25: 1 | J25: 0 | K25: 0 | L25: 1 | M25: 0 | N25: 0 | O25: 0 | P25: 0 | Q25: 0 | R25: 0 | S25: 0 | T25: 0 | U25: 0 | W25: 0.5 | X25: 1 | Y25: не релевантно | Z25: 0 | AA25: 1 | AB25: 0 | AC25: для продукта не включается в расчет | AD25: =IF(AI25="не релевантно","не релевантн",(AI25+AJ25)/2) -> не релевантн | AI25: Не релевантно | AJ25: Не релевантно | AK25: =IF(AL25="не релевантно","не релевантн",(AL25+AM25)/2) -> не релевантн | AL25: Не релевантно | AM25: Не релевантно | AN25: Не релевантно | AO25: 0 | AP25: 0 | AQ25: 0 | AR25: не релевантно | AS25: для продукта не включается в расчет | AT25: для продукта не включается в расчет | AU25: 1 | AV25: Сборы, клиенты, AUM | AW25: 1 | AX25: 0 | AY25: 0 | AZ25: 1 | BA25: 0 | BB25: 0 | BC25: 0 | BE25: нет продукта | BF25: TBD | BG25: 0 | BH25: не реевантно | BI25: Необходимо, чтобы выстраивали централизованно прогнозные значения по метрикам с привлечением Штаба УБ | BJ25: Илларионов Артем Андреевич | BK25: Требуется проверить метрики в блоке-метрики продукта- продукт не выделен в ЕКМ Релеванты ли для продукта SS/компейн? Черновики? Релевантна ли воронка оттока/анализ оттока?
A26: 14 | B26: CBP | C26: Вклады+НС | D26: 0.38613861 | E26: Требуют внимания | F26: продукт | G26: 1 | H26: 0.5 | I26: 0 | J26: 0.5 | K26: 0 | L26: 0 | M26: 0 | N26: 0 | O26: 1 | P26: 0.5 | Q26: 1 | R26: 1 | S26: 0 | T26: 1 | U26: 0 | W26: 0.5 | X26: 1 | Y26: 0 | Z26: 0 | AA26: 1 | AB26: 0 | AC26: для продукта не включается в расчет | AD26: =IF(AI26="не релевантно","не релевантн",(AI26+AJ26)/2) -> 1 | AI26: 1 | AJ26: 1 | AK26: =IF(AL26="не релевантно","не релевантн",(AL26+AM26)/2) -> 1 | AL26: 1 | AM26: 1 | AN26: 0.5 | AO26: 0 | AP26: 1 | AQ26: 0 | AR26: 0 | AS26: для продукта не включается в расчет | AT26: для продукта не включается в расчет | AU26: 1 | AV26: доп объем, % удержания | AW26: 0 | AX26: 0.5 | AY26: 0 | AZ26: 1 | BA26: 1 | BB26: 0 | BC26: 1 | BD26: 0 | BE26: 0 | BF26: TBD | BG26: 0 | BH26: 0 | BI26: не хватает ПШЕ и времени | BJ26: Тырсина Юлия Игоревна | BK26: Прохождение через опроссо значительно ниже 1 тестовой версии Ильи Лащенкова- проверить Отсутвует воронка оттока??? Нет возможности без IT доработки менять опции(кроме ценообразования)???
A27: 19 | B27: CBP | C27: КП | D27: 0.65822785 | E27: Зрелые | F27: продукт | G27: 1 | H27: 1 | I27: 1 | J27: 0.5 | K27: 0.5 | L27: 1 | M27: 0 | N27: 0 | O27: 1 | P27: 0.5 | Q27: 1 | R27: не релевантно | S27: не релевантно | T27: 0 | U27: 0 | W27: 0.5 | X27: 1 | Y27: 0.5 | Z27: 1 | AA27: 0.5 | AB27: 0.5 | AC27: для продукта не включается в расчет | AD27: =IF(AI27="не релевантно","не релевантн",(AI27+AJ27)/2) -> не релевантн | AI27: не релевантно | AJ27: не релевантно | AK27: =IF(AL27="не релевантно","не релевантн",(AL27+AM27)/2) -> не релевантн | AL27: не релевантно | AM27: не релевантно | AN27: 0.5 | AO27: 0 | AP27: 0 | AQ27: 1 | AR27: 1 | AS27: для продукта не включается в расчет | AT27: для продукта не включается в расчет | AU27: 1 | AV27: Кол-во повторных расчетов КП, среднее кол-во расчетов КП за период, вхождение в MAU КП и т.д. | AW27: 0 | AX27: 0.5 | AY27: 0.5 | AZ27: 0 | BA27: не релевантно | BB27: не релевантно | BC27: не релевантно | BD27: не релевантно | BE27: 0 | BF27: TBD | BG27: 1 | BH27: 1 | BI27: ресурсов data-аналитиков (ограниченная команда, ad-hoc запросов всегда много) | BJ27: Кистерский Сергей Анатольевич | BK27: Требуется проверить метрики в блоке-метрики продукта- продукт не выделен в ЕКМ
A28: 24 | B28: CBP | C28: Конверсия | D28: 0.44444444 | E28: Развивающиеся | F28: продукт | G28: 1 | H28: 0.5 | I28: 0.5 | J28: 0.5 | K28: 0.5 | L28: 1 | M28: 0 | N28: 0 | O28: 1 | P28: 1 | Q28: 1 | R28: 0 | S28: 0 | T28: 0 | U28: 1 | V28: новые клиенты в СБОЛ (29000 в месяц), активные клиенты (220000 в месяц) | W28: 0 | X28: 0 | Y28: 0.5 | Z28: 0 | AA28: 0.5 | AB28: 0 | AC28: для продукта не включается в расчет | AD28: =IF(AI28="не релевантно","не релевантн",(AI28+AJ28)/2) -> не релевантн | AI28: не релевантно | AJ28: не релевантно | AK28: =IF(AL28="не релевантно","не релевантн",(AL28+AM28)/2) -> не релевантн | AL28: не релевантно | AM28: не релевантно | AN28: 0 | AO28: не релевантно | AP28: 0 | AQ28: 0 | AR28: 0 | AS28: для продукта не включается в расчет | AT28: для продукта не включается в расчет | AU28: 1 | AV28: нет ответа | AW28: 0 | AX28: 0 | AY28: 1 | AZ28: 0 | BA28: 1 | BB28: 0 | BC28: 1 | BD28: нерелевантно | BE28: 1 | BF28: TBD | BG28: 1 | BH28: 0 | BI28: нет ответа | BJ28: Савенков Илья Игоревич | BK28: Не возможно оценить метрики продукта- ответ по комплексу продуктов
A29: 29 | B29: CBP | C29: Сейфы | D29: 0.47524752 | E29: Развивающиеся | F29: продукт | G29: 1 | H29: 0.5 | I29: 0.5 | J29: 0.5 | K29: 0.5 | L29: 1 | M29: 0 | N29: 0 | O29: 1 | P29: 0 | Q29: 1 | R29: 0 | S29: 0 | T29: 0 | U29: 0 | W29: 1 | X29: 1 | Y29: 0.5 | Z29: 1 | AA29: 1 | AB29: 0 | AC29: для продукта не включается в расчет | AD29: =IF(AI29="не релевантно","не релевантн",(AI29+AJ29)/2) -> 0.5 | AI29: 1 | AJ29: 0 | AK29: =IF(AL29="не релевантно","не релевантн",(AL29+AM29)/2) -> 0.5 | AL29: 1 | AM29: 0 | AN29: 0 | AO29: 0 | AP29: 0 | AQ29: 0 | AR29: 0 | AS29: для продукта не включается в расчет | AT29: для продукта не включается в расчет | AU29: 1 | AV29: % замены сейфов от потенциальных для закрытия, продление договоров, конверсия | AW29: 0 | AX29: 0 | AY29: 1 | AZ29: 0 | BA29: 0 | BB29: 0 | BC29: 0 | BD29: 0 | BE29: 1 | BF29: TBD | BG29: 1 | BH29: 0 | BI29: Ресурсов аналитиков, обучения по имеющимся в банке практикам и инструментам | BJ29: Краснов Игорь Константинович | BK29: Подтвердить релевантность механники черновиков Требуется проверить метрики в блоке-метрики продукта- продукт не выделен в ЕКМ
A30: 34 | B30: CBP | C30: Монеты | D30: 0.54320988 | E30: Развивающиеся | F30: продукт | G30: 1 | H30: 0.5 | I30: 1 | J30: 0.5 | K30: 0.5 | L30: 1 | M30: 0 | N30: 0 | O30: не релевантно | P30: не релевантно | Q30: 0 | R30: не релевантно | S30: не релевантно | T30: 0 | V30: Конкуренты, котировки, остатки, бизнес-план продукта и канала | W30: 0.5 | X30: 1 | Y30: 0.5 | Z30: 1 | AA30: 1 | AB30: 0 | AC30: для продукта не включается в расчет | AD30: =IF(AI30="не релевантно","не релевантн",(AI30+AJ30)/2) -> 0 | AI30: 0 | AJ30: 0 | AK30: =IF(AL30="не релевантно","не релевантн",(AL30+AM30)/2) -> 0.5 | AL30: 1 | AM30: 0 | AN30: 1 | AO30: 1 | AP30: 0 | AQ30: 0 | AR30: 1 | AS30: для продукта не включается в расчет | AT30: для продукта не включается в расчет | AU30: 1 | AV30: ЧКД, конверсия отклика, CSI | AW30: 0 | AX30: 0 | AY30: 1 | AZ30: 0 | BA30: 0 | BB30: 0 | BC30: 0 | BD30: нет продукта | BE30: нет продукта | BF30: TBD | BG30: 0 | BH30: 0 | BI30: Ресурсов DA/DS | BJ30: Румянцева Ирина Викторовна | BK30: Подтвердить бэклог на исследования -От 40 до 79% (https://confluence.sberbank.ru/pages/viewpage.action?pageId=16315384978 ) Требуется проверить метрики в блоке-метрики продукта- продукт не выделен в ЕКМ
A31: 39 | B31: CBP | C31: ОМС | D31: 0.58415842 | E31: Развивающиеся | F31: продукт | G31: 1 | H31: 1 | I31: 1 | J31: 0 | K31: 0.5 | L31: 1 | M31: 0 | N31: 0 | O31: 1 | P31: 0.5 | Q31: 1 | R31: 1 | S31: 0.5 | T31: 1 | U31: 0 | W31: 1 | X31: 1 | Y31: 0.5 | Z31: 1 | AA31: 0.5 | AB31: 0.5 | AC31: для продукта не включается в расчет | AD31: =IF(AI31="не релевантно","не релевантн",(AI31+AJ31)/2) -> 1 | AI31: 1 | AJ31: 1 | AK31: =IF(AL31="не релевантно","не релевантн",(AL31+AM31)/2) -> 0 | AL31: 0 | AM31: 0 | AN31: 0.5 | AO31: 0 | AP31: 1 | AQ31: 0 | AR31: 0 | AS31: для продукта не включается в расчет | AT31: для продукта не включается в расчет | AU31: 1 | AV31: CTR ; CR; Доля в доп. NPV; Кол-во продаж; SCAT | AW31: 0 | AX31: 1 | AY31: 0 | AZ31: 0 | BA31: 1 | BB31: 0 | BC31: 1 | BD31: 0 | BE31: 1 | BF31: TBD | BG31: 1 | BH31: 0 | BI31: ресурса выделенного бизнес-аналитика | BJ31: Тояков Илья Николаевич | BK31: 0
A32: 223 | B32: CBP | C32: Слитки | D32: 0.29892473 | E32: Требуют внимания | F32: продукт | G32: 0.2 | H32: 0.5 | I32: 1 | J32: 0 | K32: 0 | L32: 1 | M32: 0 | N32: 0 | O32: 1 | P32: 0.5 | Q32: 1 | R32: 1 | S32: 0 | T32: 1 | U32: 0 | W32: 0.5 | X32: 1 | Y32: 0 | Z32: 0 | AA32: 0.5 | AB32: 0.5 | AC32: для продукта не включается в расчет | AD32: =IF(AI32="не релевантно","не релевантн",(AI32+AJ32)/2) -> 0 | AI32: 0 | AJ32: 0 | AK32: =IF(AL32="не релевантно","не релевантн",(AL32+AM32)/2) -> 0 | AL32: 0 | AM32: 0 | AN32: 0.5 | AO32: 0 | AP32: 0 | AQ32: 1 | AR32: 1 | AS32: для продукта не включается в расчет | AT32: для продукта не включается в расчет | AU32: 1 | AV32: Кол-во клиентов оформивших ИБС, после покупки слитка. Надбавка для клиентов которые открыли вклад, купили золото. | AW32: 0 | AX32: 0 | AY32: 0 | AZ32: 1 | BA32: 0 | BB32: 0 | BC32: 0 | BD32: не релевантно | BE32: нет продукта | BF32: TBD | BG32: 0 | BH32: 0 | BI32: Всего хватает | BJ32: Скворцов Виталий Михайлович | BK32: Релевантны ли Черновики?
A33: 44 | B33: CBP | C33: Потребительский кредит | D33: 0.76831683 | E33: Зрелые | F33: продукт | G33: 0.4 | H33: 0.5 | I33: 0.5 | J33: 0.5 | K33: 0.5 | L33: 1 | M33: 0 | N33: 0 | O33: 1 | P33: 1 | Q33: 1 | R33: 1 | S33: 0 | T33: 1 | U33: 1 | V33: Данные Frank RG по погашениям портфеля | W33: 1 | X33: 1 | Y33: 0.5 | Z33: 1 | AA33: 1 | AB33: 1 | AC33: для продукта не включается в расчет | AD33: =IF(AI33="не релевантно","не релевантн",(AI33+AJ33)/2) -> 1 | AI33: 1 | AJ33: 1 | AK33: =IF(AL33="не релевантно","не релевантн",(AL33+AM33)/2) -> 1 | AL33: 1 | AM33: 1 | AN33: 1 | AO33: 1 | AP33: 0 | AQ33: 0 | AR33: 1 | AS33: для продукта не включается в расчет | AT33: для продукта не включается в расчет | AU33: 1 | AV33: Uplift от коммуникаций Кампейнинга | AW33: 0 | AX33: 0 | AY33: 1 | AZ33: 0 | BA33: 1 | BB33: 0 | BC33: 1 | BD33: 0.5 | BE33: 0.5 | BF33: TBD | BG33: 1 | BH33: 1 | BI33: Легкий вывод дэшбордов в Навигатор | BJ33: Крамарский Алексей Сергеевич | BK33: Подтвердить бэклог на исследования -От 40 до 79% ссылки на бэклог нет! Подтвердить механнику кросс-сейла после покупки
A34: 49 | B34: CBP | C34: Автокредит | D34: 0.40430108 | E34: Развивающиеся | F34: продукт | G34: 0.4 | H34: 1 | I34: 0 | J34: 0 | K34: 0.5 | L34: 0 | M34: 0 | N34: 0 | O34: 1 | P34: 0.5 | Q34: 1 | R34: 0 | S34: 0 | T34: 0 | U34: 0 | W34: 0.5 | X34: 1 | Y34: 0 | Z34: 0 | AA34: 1 | AB34: 0.5 | AC34: для продукта не включается в расчет | AD34: =IF(AI34="не релевантно","не релевантн",(AI34+AJ34)/2) -> 0 | AI34: 0 | AJ34: 0 | AK34: =IF(AL34="не релевантно","не релевантн",(AL34+AM34)/2) -> 1 | AL34: 1 | AM34: 1 | AN34: 0 | AO34: 0 | AP34: 0 | AQ34: 0 | AR34: 0 | AS34: для продукта не включается в расчет | AT34: для продукта не включается в расчет | AU34: 1 | AV34: доля отказов на данном шаге | AW34: 0 | AX34: 0 | AY34: 0 | AZ34: 0 | BA34: 1 | BB34: 0 | BC34: 1 | BD34: 0 | BE34: нет продукта | BF34: TBD | BG34: 1 | BH34: 1 | BI34: оперативный сбор данных от внешних источников (как пример, БКИ) | BJ34: Бажанова Елена Олеговна | BK34: 0
A35: 54 | B35: CBP | C35: Объект Авто | D35: 0.34408602 | E35: Требуют внимания | F35: продукт | G35: 1 | H35: 0.5 | I35: 0.5 | J35: 0 | K35: 0.5 | L35: 0 | M35: 0 | N35: 0 | O35: 0 | P35: 0 | Q35: 0 | R35: 0 | S35: 0 | T35: 0 | U35: 1 | V35: Activation rate - 40% от новых пользователей раздела вошли в раздел, 15% воспользовались одним из сервисов в течение 60 дней. Retention похожих экосистемных сервисов ~ 30% на 3 мес | W35: 0.5 | X35: 1 | Y35: 0 | Z35: 0 | AA35: 0.5 | AB35: 0 | AC35: для продукта не включается в расчет | AD35: =IF(AI35="не релевантно","не релевантн",(AI35+AJ35)/2) -> 1 | AI35: 1 | AJ35: 1 | AK35: =IF(AL35="не релевантно","не релевантн",(AL35+AM35)/2) -> 1 | AL35: 1 | AM35: 1 | AN35: 0 | AO35: 0 | AP35: 0 | AQ35: 0 | AR35: 0 | AS35: для продукта не включается в расчет | AT35: для продукта не включается в расчет | AU35: 1 | AV35: Retention, CR в сервисы, MAU раздела | AW35: 0 | AX35: 0.5 | AY35: 0 | AZ35: 0 | BA35: 0 | BB35: 0 | BC35: 0 | BE35: нет продукта | BF35: TBD | BG35: 0 | BH35: 0 | BI35: возможности оперативно собирать дашборды и сквозные воронки в Навигаторе и кликстриме через пользовательский интерфейс, делать преднастроенные дашборды с воронками с динамикой показателей по периодам, описанного и удобного Feature store для сегментации клиентской базы и аналитики, оперативного получения данных из ДЗО и их использования в сквозных воронках, Process Mining в контуре Sigma | BJ35: Кравченко Анна Геннадьевна | BK35: 0
A36: 59 | B36: CBP | C36: POS-кредиты | D36: 0.49896907 | E36: Развивающиеся | F36: продукт | G36: 0.6 | H36: 1 | I36: 0 | J36: 0 | K36: 0 | L36: 0 | M36: 0 | N36: 0 | O36: 1 | P36: 0.5 | Q36: 1 | R36: 0 | S36: 0 | T36: 0 | U36: 1 | V36: партнерская воронка в разрезе платежных методов, брокеров и собственных решений | W36: 0.5 | X36: 1 | Y36: 0.5 | Z36: 1 | AA36: 1 | AB36: 1 | AC36: для продукта не включается в расчет | AD36: =IF(AI36="не релевантно","не релевантн",(AI36+AJ36)/2) -> 0.5 | AI36: 1 | AJ36: 0 | AK36: =IF(AL36="не релевантно","не релевантн",(AL36+AM36)/2) -> 0 | AL36: 0 | AM36: 0 | AN36: 1 | AO36: 1 | AP36: 0 | AQ36: 0 | AR36: 1 | AS36: для продукта не включается в расчет | AT36: для продукта не включается в расчет | AU36: 1 | AV36: анализ сквозной воронки от оффера до продажи | AW36: 0 | AX36: 0 | AY36: 0.5 | AZ36: 0 | BA36: 0 | BB36: 0 | BC36: 0 | BD36: 0 | BE36: 1 | BF36: TBD | BG36: 0 | BH36: 0 | BI36: ПШЕ аналитиков | BJ36: Блинов Дмитрий Игоревич | BK36: Нужно перепройти опрос отдельно по продукту сейчас все вместе POS/BNPL/КДЗП/Образоввательный кредит
A37: 64 | B37: CBP | C37: BNPL | D37: 0.43762376 | E37: Развивающиеся | F37: Исключить | G37: 0.8 | H37: 1 | I37: 0 | J37: 0 | K37: 0 | L37: 0 | M37: 0 | N37: 0 | O37: 0.5 | P37: 0.5 | Q37: 0.5 | R37: 0 | S37: 0 | T37: 0 | U37: 0 | W37: 1 | X37: 1 | Y37: 0.5 | Z37: 1 | AA37: 1 | AB37: 0.5 | AC37: для продукта не включается в расчет | AD37: =IF(AI37="не релевантно","не релевантн",(AI37+AJ37)/2) -> 0 | AI37: 0 | AJ37: 0 | AK37: =IF(AL37="не релевантно","не релевантн",(AL37+AM37)/2) -> 0 | AL37: 0 | AM37: 0 | AN37: 0.5 | AO37: 0 | AP37: 1 | AQ37: 0 | AR37: 1 | AS37: для продукта не включается в расчет | AT37: для продукта не включается в расчет | AU37: 1 | AV37: приобретение второго идентичного продукта, продажа смежного продукта | AW37: 0 | AX37: 0.5 | AY37: 0.5 | AZ37: 0 | BA37: 1 | BB37: 0 | BC37: 1 | BD37: 0 | BE37: 0.5 | BF37: TBD | BG37: 0 | BH37: 0 | BI37: автоматизации | BJ37: Блинов Дмитрий Игоревич | BK37: Нужно перепройти опрос отдельно по продукту сейчас все вместе POS/BNPL/КДЗП/Образоввательный кредит
A38: 69 | B38: CBP | C38: Образовательный кредит | D38: 0.091954023 | E38: Требуют внимания | F38: Исключить | G38: 1 | H38: 0 | I38: 1 | J38: 0 | K38: 0 | L38: 1 | M38: 0 | N38: 0 | O38: не релевантно | P38: не релевантно | Q38: 0 | R38: 0 | S38: 0 | T38: 0 | U38: 0 | W38: 0 | X38: 0 | Y38: 0 | AA38: 0 | AB38: 0 | AC38: для продукта не включается в расчет | AD38: =IF(AI38="не релевантно","не релевантн",(AI38+AJ38)/2) -> 0 | AI38: 0 | AJ38: 0 | AK38: =IF(AL38="не релевантно","не релевантн",(AL38+AM38)/2) -> 0 | AL38: 0 | AM38: 0 | AN38: 0 | AO38: не релевантно | AP38: 0 | AQ38: 0 | AR38: 0 | AS38: для продукта не включается в расчет | AT38: для продукта не включается в расчет | AU38: 0 | AV38: 0 | AW38: 0 | AX38: 0 | AY38: 0 | AZ38: 0 | BA38: 0 | BB38: 0 | BC38: 0 | BD38: 0 | BF38: TBD | BG38: 0 | BH38: 0 | BI38: 0 | BJ38: Блинов Дмитрий Игоревич | BK38: Нужно перепройти опрос отдельно по продукту сейчас все вместе POS/BNPL/КДЗП/Образоввательный кредит
A39: 181 | B39: ДомКлик | C39: Сделка с Первичным жильём | D39: 0.68041237 | E39: Зрелые | F39: продукт | G39: 1 | H39: 1 | I39: 1 | J39: 0.5 | K39: 0.5 | L39: 1 | M39: 1 | N39: 1 | O39: 1 | P39: 0.5 | Q39: 1 | R39: не релевантно | S39: не релевантно | T39: 0 | U39: 1 | V39: Роскадастр | W39: 0.5 | X39: 1 | Y39: 0.5 | Z39: 1 | AA39: 1 | AB39: 0 | AC39: для продукта не включается в расчет | AD39: =IF(AI39="не релевантно","не релевантн",(AI39+AJ39)/2) -> 0.5 | AI39: 1 | AJ39: 0 | AK39: =IF(AL39="не релевантно","не релевантн",(AL39+AM39)/2) -> не релевантн | AL39: не релевантно | AM39: не релевантно | AN39: 0.5 | AO39: 0 | AP39: 1 | AQ39: 0 | AR39: 1 | AS39: для продукта не включается в расчет | AT39: для продукта не включается в расчет | AU39: 1 | AV39: Уровень проникновения продукта в выдачу кредитов. доля клиентов, совершивших сделку с 1+ продуктом | AW39: 0 | AX39: 0 | AY39: 1 | AZ39: 0 | BA39: 1 | BB39: 1 | BC39: 0 | BD39: 1 | BE39: 1 | BF39: TBD | BG39: 1 | BH39: 0 | BI39: Отчётность по продуктам Управления торгового финансирования. (счета эскроу, аккредитивы) | BJ39: Поддубный Иван Сергеевич | BK39: 0
A40: 186 | B40: ДомКлик | C40: Много денег (НКПЗН) | D40: 0.6 | E40: Зрелые | F40: продукт | G40: 1 | H40: 1 | I40: 0 | J40: 0.5 | K40: 0.5 | L40: 0 | M40: 1 | N40: 0 | O40: 1 | P40: 1 | Q40: 1 | R40: 0 | S40: 0 | T40: 0 | U40: 1 | V40: Frank RG | W40: 0.5 | X40: 1 | Y40: 0 | Z40: 0 | AA40: 1 | AB40: 0 | AC40: для продукта не включается в расчет | AD40: =IF(AI40="не релевантно","не релевантн",(AI40+AJ40)/2) -> 1 | AI40: 1 | AJ40: 1 | AK40: =IF(AL40="не релевантно","не релевантн",(AL40+AM40)/2) -> 0 | AL40: 0 | AM40: 0 | AN40: 1 | AO40: 1 | AP40: 0 | AQ40: 0 | AR40: 1 | AS40: для продукта не включается в расчет | AT40: для продукта не включается в расчет | AU40: 1 | AV40: Кликабельность и конверсии, результат | AW40: 0 | AX40: 0.5 | AY40: 1 | AZ40: 0 | BA40: 1 | BB40: 1 | BC40: 0 | BD40: 1 | BE40: 1 | BF40: TBD | BG40: 1 | BH40: 0 | BI40: Собственые дата-инеженеры | BJ40: Спиваков Андрей Дмитриевич | BK40: Подтвердить релевантна или нет воронка оттока , Проверить релевантнрость механник- написать какие нужно исключить Черновики? Есть ли кампейнинг? Self service??
...

Sheet свод_каналы
F2: 5 | G2: 6 | H2: 7 | I2: 8 | J2: 9
G3: =H3 -> СБерKids | H3: =F18 -> СБерKids
G4: СберKids | H4: =SUM(H33:H176)+H17+SUM(H189:H192)-H43-H44-H45-H60-H75-H89-H157-H161 -> 27.25 | I4: =SUM(I33:I176)+I17+SUM(I189:I192)-I60-I75-I89-I157-I161 -> 14.5 | J4: =I4/H4 -> 0.53211009
D5: Вопрос | F5: Ответ | G5: Комментарий | H5: =F18 -> СБерKids
C6: Вводные данные | D6: id | F6: 6 | H6: макс балл | I6: факт | J6: %
D7: Представьтесь, пожалуйста | F7: Бессонов Кирилл Павлович | H7: =F7 -> Бессонов Кирилл Павлович
D8: Выберете ваш юнит | F8: Занять и сберегать (Core Banking)
F9: Развитие клиентского опыта (CX)
F10: Транзакционный банкинг (Daily Banking)
F11: Данные и рекомендательные системы (Data)
F12: Забота о клиентах (Phygital channels)
F13: Домклик
F14: Цифровые каналы (Digital channels) | G14: 1
F15: Управление благосостояния
F16: eCom
A17: 1 | F17: Индустрии рекламы и развлечений (Entertainment) | H17: =SUM(H19:H32) -> 1 | I17: =SUM(I19:I32) -> 1 | J17: =I17/H17 -> 1
D18: Укажите, пожалуйста, владельцем какого канала вы являетесь | F18: СБерKids | I18: =F18 -> СБерKids
C19: Блок 1. Общие метрики канала | D19: Напишите процент проникновения вашего канала в клиентскую базу Сбера | F19: Укажите процент проникновения: ЦА - Дети 6-13 лет включительно. MAU канала ~3 млн | G19: 1 | H19: 0.1 | I19: 0.1 | J19: =I19/H19 -> 1
F20: Не релевантно для вашего канала
D21: Какое MAU у вашего канала? | F21: Укажите общий MAU канала - 2,8 млн | G21: 1 | H21: 0.1 | I21: 0.1 | J21: =I21/H21 -> 1
F22: При наличии, укажите MAU IOS - 2,3 млн | G22: 1 | H22: 0.1 | I22: 0.1 | J22: =I22/H22 -> 1
F23: При наличии, укажите MAU Android - 500к | G23: 1 | H23: 0.1 | I23: 0.1 | J23: =I23/H23 -> 1
F24: При наличии, укажите MAU Web | H24: 0.1 | I24: 0.1 | J24: =I24/H24 -> 1
F25: Не релевантно для вашего канала
D26: Какое DAU у вашего канала? | F26: Укажите общий DAU канала - 700К | G26: 1 | H26: 0.1 | I26: 0.1 | J26: =I26/H26 -> 1
F27: При наличии, укажите DAU IOS - 150К | G27: 1 | H27: 0.1 | I27: 0.1 | J27: =I27/H27 -> 1
F28: При наличии, укажите DAU Android - 550К | G28: 1 | H28: 0.1 | I28: 0.1 | J28: =I28/H28 -> 1
F29: При наличии, укажите DAU Web | H29: 0.1 | I29: 0.1 | J29: =I29/H29 -> 1
F30: Не релевантно для вашего канала
D31: Какое отношение DAU/MAU (липкость) у вашего канала? | F31: Укажите отношение DAU/MAU - 25% | G31: 1 | H31: 0.1 | I31: 0.1 | J31: =I31/H31 -> 1
F32: Не релевантно для вашего канала
A33: 2 | D33: Какими инструментами вы пользуетесь для мониторинга метрик из вопросов выше: | F33: Дашборд в Навигаторе (доступны все метрики) | G33: 1 | H33: 0.5 | I33: =IF(G33=1,0.5,IF(AND(G38=1,G36=""),0.5,IF(OR(G35=1,G34=1),0.25,0))) -> 0.5 | J33: =IFERROR(IF(H33=0,"",I33/H33),"") -> 1
F34: Дашборд в Навигаторе (доступна часть метрик) | J34: =IFERROR(IF(H34=0,"",I34/H34),"")
F35: Запрашиваете необходимую информацию у аналитиков | G35: 1 | J35: =IFERROR(IF(H35=0,"",I35/H35),"")
F36: Собственная отчетность канала (не Навигатор)
F37: Свой вариант ответа | G37: 1
F38: Затрудняюсь ответить
C39: Блок 2. Цели, факторный анализ, прогноз | D39: Отчетность по целям/драйверам/прогнозам продукта уровня ЛЮ-ЛТ выведена на мониторинг и доступна владельцу продукта | F39: Цели | G39: В Навигаторе | H39: 1 | I39: =IF(G39="Отсутствует",0,IF(AND(G39="В Навигаторе",I193=1),1,IF(AND(G39="В Навигаторе",I193<>1),0,IF(G39="Не в Навигаторе",0.5,0)))) -> 0 | J39: =IFERROR(IF(H39=0,"",I39/H39),"") -> 0
F40: Факторный анализ | G40: В Навигаторе | H40: 1 | I40: =IF(G40="Отсутствует",0,IF(AND(G40="В Навигаторе",I162=1),1,IF(AND(G40="В Навигаторе",I162<>1),0,IF(G40="Не в Навигаторе",0.5,0)))) -> 0 | J40: =IFERROR(IF(H40=0,"",I40/H40),"") -> 0
F41: Прогноз по целям | G41: В Навигаторе | H41: 1 | I41: =IF(G41="Отсутствует",0,IF(AND(G41="В Навигаторе",I163=1),1,IF(AND(G41="В Навигаторе",I163<>1),0,IF(G41="Не в Навигаторе",0.5,0)))) -> 0 | J41: =IFERROR(IF(H41=0,"",I41/H41),"") -> 0
...

Sheet свод_сегменты
I1: 9 | J1: 10 | K1: 11 | L1: 12 | M1: 13 | N1: 14 | O1: 15 | P1: 16 | Q1: 17 | R1: 18 | S1: 19 | T1: 20 | U1: 21 | V1: 22 | W1: 23 | X1: 24 | Y1: 25 | Z1: 26 | AA1: 27 | AB1: 28 | AC1: 29 | AD1: 30 | AE1: 31 | AF1: 32 | AG1: 33 | AH1: 34 | AI1: 35 | AJ1: 36 | AK1: 37 | AL1: 38 | AM1: 39 | AN1: 40 | AO1: 41 | AP1: 42 | AQ1: 43
K2: Возрастной | P2: Возрастной | U2: Возрастной | Z2: Возрастной | AE2: Доходный | AJ2: Доходный | AO2: Доходный
K3: Дети | P3: Молодежь | U3: =S23 -> Рабочий возраст | Z3: =X24 -> Зрелость | AE3: =AE19 -> Top Affluent | AJ3: =AH18 -> PB | AO3: МВС
K4: =SUM(K25:K216)+K222 -> 19.35 | L4: =SUM(L25:L216)-L86-L101-L164-L195-L149-L163+L222 -> 10.95 | M4: =L4/K4 -> 0.56589147 | P4: =SUM(P25:P216)+P222 -> 19.65 | Q4: =SUM(Q25:Q216)-Q86-Q101-Q164-Q195-Q149+Q222 -> 9.45 | R4: =Q4/P4 -> 0.48091603 | U4: =SUM(U25:U216)+U222 -> 20.55 | V4: =SUM(V25:V216)-V86-V101-V164-V195-V163-V149+V222 -> 12.8 | W4: =V4/U4 -> 0.62287105 | Z4: =SUM(Z25:Z216)+Z222 -> 19.65 | AA4: =SUM(AA25:AA216)-AA86-AA101-AA164-AA195-AA149+AA222 -> 7.9 | AB4: =AA4/Z4 -> 0.40203562 | AE4: =SUM(AE25:AE216)+AE222 -> 22.75 | AF4: =SUM(AF25:AF216)-AF86-AF101-AF149-AF169-AF195-AF185-AF156+AF222 -> 12.625 | AG4: =AF4/AE4 -> 0.55494505 | AJ4: =SUM(AJ25:AJ216)+AJ222 -> 22.25 | AK4: =SUM(AK25:AK216)-AK86-AK101-AK149-AK169-AK195-AK185-AK156+AK222 -> 11.625 | AL4: =AK4/AJ4 -> 0.52247191 | AO4: =SUM(AO25:AO216)+AO222 -> 22.25 | AP4: =SUM(AP25:AP216)-AP86-AP101-AP149-AP169-AP163-AP195-AP185-AP156+AP222 -> 9.125 | AQ4: =AP4/AO4 -> 0.41011236
D5: Вопрос | E5: Ответ | G5: Оценка | I5: Ответ | J5: Комментарий | K5: =K3 -> Дети | N5: Ответ | O5: Комментарий | P5: =P3 -> Молодежь | S5: Ответ | T5: Комментарий | U5: =U3 -> Рабочий возраст | X5: Ответ | Y5: Комментарий | Z5: =Z3 -> Зрелость | AC5: Ответ | AD5: Комментарий | AE5: =AE3 -> Top Affluent | AH5: Ответ | AI5: Комментарий | AJ5: =AJ3 -> PB | AM5: Ответ | AN5: Комментарий | AO5: =AO3 -> МВС
B6: Вводные данные | D6: id | I6: 8 | K6: макс балл | L6: факт | M6: % | N6: 11 | P6: макс балл | Q6: факт | R6: % | S6: 16 | U6: макс балл | V6: факт | W6: % | X6: 19 | Z6: макс балл | AA6: факт | AB6: % | AC6: 13 | AE6: макс балл | AF6: факт | AG6: % | AH6: 17 | AJ6: макс балл | AK6: факт | AL6: % | AM6: 21 | AO6: макс балл | AP6: факт | AQ6: %
A7: 100 | D7: Представьтесь, пожалуйста | I7: Буканова | K7: =I7 -> Буканова | N7: Водяницкий Андрей Андреевич | P7: =N7 -> Водяницкий Андрей Андреевич | S7: Кудряшов Грант Андреевич | U7: =S7 -> Кудряшов Грант Андреевич | X7: Серебряников Антон Олегович | Z7: =X7 -> Серебряников Антон Олегович | AC7: Багдасарян Артем Робертович | AE7: =AC7 -> Багдасарян Артем Робертович | AH7: Арташес Маркарьян | AJ7: =AH7 -> Арташес Маркарьян | AM7: Бахтанов Андрей Юрьевич | AO7: =AM7 -> Бахтанов Андрей Юрьевич
D8: Выберете ваш юнит | E8: Занять и сберегать (Core Banking) | I8: Занять и сберегать (Core Banking) | N8: Занять и сберегать (Core Banking) | S8: Занять и сберегать (Core Banking) | X8: Занять и сберегать (Core Banking) | AC8: Занять и сберегать (Core Banking) | AH8: Занять и сберегать (Core Banking) | AM8: Занять и сберегать (Core Banking)
E9: Развитие клиентского опыта (CX) | I9: Развитие клиентского опыта (CX) | J9: 1 | N9: Развитие клиентского опыта (CX) | O9: 1 | S9: Развитие клиентского опыта (CX) | T9: 1 | X9: Развитие клиентского опыта (CX) | Y9: 1 | AC9: Развитие клиентского опыта (CX) | AD9: 1 | AH9: Развитие клиентского опыта (CX) | AI9: 1 | AM9: Развитие клиентского опыта (CX) | AN9: 1
E10: Транзакционный банкинг (Daily Banking) | I10: Транзакционный банкинг (Daily Banking) | N10: Транзакционный банкинг (Daily Banking) | S10: Транзакционный банкинг (Daily Banking) | X10: Транзакционный банкинг (Daily Banking) | AC10: Транзакционный банкинг (Daily Banking) | AH10: Транзакционный банкинг (Daily Banking) | AM10: Транзакционный банкинг (Daily Banking)
E11: Данные и рекомендательные системы (Data) | I11: Данные и рекомендательные системы (Data) | N11: Данные и рекомендательные системы (Data) | S11: Данные и рекомендательные системы (Data) | X11: Данные и рекомендательные системы (Data) | AC11: Данные и рекомендательные системы (Data) | AH11: Данные и рекомендательные системы (Data) | AM11: Данные и рекомендательные системы (Data)
E12: Забота о клиентах (Phygital channels) | I12: Забота о клиентах (Phygital channels) | N12: Забота о клиентах (Phygital channels) | S12: Забота о клиентах (Phygital channels) | X12: Забота о клиентах (Phygital channels) | AC12: Забота о клиентах (Phygital channels) | AH12: Забота о клиентах (Phygital channels) | AM12: Забота о клиентах (Phygital channels)
E13: Домклик | I13: Домклик | N13: Домклик | S13: Домклик | X13: Домклик | AC13: Домклик | AH13: Домклик | AM13: Домклик
E14: Цифровые каналы (Digital channels) | I14: Цифровые каналы (Digital channels) | N14: Цифровые каналы (Digital channels) | S14: Цифровые каналы (Digital channels) | X14: Цифровые каналы (Digital channels) | AC14: Цифровые каналы (Digital channels) | AH14: Цифровые каналы (Digital channels) | AM14: Цифровые каналы (Digital channels)
E15: Управление благосостояния | I15: Управление благосостояния | N15: Управление благосостояния | S15: Управление благосостояния | X15: Управление благосостояния | AC15: Управление благосостояния | AH15: Управление благосостояния | AM15: Управление благосостояния
E16: eCom | I16: eCom | N16: eCom | S16: eCom | X16: eCom | AC16: eCom | AH16: eCom | AM16: eCom
E17: Индустрии рекламы и развлечений (Entertainment) | I17: Индустрии рекламы и развлечений (Entertainment) | N17: Индустрии рекламы и развлечений (Entertainment) | S17: Индустрии рекламы и развлечений (Entertainment) | X17: Индустрии рекламы и развлечений (Entertainment) | AC17: Индустрии рекламы и развлечений (Entertainment) | AH17: Индустрии рекламы и развлечений (Entertainment) | AM17: Индустрии рекламы и развлечений (Entertainment)
D18: Выберете, пожалуйста, владельцем какого сегмента вы являетесь | E18: PB | I18: PB | K18: =IF(J18=1,I18,"") | N18: PB | P18: =IF(O18=1,N18,"") | S18: PB | U18: =IF(T18=1,S18,"") | X18: PB | Z18: =IF(Y18=1,X18,"") | AC18: PB | AE18: =IF(AD18=1,AC18,"") | AH18: PB | AI18: 1 | AJ18: =IF(AI18=1,AH18,"") -> PB | AM18: PB | AO18: =IF(AN18=1,AM18,"")
E19: Top Affluent | I19: Top Affluent | K19: =IF(J19=1,I19,"") | N19: Top Affluent | P19: =IF(O19=1,N19,"") | S19: Top Affluent | U19: =IF(T19=1,S19,"") | X19: Top Affluent | Z19: =IF(Y19=1,X19,"") | AC19: Top Affluent | AD19: 1 | AE19: =IF(AD19=1,AC19,"") -> Top Affluent | AH19: Top Affluent | AJ19: =IF(AI19=1,AH19,"") | AM19: Top Affluent | AO19: =IF(AN19=1,AM19,"")
E20: МВС | I20: МВС | K20: =IF(J20=1,I20,"") | N20: МВС | P20: =IF(O20=1,N20,"") | S20: МВС | U20: =IF(T20=1,S20,"") | X20: МВС | Z20: =IF(Y20=1,X20,"") | AC20: МВС | AE20: =IF(AD20=1,AC20,"") | AH20: МВС | AJ20: =IF(AI20=1,AH20,"") | AM20: МВС | AN20: 1 | AO20: =IF(AN20=1,AM20,"") -> МВС
E21: Дети | I21: Дети | J21: 1 | K21: =IF(J21=1,I21,"") -> Дети | N21: Дети | P21: =IF(O21=1,N21,"") | S21: Дети | U21: =IF(T21=1,S21,"") | X21: Дети | Z21: =IF(Y21=1,X21,"") | AC21: Дети | AE21: =IF(AD21=1,AC21,"") | AH21: Дети | AJ21: =IF(AI21=1,AH21,"") | AM21: Дети | AO21: =IF(AN21=1,AM21,"")
E22: Молодежь | I22: Молодежь | K22: =IF(J22=1,I22,"") | N22: Молодежь | O22: 1 | P22: =IF(O22=1,N22,"") -> Молодежь | S22: Молодежь | U22: =IF(T22=1,S22,"") | X22: Молодежь | Z22: =IF(Y22=1,X22,"") | AC22: Молодежь | AE22: =IF(AD22=1,AC22,"") | AH22: Молодежь | AJ22: =IF(AI22=1,AH22,"") | AM22: Молодежь | AO22: =IF(AN22=1,AM22,"")
E23: Рабочий возраст | I23: Рабочий возраст | K23: =IF(J23=1,I23,"") | N23: Рабочий возраст | P23: =IF(O23=1,N23,"") | S23: Рабочий возраст | T23: 1 | U23: =IF(T23=1,S23,"") -> Рабочий возраст | X23: Рабочий возраст | Z23: =IF(Y23=1,X23,"") | AC23: Рабочий возраст | AE23: =IF(AD23=1,AC23,"") | AH23: Рабочий возраст | AJ23: =IF(AI23=1,AH23,"") | AM23: Рабочий возраст | AO23: =IF(AN23=1,AM23,"")
A24: 1 | E24: Зрелость | I24: Зрелость | K24: =SUM(K25:K64) -> 0.6 | L24: =SUM(L25:L64) -> 0.45 | M24: =L24/K24 -> 0.75 | N24: Зрелость | P24: =SUM(P25:P64) -> 0.9 | Q24: =SUM(Q25:Q64) -> 0.45 | R24: =Q24/P24 -> 0.5 | S24: Зрелость | U24: =SUM(U25:U64) -> 1.8 | V24: =SUM(V25:V64) -> 1.8 | W24: =V24/U24 -> 1 | X24: Зрелость | Y24: 1 | Z24: =SUM(Z25:Z64) -> 0.9 | AA24: =SUM(AA25:AA64) -> 0.9 | AB24: =AA24/Z24 -> 1 | AC24: Зрелость | AE24: =SUM(AE25:AE64) -> 1 | AF24: =SUM(AF25:AF64) -> 0.875 | AG24: =AF24/AE24 -> 0.875 | AH24: Зрелость | AJ24: =SUM(AJ25:AJ64) -> 1 | AK24: =SUM(AK25:AK64) -> 0.875 | AL24: =AK24/AJ24 -> 0.875 | AM24: Зрелость | AO24: =SUM(AO25:AO64) -> 1 | AP24: =SUM(AP25:AP64) -> 0.875 | AQ24: =AP24/AO24 -> 0.875
