Workbook

Sheet титул
B1: Юнит | C1: Продукт | D1: Оценка | E1: Группа | F1: тип
A2: 75 | B2: УБ | C2: ОСАГО | D2: 0.62574257 | E2: Зрелые | F2: продукт
A3: 80 | B3: УБ | C3: КАСКО | D3: 0.62574257 | E3: Зрелые | F3: продукт
A4: 85 | B4: УБ | C4: ИнвестКопилка | D4: 0.47640449 | E4: Развивающиеся | F4: продукт
A5: 90 | B5: УБ | C5: СберСова | D5: 0.47293447 | E5: Развивающиеся | F5: продукт
A6: 95 | B6: УБ | C6: Залоговое страхование (корпоративное) | D6: 0.36082474 | E6: Требуют внимания | F6: продукт
A7: 100 | B7: УБ | C7: НСЖ | D7: 0.46419753 | E7: Развивающиеся | F7: продукт
A8: 105 | B8: УБ | C8: ИСЖ | D8: 0.46236559 | E8: Развивающиеся | F8: продукт
A9: 110 | B9: УБ | C9: Страхование жизни | D9: 0.4 | E9: Развивающиеся | F9: продукт
A10: 115 | B10: УБ | C10: Брокерский счет | D10: 0.42178218 | E10: Развивающиеся | F10: продукт
A11: 120 | B11: УБ | C11: БПИФ | D11: 0.47010309 | E11: Развивающиеся | F11: продукт
A12: 125 | B12: УБ | C12: ЗПИФ | D12: 0.63505155 | F12: продукт
A13: 130 | B13: УБ | C13: ПДС | D13: 0.53195876 | E13: Развивающиеся | F13: продукт
A14: 135 | B14: УБ | C14: ОПИФ | D14: 0.60990099 | E14: Зрелые | F14: продукт
A15: 140 | B15: УБ | C15: ВЗР | D15: 0.57029703 | E15: Развивающиеся | F15: продукт
A16: 145 | B16: УБ | C16: ДУ | D16: 0.38651685 | E16: Требуют внимания | F16: продукт
A17: 150 | B17: УБ | C17: Страхование залога (к ипотеке) | D17: 0.51546392 | E17: Развивающиеся | F17: продукт
A18: 155 | B18: УБ | C18: Личная защита Плюс | D18: 0.59381443 | E18: Развивающиеся | F18: продукт
A19: 160 | B19: УБ | C19: Защита на любой случай | D19: 0.54491018 | E19: Развивающиеся | F19: продукт
A20: 165 | B20: УБ | C20: ДСЖ ПК | D20: 0.53882353 | E20: Развивающиеся | F20: продукт
A21: 170 | B21: УБ | C21: ДСЖ КК | D21: 0.55730337 | E21: Развивающиеся | F21: продукт
A22: 175 | B22: УБ | C22: ЦФА | D22: 0.28808864 | E22: Требуют внимания | F22: продукт
A23: 14 | B23: CBP | C23: Вклады+НС | D23: 0.39805825 | E23: Развивающиеся | F23: продукт
A24: 19 | B24: CBP | C24: КП | D24: 0.60759494 | E24: Зрелые | F24: продукт
... A69: 420 | B69: СХ | C69: СберСпасибо | D69: 0.68493151 | E69: Зрелые | F69: продукт

Sheet деталка
A1: fake_id | B1: perc_id | C1: value_id | D1: max_value_id | E1: Юнит | F1: Продукт | G1: metric | H1: metric_name | I1: value | J1: max_value | K1: metric_group | L1: metric_subgroup | M1: metric_footer | N1: recommendation | O1: recommendation_group | P1: type | Q1: sort
A2: 18 | B2: 19 | C2: 18 | D2: 17 | E2: CX | F2: Молодежь | G2: 99 | H2: Активная клиентская база | I2: 0.15 | J2: 0.3 | K2: =VLOOKUP(H2,metric_dict!A:B,2,0) -> Знание ключевых метрик | L2: =IF(VLOOKUP(H2,metric_dict!A:C,3,0)=0,"",VLOOKUP(H2,metric_dict!A:C,3,0)) | M2: =VLOOKUP(H2,metric_dict!A:AA,4,0) -> Знание значения метрики активной клиентской базы | N2: =VLOOKUP(H2,metric_dict!A:AA,5,0) -> Знание метрик и инструментов | O2: =VLOOKUP(H2,metric_dict!A:AA,6,0) -> 1 | P2: segment | Q2: =VLOOKUP(H2,metric_dict!A:AA,7,0) -> 5
A3: 18 | B3: 19 | C3: 18 | D3: 17 | E3: CX | F3: Молодежь | G3: 98 | H3: Кол-во Major клиентов | I3: 0.15 | J3: 0.3 | K3: =VLOOKUP(H3,metric_dict!A:B,2,0) -> Знание ключевых метрик | L3: =IF(VLOOKUP(H3,metric_dict!A:C,3,0)=0,"",VLOOKUP(H3,metric_dict!A:C,3,0)) | M3: =VLOOKUP(H3,metric_dict!A:AA,4,0) -> Знание метрики Major | N3: =VLOOKUP(H3,metric_dict!A:AA,5,0) -> Знание метрик и инструментов | O3: =VLOOKUP(H3,metric_dict!A:AA,6,0) -> 1 | P3: segment | Q3: =VLOOKUP(H3,metric_dict!A:AA,7,0) -> 6
A4: 18 | B4: 19 | C4: 18 | D4: 17 | E4: CX | F4: Молодежь | G4: 97 | H4: Кол-во клиентов с 2+ нефин. сервисов | I4: 0.15 | J4: 0.3 | K4: =VLOOKUP(H4,metric_dict!A:B,2,0) -> Знание ключевых метрик | L4: =IF(VLOOKUP(H4,metric_dict!A:C,3,0)=0,"",VLOOKUP(H4,metric_dict!A:C,3,0)) | M4: =VLOOKUP(H4,metric_dict!A:AA,4,0) -> Знание метрики кол-во клиентов с 2+ нефин.сервисов | N4: =VLOOKUP(H4,metric_dict!A:AA,5,0) -> Знание метрик и инструментов | O4: =VLOOKUP(H4,metric_dict!A:AA,6,0) -> 1 | P4: segment | Q4: =VLOOKUP(H4,metric_dict!A:AA,7,0) -> 7
A5: 18 | B5: 19 | C5: 18 | D5: 17 | E5: CX | F5: Молодежь | G5: 2 | H5: Знание об отчетности в Навигаторе | I5: 0.25 | J5: 0.5 | K5: =VLOOKUP(H5,metric_dict!A:B,2,0) -> Знание ключевых метрик | L5: =IF(VLOOKUP(H5,metric_dict!A:C,3,0)=0,"",VLOOKUP(H5,metric_dict!A:C,3,0)) | M5: =VLOOKUP(H5,metric_dict!A:AA,4,0) -> Понимание доступной отчетности и регулярного мониторинга | N5: =VLOOKUP(H5,metric_dict!A:AA,5,0) -> Знание метрик и инструментов | O5: =VLOOKUP(H5,metric_dict!A:AA,6,0) -> 1 | P5: segment | Q5: =VLOOKUP(H5,metric_dict!A:AA,7,0) -> 13
A6: 18 | B6: 19 | C6: 18 | D6: 17 | E6: CX | F6: Молодежь | G6: 3 | H6: Цели выведены на мониторинг | I6: 1 | J6: 1 | K6: =VLOOKUP(H6,metric_dict!A:B,2,0) -> Цели | L6: =IF(VLOOKUP(H6,metric_dict!A:C,3,0)=0,"",VLOOKUP(H6,metric_dict!A:C,3,0)) | M6: =VLOOKUP(H6,metric_dict!A:AA,4,0) -> Регулярное обновление в Навигаторе | N6: =VLOOKUP(H6,metric_dict!A:AA,5,0) -> Обогащение целей/драйверов/прогнозов в Навигаторе | O6: =VLOOKUP(H6,metric_dict!A:AA,6,0) -> 2 | P6: segment | Q6: =VLOOKUP(H6,metric_dict!A:AA,7,0) -> 1
A7: 18 | B7: 19 | C7: 18 | D7: 17 | E7: CX | F7: Молодежь | G7: 4 | H7: Факторный анализ — драйверы 1–2 ур. | I7: 0.5 | J7: 1 | K7: =VLOOKUP(H7,metric_dict!A:B,2,0) -> Цели | L7: =IF(VLOOKUP(H7,metric_dict!A:C,3,0)=0,"",VLOOKUP(H7,metric_dict!A:C,3,0)) | M7: =VLOOKUP(H7,metric_dict!A:AA,4,0) -> Согласно модели бизнес-процесса | N7: =VLOOKUP(H7,metric_dict!A:AA,5,0) -> Декомпозировать значения целей на драйверы | O7: =VLOOKUP(H7,metric_dict!A:AA,6,0) -> 7 | P7: segment | Q7: =VLOOKUP(H7,metric_dict!A:AA,7,0) -> 2
A8: 18 | B8: 19 | C8: 18 | D8: 17 | E8: CX | F8: Молодежь | G8: 5 | H8: Прогноз по целям | I8: 0 | J8: 1 | K8: =VLOOKUP(H8,metric_dict!A:B,2,0) -> Цели | L8: =IF(VLOOKUP(H8,metric_dict!A:C,3,0)=0,"",VLOOKUP(H8,metric_dict!A:C,3,0)) | M8: =VLOOKUP(H8,metric_dict!A:AA,4,0) -> Прогноз выведен в Навигатор | N8: =VLOOKUP(H8,metric_dict!A:AA,5,0) -> Сформировать прогнозные значения по целям | O8: =VLOOKUP(H8,metric_dict!A:AA,6,0) -> 8 | P8: segment | Q8: =VLOOKUP(H8,metric_dict!A:AA,7,0) -> 3
A9: 18 | B9: 19 | C9: 18 | D9: 17 | E9: CX | F9: Молодежь | G9: 9 | H9: Привлечение.Регулярная отчётность | I9: 0.25 | J9: 0.5 | K9: =VLOOKUP(H9,metric_dict!A:B,2,0) -> Воронка привлечения | L9: =IF(VLOOKUP(H9,metric_dict!A:C,3,0)=0,"",VLOOKUP(H9,metric_dict!A:C,3,0)) -> Отчетность | M9: =VLOOKUP(H9,metric_dict!A:AA,4,0) -> Настроена по воронке | N9: =VLOOKUP(H9,metric_dict!A:AA,5,0) -> Настроить мониторинг по воронке привлечения | O9: =VLOOKUP(H9,metric_dict!A:AA,6,0) -> 2 | P9: segment | Q9: =VLOOKUP(H9,metric_dict!A:AA,7,0) -> 1
A10: 18 | B10: 19 | C10: 18 | D10: 17 | E10: CX | F10: Молодежь | G10: 10 | H10: Привлечение.Полнота отчёта | I10: 0.25 | J10: 0.5 | K10: =VLOOKUP(H10,metric_dict!A:B,2,0) -> Воронка привлечения | L10: =IF(VLOOKUP(H10,metric_dict!A:C,3,0)=0,"",VLOOKUP(H10,metric_dict!A:C,3,0)) -> Отчетность | M10: =VLOOKUP(H10,metric_dict!A:AA,4,0) -> Источники, CR, объёмы, сегменты | N10: =VLOOKUP(H10,metric_dict!A:AA,5,0) -> Донасытить метриками мониторинг по воронке привлечения | O10: =VLOOKUP(H10,metric_dict!A:AA,6,0) -> 3 | P10: segment | Q10: =VLOOKUP(H10,metric_dict!A:AA,7,0) -> 2
A11: 18 | B11: 19 | C11: 18 | D11: 17 | E11: CX | F11: Молодежь | G11: 12 | H11: Отток.Регулярная отчётность | I11: 0 | J11: 0.5 | K11: =VLOOKUP(H11,metric_dict!A:B,2,0) -> Воронка оттока | L11: =IF(VLOOKUP(H11,metric_dict!A:C,3,0)=0,"",VLOOKUP(H11,metric_dict!A:C,3,0)) -> Отчетность | M11: =VLOOKUP(H11,metric_dict!A:AA,4,0) -> Настроена по воронке | N11: =VLOOKUP(H11,metric_dict!A:AA,5,0) -> Настроить мониторинг по воронке оттока | O11: =VLOOKUP(H11,metric_dict!A:AA,6,0) -> 2 | P11: segment | Q11: =VLOOKUP(H11,metric_dict!A:AA,7,0) -> 1
A12: 18 | B12: 19 | C12: 18 | D12: 17 | E12: CX | F12: Молодежь | G12: 13 | H12: Отток.Полнота отчёта | I12: 0 | J12: 0.5 | K12: =VLOOKUP(H12,metric_dict!A:B,2,0) -> Воронка оттока | L12: =IF(VLOOKUP(H12,metric_dict!A:C,3,0)=0,"",VLOOKUP(H12,metric_dict!A:C,3,0)) -> Отчетность | M12: =VLOOKUP(H12,metric_dict!A:AA,4,0) -> Retention, CR, удержание | N12: =VLOOKUP(H12,metric_dict!A:AA,5,0) -> Донасытить метриками мониторинг по воронке оттока | O12: =VLOOKUP(H12,metric_dict!A:AA,6,0) -> 3 | P12: segment | Q12: =VLOOKUP(H12,metric_dict!A:AA,7,0) -> 2
A13: 18 | B13: 19 | C13: 18 | D13: 17 | E13: CX | F13: Молодежь | G13: 15 | H13: Наличие бенчмарков | I13: 1 | J13: 1 | K13: =VLOOKUP(H13,metric_dict!A:B,2,0) -> BENCHMARKS | L13: =IF(VLOOKUP(H13,metric_dict!A:C,3,0)=0,"",VLOOKUP(H13,metric_dict!A:C,3,0)) | M13: =VLOOKUP(H13,metric_dict!A:AA,4,0) -> Цели / динамика / рынок | N13: =VLOOKUP(H13,metric_dict!A:AA,5,0) -> Сформировать бенчмарки по продуктовым метрикам | O13: =VLOOKUP(H13,metric_dict!A:AA,6,0) -> 5 | P13: segment | Q13: =VLOOKUP(H13,metric_dict!A:AA,7,0) -> 6
... A104: 229 | B104: 230 | C104: 229 | D104: 228 | E104: CX | F104: СберПрайм | G104: 29 | H104: Мониторинг механик | I104: 0 | J104: 0 | K104: =VLOOKUP(H104,metric_dict!A:B,2,0) -> Механики | L104: =IF(VLOOKUP(H104,metric_dict!A:C,3,0)=0,"",VLOOKUP(H104,metric_dict!A:C,3,0)) | M104: =VLOOKUP(H104,metric_dict!A:AA,4,0) -> Настроен по ключевым механикам работы с клиентской базой | N104: =VLOOKUP(H104,metric_dict!A:AA,5,0) -> Настроить мониторинг по ключевым механикам | O104: =VLOOKUP(H104,metric_dict!A:AA,6,0) -> 2 | P104: product | Q104: =VLOOKUP(H104,metric_dict!A:AA,7,0) -> 22
A105: 229 | B105: 230 | C105: 229 | D105: 228 | E105: CX | F105: СберПрайм | G105: 30 | H105: Cross-sell | I105: 0 | J105: Не релевантно | K105: =VLOOKUP(H105,metric_dict!A:B,2,0) -> Механики | L105: =IF(VLOOKUP(H105,metric_dict!A:C,3,0)=0,"",VLOOKUP(H105,metric_dict!A:C,3,0)) | M105: =VLOOKUP(H105,metric_dict!A:AA,4,0) -> В оформлении и после покупки | N105: =VLOOKUP(H105,metric_dict!A:AA,5,0) -> Проработать механики кросс-продаж | O105: =VLOOKUP(H105,metric_dict!A:AA,6,0) -> 5 | P105: product | Q105: =VLOOKUP(H105,metric_dict!A:AA,7,0) -> 8
A106: 229 | B106: 230 | C106: 229 | D106: 228 | E106: CX | F106: СберПрайм | G106: 31 | H106: Cross-sell | I106: 0 | J106: 0 | K106: =VLOOKUP(H106,metric_dict!A:B,2,0) -> Механики | L106: =IF(VLOOKUP(H106,metric_dict!A:C,3,0)=0,"",VLOOKUP(H106,metric_dict!A:C,3,0)) | M106: =VLOOKUP(H106,metric_dict!A:AA,4,0) -> В оформлении и после покупки | N106: =VLOOKUP(H106,metric_dict!A:AA,5,0) -> Проработать механики кросс-продаж | O106: =VLOOKUP(H106,metric_dict!A:AA,6,0) -> 5 | P106: product | Q106: =VLOOKUP(H106,metric_dict!A:AA,7,0) -> 8
A107: 229 | B107: 230 | C107: 229 | D107: 228 | E107: CX | F107: СберПрайм | G107: 32 | H107: Cross-sell | I107: 0 | J107: 0 | K107: =VLOOKUP(H107,metric_dict!A:B,2,0) -> Механики | L107: =IF(VLOOKUP(H107,metric_dict!A:C,3,0)=0,"",VLOOKUP(H107,metric_dict!A:C,3,0)) | M107: =VLOOKUP(H107,metric_dict!A:AA,4,0) -> В оформлении и после покупки | N107: =VLOOKUP(H107,metric_dict!A:AA,5,0) -> Проработать механики кросс-продаж | O107: =VLOOKUP(H107,metric_dict!A:AA,6,0) -> 5 | P107: product | Q107: =VLOOKUP(H107,metric_dict!A:AA,7,0) -> 8
A108: 229 | B108: 230 | C108: 229 | D108: 228 | E108: CX | F108: СберПрайм | G108: 33 | H108: Допродажи (upsell) | I108: 1 | J108: 1 | K108: =VLOOKUP(H108,metric_dict!A:B,2,0) -> Механики | L108: =IF(VLOOKUP(H108,metric_dict!A:C,3,0)=0,"",VLOOKUP(H108,metric_dict!A:C,3,0)) | M108: =VLOOKUP(H108,metric_dict!A:AA,4,0) -> Переход клиента на более ценный продукт или расширенный пакет услуг | N108: =VLOOKUP(H108,metric_dict!A:AA,5,0) -> Настроить мониторинг по ключевым механикам | O108: =VLOOKUP(H108,metric_dict!A:AA,6,0) -> 5 | P108: product | Q108: =VLOOKUP(H108,metric_dict!A:AA,7,0) -> 10
A109: 229 | B109: 230 | C109: 229 | D109: 228 | E109: CX | F109: СберПрайм | G109: 34 | H109: Мониторинг механик | I109: 0 | J109: 0 | K109: =VLOOKUP(H109,metric_dict!A:B,2,0) -> Механики | L109: =IF(VLOOKUP(H109,metric_dict!A:C,3,0)=0,"",VLOOKUP(H109,metric_dict!A:C,3,0)) | M109: =VLOOKUP(H109,metric_dict!A:AA,4,0) -> Настроен по ключевым механикам работы с клиентской базой | N109: =VLOOKUP(H109,metric_dict!A:AA,5,0) -> Настроить мониторинг по ключевым механикам | O109: =VLOOKUP(H109,metric_dict!A:AA,6,0) -> 2 | P109: product | Q109: =VLOOKUP(H109,metric_dict!A:AA,7,0) -> 22
A110: 229 | B110: 230 | C110: 229 | D110: 228 | E110: CX | F110: СберПрайм | G110: 35 | H110: Discovery ≥40% бэклога | I110: 0.5 | J110: 1 | K110: =VLOOKUP(H110,metric_dict!A:B,2,0) -> Гипотезы и инициативы | L110: =IF(VLOOKUP(H110,metric_dict!A:C,3,0)=0,"",VLOOKUP(H110,metric_dict!A:C,3,0)) | M110: =VLOOKUP(H110,metric_dict!A:AA,4,0) -> Доля исследовательских задач DA | N110: =VLOOKUP(H110,metric_dict!A:AA,5,0) -> Сфокусировать бэклог аналитиков на research-задачи | O110: =VLOOKUP(H110,metric_dict!A:AA,6,0) -> 5 | P110: product | Q110: =VLOOKUP(H110,metric_dict!A:AA,7,0) -> 1
A111: 229 | B111: 230 | C111: 229 | D111: 228 | E111: CX | F111: СберПрайм | G111: 36 | H111: Нет собственных аналитиков | I111: 0 | J111: 0 | K111: =VLOOKUP(H111,metric_dict!A:B,2,0) -> #N/A | L111: =IF(VLOOKUP(H111,metric_dict!A:C,3,0)=0,"",VLOOKUP(H111,metric_dict!A:C,3,0)) -> #N/A | M111: =VLOOKUP(H111,metric_dict!A:AA,4,0) -> #N/A | N111: =VLOOKUP(H111,metric_dict!A:AA,5,0) -> #N/A | O111: =VLOOKUP(H111,metric_dict!A:AA,6,0) -> #N/A | P111: product | Q111: =VLOOKUP(H111,metric_dict!A:AA,7,0) -> #N/A
A112: 229 | B112: 230 | C112: 229 | D112: 228 | E112: CX | F112: СберПрайм | G112: 38 | H112: Запуски кампаний за квартал | I112: 0.5 | J112: 0.5 | K112: =VLOOKUP(H112,metric_dict!A:B,2,0) -> Воронка привлечения | L112: =IF(VLOOKUP(H112,metric_dict!A:C,3,0)=0,"",VLOOKUP(H112,metric_dict!A:C,3,0)) | M112: =VLOOKUP(H112,metric_dict!A:AA,4,0) -> Self-service / кампейнинг, успешность | N112: =VLOOKUP(H112,metric_dict!A:AA,5,0) -> Развитие кампейнинга | O112: =VLOOKUP(H112,metric_dict!A:AA,6,0) -> 2 | P112: product | Q112: =VLOOKUP(H112,metric_dict!A:AA,7,0) -> 6
A113: 229 | B113: 230 | C113: 229 | D113: 228 | E113: CX | F113: СберПрайм | G113: 39 | H113: Запуски кампаний за квартал | I113: 0 | J113: 0.5 | K113: =VLOOKUP(H113,metric_dict!A:B,2,0) -> Воронка привлечения | L113: =IF(VLOOKUP(H113,metric_dict!A:C,3,0)=0,"",VLOOKUP(H113,metric_dict!A:C,3,0)) | M113: =VLOOKUP(H113,metric_dict!A:AA,4,0) -> Self-service / кампейнинг, успешность | N113: =VLOOKUP(H113,metric_dict!A:AA,5,0) -> Развитие кампейнинга | O113: =VLOOKUP(H113,metric_dict!A:AA,6,0) -> 2 | P113: product | Q113: =VLOOKUP(H113,metric_dict!A:AA,7,0) -> 6
A114: 229 | B114: 230 | C114: 229 | D114: 228 | E114: CX | F114: СберПрайм | G114: 40 | H114: Запуски кампаний за квартал | I114: 0.5 | J114: 0.5 | K114: =VLOOKUP(H114,metric_dict!A:B,2,0) -> Воронка привлечения | L114: =IF(VLOOKUP(H114,metric_dict!A:C,3,0)=0,"",VLOOKUP(H114,metric_dict!A:C,3,0)) | M114: =VLOOKUP(H114,metric_dict!A:AA,4,0) -> Self-service / кампейнинг, успешность | N114: =VLOOKUP(H114,metric_dict!A:AA,5,0) -> Развитие кампейнинга | O114: =VLOOKUP(H114,metric_dict!A:AA,6,0) -> 2 | P114: product | Q114: =VLOOKUP(H114,metric_dict!A:AA,7,0) -> 6
A115: 229 | B115: 230 | C115: 229 | D115: 228 | E115: CX | F115: СберПрайм | G115: 41 | H115: Черновики в СБОЛ ≥70% | I115: 0.5 | J115: 1 | K115: =VLOOKUP(H115,metric_dict!A:B,2,0) -> Воронка привлечения | L115: =IF(VLOOKUP(H115,metric_dict!A:C,3,0)=0,"",VLOOKUP(H115,metric_dict!A:C,3,0)) | M115: =VLOOKUP(H115,metric_dict!A:AA,4,0) -> Покрытие черновиков коммуникациями | N115: =VLOOKUP(H115,metric_dict!A:AA,5,0) -> Увеличить покрытие черновиков | O115: =VLOOKUP(H115,metric_dict!A:AA,6,0) -> 5 | P115: product | Q115: =VLOOKUP(H115,metric_dict!A:AA,7,0) -> 7
A116: 229 | B116: 230 | C116: 229 | D116: 228 | E116: CX | F116: СберПрайм | G116: 42 | H116: CX Score | I116: 0.5 | J116: 1 | K116: =VLOOKUP(H116,metric_dict!A:B,2,0) -> Клиентский опыт | L116: =IF(VLOOKUP(H116,metric_dict!A:C,3,0)=0,"",VLOOKUP(H116,metric_dict!A:C,3,0)) | M116: =VLOOKUP(H116,metric_dict!A:AA,4,0) -> Зелёная зона клиентского пути | N116: =VLOOKUP(H116,metric_dict!A:AA,5,0) -> Достигнуть целевого CX Score | O116: =VLOOKUP(H116,metric_dict!A:AA,6,0) -> 5 | P116: product | Q116: =VLOOKUP(H116,metric_dict!A:AA,7,0) -> 1
A117: 229 | B117: 230 | C117: 229 | D117: 228 | E117: CX | F117: СберПрайм | G117: 43 | H117: A/B-тесты | I117: 0 | J117: 0 | K117: =VLOOKUP(H117,metric_dict!A:B,2,0) -> Гипотезы и инициативы | L117: =IF(VLOOKUP(H117,metric_dict!A:C,3,0)=0,"",VLOOKUP(H117,metric_dict!A:C,3,0)) | M117: =VLOOKUP(H117,metric_dict!A:AA,4,0) -> Проведение A/B тестов | N117: =VLOOKUP(H117,metric_dict!A:AA,5,0) -> Запустить A/B-тестирование | O117: =VLOOKUP(H117,metric_dict!A:AA,6,0) -> 5 | P117: product | Q117: =VLOOKUP(H117,metric_dict!A:AA,7,0) -> 3
... A128: 239 | B128: 240 | C128: 239 | D128: 238 | E128: CX | F128: Пакет услуг СберПервый | G128: 53 | H128: Ссылка на воронку оттока | I128: 0 | J128: 0 | K128: =VLOOKUP(H128,metric_dict!A:B,2,0) -> #N/A | L128: =IF(VLOOKUP(H128,metric_dict!A:C,3,0)=0,"",VLOOKUP(H128,metric_dict!A:C,3,0)) -> #N/A | M128: =VLOOKUP(H128,metric_dict!A:AA,4,0) -> #N/A | N128: =VLOOKUP(H128,metric_dict!A:AA,5,0) -> #N/A | O128: =VLOOKUP(H128,metric_dict!A:AA,6,0) -> #N/A | P128: product | Q128: =VLOOKUP(H128,metric_dict!A:AA,7,0) -> #N/A
A129: 229 | B129: 230 | C129: 229 | D129: 228 | E129: CX | F129: СберПрайм | G129: 53 | H129: Ссылка на воронку оттока | I129: 0 | J129: https://confluence.sberbank.ru/pages/viewpage.action?pageId=14212498623 | K129: =VLOOKUP(H129,metric_dict!A:B,2,0) -> #N/A | L129: =IF(VLOOKUP(H129,metric_dict!A:C,3,0)=0,"",VLOOKUP(H129,metric_dict!A:C,3,0)) -> #N/A | M129: =VLOOKUP(H129,metric_dict!A:AA,4,0) -> #N/A | N129: =VLOOKUP(H129,metric_dict!A:AA,5,0) -> #N/A | O129: =VLOOKUP(H129,metric_dict!A:AA,6,0) -> #N/A | P129: product | Q129: =VLOOKUP(H129,metric_dict!A:AA,7,0) -> #N/A
A130: 239 | B130: 240 | C130: 239 | D130: 238 | E130: CX | F130: Пакет услуг СберПервый | G130: 54 | H130: Ссылка на бэклог | I130: 0 | J130: https://sbertrack.sberbank.ru/swtr/board/b5380d96-6b2a-4846-9a42-ac7e877607cf?space=PSDA&tenant=default&spaces=%5B%7B%22label%22%3A%22Premium_Solutions_DA%22%2C%22value%22%3A%22PSDA%22%7D%5D (аналитик Шеремет А) | K130: =VLOOKUP(H130,metric_dict!A:B,2,0) -> #N/A | L130: =IF(VLOOKUP(H130,metric_dict!A:C,3,0)=0,"",VLOOKUP(H130,metric_dict!A:C,3,0)) -> #N/A | M130: =VLOOKUP(H130,metric_dict!A:AA,4,0) -> #N/A | N130: =VLOOKUP(H130,metric_dict!A:AA,5,0) -> #N/A | O130: =VLOOKUP(H130,metric_dict!A:AA,6,0) -> #N/A | P130: product | Q130: =VLOOKUP(H130,metric_dict!A:AA,7,0) -> #N/A
A131: 229 | B131: 230 | C131: 229 | D131: 228 | E131: CX | F131: СберПрайм | G131: 52 | H131: Ссылка на коронку привлечения | I131: 0 | J131: https://confluence.sberbank.ru/pages/viewpage.action?pageId=14212498623 | K131: =VLOOKUP(H131,metric_dict!A:B,2,0) -> #N/A | L131: =IF(VLOOKUP(H131,metric_dict!A:C,3,0)=0,"",VLOOKUP(H131,metric_dict!A:C,3,0)) -> #N/A | M131: =VLOOKUP(H131,metric_dict!A:AA,4,0) -> #N/A | N131: =VLOOKUP(H131,metric_dict!A:AA,5,0) -> #N/A | O131: =VLOOKUP(H131,metric_dict!A:AA,6,0) -> #N/A | P131: product | Q131: =VLOOKUP(H131,metric_dict!A:AA,7,0) -> #N/A
A132: 239 | B132: 240 | C132: 239 | D132: 238 | E132: CX | F132: Пакет услуг СберПервый | G132: 101 | H132: Цифр.цели | I132: 0 | J132: 1 | K132: =VLOOKUP(H132,metric_dict!A:B,2,0) -> #N/A | L132: =IF(VLOOKUP(H132,metric_dict!A:C,3,0)=0,"",VLOOKUP(H132,metric_dict!A:C,3,0)) -> #N/A | M132: =VLOOKUP(H132,metric_dict!A:AA,4,0) -> #N/A | N132: =VLOOKUP(H132,metric_dict!A:AA,5,0) -> #N/A | O132: =VLOOKUP(H132,metric_dict!A:AA,6,0) -> #N/A | P132: product | Q132: =VLOOKUP(H132,metric_dict!A:AA,7,0) -> #N/A
A133: 229 | B133: 230 | C133: 229 | D133: 228 | E133: CX | F133: СберПрайм | G133: 101 | H133: Цифр.цели | I133: 1 | J133: 1 | K133: =VLOOKUP(H133,metric_dict!A:B,2,0) -> #N/A | L133: =IF(VLOOKUP(H133,metric_dict!A:C,3,0)=0,"",VLOOKUP(H133,metric_dict!A:C,3,0)) -> #N/A | M133: =VLOOKUP(H133,metric_dict!A:AA,4,0) -> #N/A | N133: =VLOOKUP(H133,metric_dict!A:AA,5,0) -> #N/A | O133: =VLOOKUP(H133,metric_dict!A:AA,6,0) -> #N/A | P133: product | Q133: =VLOOKUP(H133,metric_dict!A:AA,7,0) -> #N/A
A134: 239 | B134: 240 | C134: 239 | D134: 238 | E134: CX | F134: Пакет услуг СберПервый | G134: 102 | H134: Цифр.факторы | I134: 0 | J134: 1 | K134: =VLOOKUP(H134,metric_dict!A:B,2,0) -> #N/A | L134: =IF(VLOOKUP(H134,metric_dict!A:C,3,0)=0,"",VLOOKUP(H134,metric_dict!A:C,3,0)) -> #N/A | M134: =VLOOKUP(H134,metric_dict!A:AA,4,0) -> #N/A | N134: =VLOOKUP(H134,metric_dict!A:AA,5,0) -> #N/A | O134: =VLOOKUP(H134,metric_dict!A:AA,6,0) -> #N/A | P134: product | Q134: =VLOOKUP(H134,metric_dict!A:AA,7,0) -> #N/A
A135: 229 | B135: 230 | C135: 229 | D135: 228 | E135: CX | F135: СберПрайм | G135: 102 | H135: Цифр.факторы | I135: 0 | J135: 1 | K135: =VLOOKUP(H135,metric_dict!A:B,2,0) -> #N/A | L135: =IF(VLOOKUP(H135,metric_dict!A:C,3,0)=0,"",VLOOKUP(H135,metric_dict!A:C,3,0)) -> #N/A | M135: =VLOOKUP(H135,metric_dict!A:AA,4,0) -> #N/A | N135: =VLOOKUP(H135,metric_dict!A:AA,5,0) -> #N/A | O135: =VLOOKUP(H135,metric_dict!A:AA,6,0) -> #N/A | P135: product | Q135: =VLOOKUP(H135,metric_dict!A:AA,7,0) -> #N/A
A136: 239 | B136: 240 | C136: 239 | D136: 238 | E136: CX | F136: Пакет услуг СберПервый | G136: 103 | H136: Цифр.прогнозы | I136: 0 | J136: 1 | K136: =VLOOKUP(H136,metric_dict!A:B,2,0) -> #N/A | L136: =IF(VLOOKUP(H136,metric_dict!A:C,3,0)=0,"",VLOOKUP(H136,metric_dict!A:C,3,0)) -> #N/A | M136: =VLOOKUP(H136,metric_dict!A:AA,4,0) -> #N/A | N136: =VLOOKUP(H136,metric_dict!A:AA,5,0) -> #N/A | O136: =VLOOKUP(H136,metric_dict!A:AA,6,0) -> #N/A | P136: product | Q136: =VLOOKUP(H136,metric_dict!A:AA,7,0) -> #N/A
A137: 229 | B137: 230 | C137: 229 | D137: 228 | E137: CX | F137: СберПрайм | G137: 103 | H137: Цифр.прогнозы | I137: 0 | J137: 1 | K137: =VLOOKUP(H137,metric_dict!A:B,2,0) -> #N/A | L137: =IF(VLOOKUP(H137,metric_dict!A:C,3,0)=0,"",VLOOKUP(H137,metric_dict!A:C,3,0)) -> #N/A | M137: =VLOOKUP(H137,metric_dict!A:AA,4,0) -> #N/A | N137: =VLOOKUP(H137,metric_dict!A:AA,5,0) -> #N/A | O137: =VLOOKUP(H137,metric_dict!A:AA,6,0) -> #N/A | P137: product | Q137: =VLOOKUP(H137,metric_dict!A:AA,7,0) -> #N/A
A138: 13 | B138: 14 | C138: 13 | D138: 12 | E138: CX | F138: Дети | G138: 99 | H138: Активная клиентская база | I138: 0.3 | J138: 0.3 | K138: =VLOOKUP(H138,metric_dict!A:B,2,0) -> Знание ключевых метрик | L138: =IF(VLOOKUP(H138,metric_dict!A:C,3,0)=0,"",VLOOKUP(H138,metric_dict!A:C,3,0)) | M138: =VLOOKUP(H138,metric_dict!A:AA,4,0) -> Знание значения метрики активной клиентской базы | N138: =VLOOKUP(H138,metric_dict!A:AA,5,0) -> Знание метрик и инструментов | O138: =VLOOKUP(H138,metric_dict!A:AA,6,0) -> 1 | P138: segment | Q138: =VLOOKUP(H138,metric_dict!A:AA,7,0) -> 5
A139: 13 | B139: 14 | C139: 13 | D139: 12 | E139: CX | F139: Дети | G139: 98 | H139: Кол-во Major клиентов | I139: 0.15 | J139: 0.3 | K139: =VLOOKUP(H139,metric_dict!A:B,2,0) -> Знание ключевых метрик | L139: =IF(VLOOKUP(H139,metric_dict!A:C,3,0)=0,"",VLOOKUP(H139,metric_dict!A:C,3,0)) | M139: =VLOOKUP(H139,metric_dict!A:AA,4,0) -> Знание метрики Major | N139: =VLOOKUP(H139,metric_dict!A:AA,5,0) -> Знание метрик и инструментов | O139: =VLOOKUP(H139,metric_dict!A:AA,6,0) -> 1 | P139: segment | Q139: =VLOOKUP(H139,metric_dict!A:AA,7,0) -> 6
A140: 13 | B140: 14 | C140: 13 | D140: 12 | E140: CX | F140: Дети | G140: 97 | H140: Кол-во клиентов с 2+ нефин. сервисов | I140: 0 | J140: 0 | K140: =VLOOKUP(H140,metric_dict!A:B,2,0) -> Знание ключевых метрик | L140: =IF(VLOOKUP(H140,metric_dict!A:C,3,0)=0,"",VLOOKUP(H140,metric_dict!A:C,3,0)) | M140: =VLOOKUP(H140,metric_dict!A:AA,4,0) -> Знание метрики кол-во клиентов с 2+ нефин.сервисов | N140: =VLOOKUP(H140,metric_dict!A:AA,5,0) -> Знание метрик и инструментов | O140: =VLOOKUP(H140,metric_dict!A:AA,6,0) -> 1 | P140: segment | Q140: =VLOOKUP(H140,metric_dict!A:AA,7,0) -> 7
...

Sheet metric_dict
A1: metric_name | B1: metric_group | C1: metric_subgroup | D1: metric_footer | E1: recommendation | F1: recommendation_group | G1: sort
A2: Отток.Регулярность (авто) | B2: Воронка оттока | C2: Отчетность | D2: Daily / weekly | E2: Автоматизировать расчет воронки оттока | F2: 4 | G2: 3
A3: Привлечение.Регулярность (авто) | B3: Воронка привлечения | C3: Отчетность | D3: Daily / weekly | E3: Автоматизировать расчет воронки привлечения | F3: 4 | G3: 3
A4: Оповещения по бизнес-метрикам | B4: Алерты | D4: Светофоры целей, драйверов, воронок | E4: Внедрить систему оповещений | F4: 3 | G4: 2
A5: Оповещения по системным сбоям | B5: Алерты | D5: Авто-алерты по IT-инфраструктуре | E5: Внедрить систему оповещений | F5: 5 | G5: 1
A6: Гибкое изменение условий продукта | B6: Механики | D6: Возможность изменить набор опций по продукту без IT-разработки | E6: Выстроить процесс гибкого изменения условий без IT | F6: 10 | G6: 7
A7: Факторный анализ — драйверы 1–2 ур. | B7: Цели | D7: Согласно модели бизнес-процесса | E7: Декомпозировать значения целей на драйверы | F7: 7 | G7: 2
A8: Отток.Полнота отчёта | B8: Воронка оттока | C8: Отчетность | D8: Retention, CR, удержание | E8: Донасытить метриками мониторинг по воронке оттока | F8: 3 | G8: 2
A9: Привлечение.Полнота отчёта | B9: Воронка привлечения | C9: Отчетность | D9: Источники, CR, объёмы, сегменты | E9: Донасытить метриками мониторинг по воронке привлечения | F9: 3 | G9: 2
A10: CX Score | B10: Клиентский опыт | D10: Зелёная зона клиентского пути | E10: Достигнуть целевого CX Score | F10: 5 | G10: 1
A11: A/B-тесты | B11: Гипотезы и инициативы | D11: Проведение A/B тестов | E11: Запустить A/B-тестирование | F11: 5 | G11: 3
A12: Отток.Регулярная отчётность | B12: Воронка оттока | C12: Отчетность | D12: Настроена по воронке | E12: Настроить мониторинг по воронке оттока | F12: 2 | G12: 1
A13: Привлечение.Регулярная отчётность | B13: Воронка привлечения | C13: Отчетность | D13: Настроена по воронке | E13: Настроить мониторинг по воронке привлечения | F13: 2 | G13: 1
A14: Мониторинг механик | B14: Механики | D14: Настроен по ключевым механикам работы с клиентской базой | E14: Настроить мониторинг по ключевым механикам | F14: 2 | G14: 22
A15: Цели выведены на мониторинг | B15: Цели | D15: Регулярное обновление в Навигаторе | E15: Обогащение целей/драйверов/прогнозов в Навигаторе | F15: 2 | G15: 1
A16: MAU продукта | B16: Знание ключевых метрик | D16: Активная месячная аудитория продукта | E16: Знание метрик и инструментов | F16: 1 | G16: 4
A17: Активная клиентская база | B17: Знание ключевых метрик | D17: Знание значения метрики активной клиентской базы | E17: Знание метрик и инструментов | F17: 1 | G17: 5
A18: Доля рынка ФОТ, % | B18: Знание ключевых метрик | D18: Знание метрики доля рынка ФОТ, % | E18: Знание метрик и инструментов | F18: 1 | G18: 9
A19: Знание об отчетности в Навигаторе | B19: Знание ключевых метрик | D19: Понимание доступной отчетности и регулярного мониторинга | E19: Знание метрик и инструментов | F19: 1 | G19: 13
A20: Знание продуктов спутников | B20: Знание ключевых метрик | D20: Понимание связанных продуктов и сценариев | E20: Знание метрик и инструментов | F20: 1 | G20: 12
A21: Клиенты с продуктом | B21: Знание ключевых метрик | D21: Фактическая база клиентов продукта | E21: Знание метрик и инструментов | F21: 1 | G21: 3
A22: Кол-во Major клиентов | B22: Знание ключевых метрик | D22: Знание метрики Major | E22: Знание метрик и инструментов | F22: 1 | G22: 6
A23: Кол-во клиентов с 2+ нефин. сервисов | B23: Знание ключевых метрик | D23: Знание метрики кол-во клиентов с 2+ нефин.сервисов | E23: Знание метрик и инструментов | F23: 1 | G23: 7
A24: Кол-во получателей ЗП | B24: Знание ключевых метрик | D24: Знание метрики кол-во получателей ЗП | E24: Знание метрик и инструментов | F24: 1 | G24: 8
A25: Объем зачислений ФОТ | B25: Знание ключевых метрик | D25: Знание метрики объем зачислений ФОТ | E25: Знание метрик и инструментов | F25: 1 | G25: 10
... A49: Допродажи (upsell) | B49: Механики | D49: Переход клиента на более ценный продукт или расширенный пакет услуг | E49: Настроить мониторинг по ключевым механикам | F49: 5 | G49: 10

Sheet резерв
A1: fake_id | B1: perc_id | C1: value_id | D1: max_value_id | E1: Юнит | F1: Продукт | G1: metric | H1: metric_name | I1: value | J1: max_value | K1: metric_group | L1: metric_footer | M1: recommendation | N1: recommendation_group | O1: type
A2: 75 | B2: 76 | C2: 75 | D2: 74 | E2: УБ | F2: Осаго | G2: 1 | H2: Объем целевого рынка в России | I2: 0 | J2: 0.2 | K2: Самооценка знания продуктовых метрик | L2: Оценка потенциального объема клиентов в России | M2: Ознакомиться со значениями ключевых метрик | N2: easy | O2: product
A3: 75 | B3: 76 | C3: 75 | D3: 74 | E3: УБ | F3: Осаго | G3: 2 | H3: Знание об отчетности в Навигаторе | I3: 0.25 | J3: 0.5 | K3: Самооценка знания продуктовых метрик | L3: Понимание доступной отчетности и регулярного мониторинга | M3: Ознакомиться со значениями ключевых метрик | N3: easy | O3: product
A4: 75 | B4: 76 | C4: 75 | D4: 74 | E4: УБ | F4: Осаго | G4: 3 | H4: Цели выведены на мониторинг | I4: 0.5 | J4: 1 | K4: Цели | L4: Регулярное обновление в Навигаторе | M4: Настроить мониторинг целей в Навигаторе | N4: easy | O4: product
A5: 75 | B5: 76 | C5: 75 | D5: 74 | E5: УБ | F5: Осаго | G5: 4 | H5: Факторный анализ — драйверы 1–2 ур. | I5: 0.5 | J5: 1 | K5: Цели | L5: Согласно модели бизнес-процесса | M5: Декомпозировать значения целей на драйверы | N5: medium | O5: product
A6: 75 | B6: 76 | C6: 75 | D6: 74 | E6: УБ | F6: Осаго | G6: 5 | H6: Прогноз по целям | I6: 0.5 | J6: 1 | K6: Цели | L6: Прогноз выведен в Навигатор | M6: Сформировать прогнозные значения по целям | N6: medium | O6: product
A7: 75 | B7: 76 | C7: 75 | D7: 74 | E7: УБ | F7: Осаго | G7: 9 | H7: Привлечение.Регулярная отчётность | I7: 0.5 | J7: 0.5 | K7: Воронка привлечения | L7: Настроена по воронке | M7: Настроить мониторинг по воронке привлечения | N7: easy | O7: product
A8: 75 | B8: 76 | C8: 75 | D8: 74 | E8: УБ | F8: Осаго | G8: 10 | H8: Привлечение.Полнота отчёта | I8: 0.5 | J8: 0.5 | K8: Воронка привлечения | L8: Источники, CR, объёмы, сегменты | M8: Донасытить метриками мониторинг по воронке привлечения | N8: easy | O8: product
A9: 75 | B9: 76 | C9: 75 | D9: 74 | E9: УБ | F9: Осаго | G9: 11 | H9: Привлечение.Регулярность (авто) | I9: 1 | J9: 1 | K9: Воронка привлечения | L9: Daily / weekly | M9: Автоматизировать расчет воронки привлечения | N9: medium | O9: product
A10: 75 | B10: 76 | C10: 75 | D10: 74 | E10: УБ | F10: Осаго | G10: 12 | H10: Отток.Регулярная отчётность | I10: 0.5 | J10: 0.5 | K10: Воронка оттока | L10: Настроена по воронке | M10: Настроить мониторинг по воронке оттока | N10: easy | O10: product
A11: 75 | B11: 76 | C11: 75 | D11: 74 | E11: УБ | F11: Осаго | G11: 13 | H11: Отток.Полнота отчёта | I11: 0 | J11: 0.5 | K11: Воронка оттока | L11: Retention, CR, удержание | M11: Донасытить метриками мониторинг по воронке оттока | N11: easy | O11: product
A12: 75 | B12: 76 | C12: 75 | D12: 74 | E12: УБ | F12: Осаго | G12: 14 | H12: Отток.Регулярность (авто) | I12: 1 | J12: 1 | K12: Воронка оттока | L12: Daily / weekly | M12: Автоматизировать расчет воронки оттока | N12: medium | O12: product
A13: 75 | B13: 76 | C13: 75 | D13: 74 | E13: УБ | F13: Осаго | G13: 15 | H13: Наличие бенчмарков | I13: 1 | J13: 1 | K13: BENCHMARKS | L13: Цели / динамика / рынок | M13: Сформировать бенчмарки по продуктовым метрикам | N13: medium | O13: product
A14: 75 | B14: 76 | C14: 75 | D14: 74 | E14: УБ | F14: Осаго | G14: 16 | H14: Опишите, какие бенчмарки используются | I14: 0 | J14: 0 | K14: #N/A | L14: #N/A | M14: #N/A | N14: #N/A | O14: product
A15: 75 | B15: 76 | C15: 75 | D15: 74 | E15: УБ | F15: Осаго | G15: 17 | H15: Проведение анализа воронки привлечения | I15: 1 | J15: 1 | K15: Воронка привлечения | L15: Оценка эффективности, поиск точек роста | M15: Провести анализ привлечения, выявить точки роста | N15: medium | O15: product
A16: 75 | B16: 76 | C16: 75 | D16: 74 | E16: УБ | F16: Осаго | G16: 18 | H16: Составлен перечень инициатив по привлечению | I16: 1 | J16: 1 | K16: Воронка привлечения | L16: План действий по росту | M16: Сформировать перечень инициатив | N16: medium | O16: product
A17: 75 | B17: 76 | C17: 75 | D17: 74 | E17: УБ | F17: Осаго | G17: 19 | H17: Проведение анализа воронки оттока | I17: 1 | J17: 1 | K17: Воронка оттока | L17: Оценка причин и узких мест | M17: Провести анализ оттока, выявить точки роста | N17: medium | O17: product
A18: 75 | B18: 76 | C18: 75 | D18: 74 | E18: УБ | F18: Осаго | G18: 20 | H18: Мероприятия по работе с отклонениями | I18: 1 | J18: 1 | K18: Воронка оттока | L18: План действий по отклонениям | M18: Сформировать список мероприятий по снижению оттока | N18: medium | O18: product
A19: 75 | B19: 76 | C19: 75 | D19: 74 | E19: УБ | F19: Осаго | G19: 21 | H19: Оповещения по системным сбоям | I19: 1 | J19: 1 | K19: Алерты | L19: Авто-алерты по IT-инфраструктуре | M19: Внедрить систему оповещений | N19: easy | O19: product
A20: 75 | B20: 76 | C20: 75 | D20: 74 | E20: УБ | F20: Осаго | G20: 22 | H20: Оповещения по бизнес-метрикам | I20: 1 | J20: 1 | K20: Алерты | L20: Светофоры целей, драйверов, воронок | M20: Внедрить систему оповещений | N20: medium | O20: product
A21: 75 | B21: 76 | C21: 75 | D21: 74 | E21: УБ | F21: Осаго | G21: 23 | H21: Полнота продуктовых механик | I21: 0 | J21: 0 | K21: Клиентский опыт | L21: Механики, влияющие на клиентский опыт | M21: Увеличить покрытие механиками | N21: medium | O21: product
A22: 75 | B22: 76 | C22: 75 | D22: 74 | E22: УБ | F22: Осаго | G22: 24 | H22: Удержание клиентов | I22: 0.5 | J22: 0.5 | K22: Воронка оттока | L22: Коммуникация + ценность | M22: Проработать механики удержания клиентов | N22: medium | O22: product
A23: 75 | B23: 76 | C23: 75 | D23: 74 | E23: УБ | F23: Осаго | G23: 25 | H23: Удержание клиентов | I23: 0.5 | J23: 0.5 | K23: Воронка оттока | L23: Коммуникация + ценность | M23: Проработать механики удержания клиентов | N23: medium | O23: product
A24: 75 | B24: 76 | C24: 75 | D24: 74 | E24: УБ | F24: Осаго | G24: 26 | H24: Полнота продуктовых механик | I24: 0 | J24: 0 | K24: Клиентский опыт | L24: Механики, влияющие на клиентский опыт | M24: Увеличить покрытие механиками | N24: medium | O24: product
A25: 75 | B25: 76 | C25: 75 | D25: 74 | E25: УБ | F25: Осаго | G25: 27 | H25: Возврат клиентов | I25: 0.5 | J25: 0.5 | K25: Воронка оттока | L25: Реактивация оттекающих клиентов | M25: Проработать механики реактивации клиентов | N25: medium | O25: product
A26: 75 | B26: 76 | C26: 75 | D26: 74 | E26: УБ | F26: Осаго | G26: 28 | H26: Возврат клиентов | I26: 0.5 | J26: 0.5 | K26: Воронка оттока | L26: Реактивация оттекающих клиентов | M26: Проработать механики реактивации клиентов | N26: medium | O26: product
... A33: 75 | B33: 76 | C33: 75 | D33: 74 | E33: УБ | F33: Осаго | G33: 35 | H33: Discovery ≥40% бэклога | I33: 0.5 | J33: 1 | K33: Гипотезы и инициативы | L33: Доля исследовательских задач DA | M33: Сфокусировать бэклог аналитиков на research-задачи | N33: medium | O33: product
A34: 75 | B34: 76 | C34: 75 | D34: 74 | E34: УБ | F34: Осаго | G34: 36 | H34: Нет собственных аналитиков | I34: 0 | J34: 0 | K34: #N/A | L34: #N/A | M34: #N/A | N34: #N/A | O34: product
A35: 75 | B35: 76 | C35: 75 | D35: 74 | E35: УБ | F35: Осаго | G35: 38 | H35: Запуски кампаний за квартал | I35: 0.5 | J35: 0.5 | K35: Воронка привлечения | L35: Self-service / кампейнинг, покрытие | M35: Запустить кампании | N35: easy | O35: product
A36: 75 | B36: 76 | C36: 75 | D36: 74 | E36: УБ | F36: Осаго | G36: 39 | H36: Запуски кампаний за квартал | I36: 0 | J36: 0.5 | K36: Воронка привлечения | L36: Self-service / кампейнинг, покрытие | M36: Запустить кампании | N36: easy | O36: product
A37: 75 | B37: 76 | C37: 75 | D37: 74 | E37: УБ | F37: Осаго | G37: 40 | H37: Запуски кампаний за квартал | I37: 0.5 | J37: 0.5 | K37: Воронка привлечения | L37: Self-service / кампейнинг, покрытие | M37: Запустить кампании | N37: easy | O37: product
A38: 75 | B38: 76 | C38: 75 | D38: 74 | E38: УБ | F38: Осаго | G38: 41 | H38: Черновики в СБОЛ ≥70% | I38: 0.5 | J38: 1 | K38: Гипотезы и инициативы | L38: Покрытие черновиками | M38: Увеличить покрытие черновиков | N38: medium | O38: product
A39: 75 | B39: 76 | C39: 75 | D39: 74 | E39: УБ | F39: Осаго | G39: 42 | H39: CX Score | I39: 0.5 | J39: 1 | K39: Клиентский опыт | L39: Зелёная зона клиентского пути | M39: Достигнуть целевого CX Score | N39: medium | O39: product
A40: 75 | B40: 76 | C40: 75 | D40: 74 | E40: УБ | F40: Осаго | G40: 43 | H40: A/B-тесты | I40: 0 | J40: 0 | K40: Гипотезы и инициативы | L40: Проведение A/B тестов | M40: Запустить A/B-тестирование | N40: medium | O40: product
A41: 75 | B41: 76 | C41: 75 | D41: 74 | E41: УБ | F41: Осаго | G41: 44 | H41: Рейтинг DataDriven ≥7,5 | I41: 0 | J41: 1 | K41: Гипотезы и инициативы | L41: Средняя оценка проведенных исследований | M41: Повысить качество проведенных исследований | N41: medium | O41: product
A42: 75 | B42: 76 | C42: 75 | D42: 74 | E42: УБ | F42: Осаго | G42: 45 | H42: Доп. инициативы сверх БП | I42: 0 | J42: 1 | K42: Гипотезы и инициативы | L42: В реестре инициатив | M42: Сформировать перечень инициатив | N42: medium | O42: product
A43: 75 | B43: 76 | C43: 75 | D43: 74 | E43: УБ | F43: Осаго | G43: 47 | H43: Объем целевого рынка в Сбере | I43: 0 | J43: 0.2 | K43: Самооценка знания продуктовых метрик | L43: Оценка потенциального объема клиентов в Сбере | M43: Ознакомиться со значениями ключевых метрик | N43: easy | O43: product
A44: 75 | B44: 76 | C44: 75 | D44: 74 | E44: УБ | F44: Осаго | G44: 48 | H44: Клиенты с продуктом | I44: 0 | J44: 0.2 | K44: Самооценка знания продуктовых метрик | L44: Фактическая база клиентов продукта | M44: Ознакомиться со значениями ключевых метрик | N44: easy | O44: product
A45: 75 | B45: 76 | C45: 75 | D45: 74 | E45: УБ | F45: Осаго | G45: 49 | H45: MAU продукта | I45: 0.2 | J45: 0.2 | K45: Самооценка знания продуктовых метрик | L45: Активная месячная аудитория продукта | M45: Ознакомиться со значениями ключевых метрик | N45: easy | O45: product
A46: 75 | B46: 76 | C46: 75 | D46: 74 | E46: УБ | F46: Осаго | G46: 50 | H46: Знание продуктов спутников | I46: 0.1 | J46: 0.1 | K46: Самооценка знания продуктовых метрик | L46: Понимание связанных продуктов и сценариев | M46: Ознакомиться со значениями ключевых метрик | N46: easy | O46: product
...
